,ts_recv,ts_event,rtype,publisher_id,instrument_id,action,side,depth,price,size,flags,ts_in_delta,sequence,bid_px_00,bid_sz_00,bid_ct_00,ask_px_00,ask_sz_00,ask_ct_00,bid_px_01,bid_sz_01,bid_ct_01,ask_px_01,ask_sz_01,ask_ct_01,bid_px_02,bid_sz_02,bid_ct_02,ask_px_02,ask_sz_02,ask_ct_02,bid_px_03,bid_sz_03,bid_ct_03,ask_px_03,ask_sz_03,ask_ct_03,bid_px_04,bid_sz_04,bid_ct_04,ask_px_04,ask_sz_04,ask_ct_04,bid_px_05,bid_sz_05,bid_ct_05,ask_px_05,ask_sz_05,ask_ct_05,bid_px_06,bid_sz_06,bid_ct_06,ask_px_06,ask_sz_06,ask_ct_06,bid_px_07,bid_sz_07,bid_ct_07,ask_px_07,ask_sz_07,ask_ct_07,bid_px_08,bid_sz_08,bid_ct_08,ask_px_08,ask_sz_08,ask_ct_08,bid_px_09,bid_sz_09,bid_ct_09,ask_px_09,ask_sz_09,ask_ct_09,symbol,order_id
1672,2025-07-17T16:02:20.653461966Z,2025-07-17T16:02:20.653461966Z,10,2,1108,A,A,0,13.830000000,15,130,165266,271676148,13.27,10,1,13.83,115,1,13.04,2,1,13.92,2,1,13.03,100,1,14.28,100,1,13.02,100,1,14.45,100,1,12.73,100,1,14.51,100,1,12.71,100,1,14.53,700,1,12.5,700,1,14.56,800,1,12.46,200,1,14.6,700,1,12.43,700,1,14.63,100,1,12.42,700,1,14.64,100,1,ARL,325714721
1673,2025-07-17T16:02:20.653721185Z,2025-07-17T16:02:20.653721185Z,10,2,1108,C,B,0,13.020000000,100,0,165711,271676153,13.27,10,1,13.83,115,1,13.04,2,1,13.92,2,1,13.03,100,1,14.28,100,1,12.73,100,1,14.45,100,1,12.71,100,1,14.51,100,1,12.5,700,1,14.53,700,1,12.46,200,1,14.56,800,1,12.43,700,1,14.6,700,1,12.42,700,1,14.63,100,1,12.37,700,1,14.64,100,1,ARL,320485385
1674,2025-07-17T16:02:20.653721185Z,2025-07-17T16:02:20.653721185Z,10,2,1108,A,B,0,13.260000000,100,130,165711,271676153,13.27,10,1,13.83,115,1,13.26,100,1,13.92,2,1,13.04,2,1,14.28,100,1,13.03,100,1,14.45,100,1,12.73,100,1,14.51,100,1,12.71,100,1,14.53,700,1,12.5,700,1,14.56,800,1,12.46,200,1,14.6,700,1,12.43,700,1,14.63,100,1,12.42,700,1,14.64,100,1,ARL,325714729
1675,2025-07-17T16:02:20.655111649Z,2025-07-17T16:02:20.655111649Z,10,2,1108,C,B,0,13.040000000,2,0,165417,271676165,13.27,10,1,13.83,115,1,13.26,100,1,13.92,2,1,13.03,100,1,14.28,100,1,12.73,100,1,14.45,100,1,12.71,100,1,14.51,100,1,12.5,700,1,14.53,700,1,12.46,200,1,14.56,800,1,12.43,700,1,14.6,700,1,12.42,700,1,14.63,100,1,12.37,700,1,14.64,100,1,ARL,293594281
1676,2025-07-17T16:02:20.655111649Z,2025-07-17T16:02:20.655111649Z,10,2,1108,A,B,0,12.910000000,2,130,165417,271676165,13.27,10,1,13.83,115,1,13.26,100,1,13.92,2,1,13.03,100,1,14.28,100,1,12.91,2,1,14.45,100,1,12.73,100,1,14.51,100,1,12.71,100,1,14.53,700,1,12.5,700,1,14.56,800,1,12.46,200,1,14.6,700,1,12.43,700,1,14.63,100,1,12.42,700,1,14.64,100,1,ARL,325714741
1677,2025-07-17T16:02:20.663209235Z,2025-07-17T16:02:20.663209235Z,10,2,1108,C,A,0,13.830000000,100,130,165341,271676274,13.27,10,1,13.83,15,1,13.26,100,1,13.92,2,1,13.03,100,1,14.28,100,1,12.91,2,1,14.45,100,1,12.73,100,1,14.51,100,1,12.71,100,1,14.53,700,1,12.5,700,1,14.56,800,1,12.46,200,1,14.6,700,1,12.43,700,1,14.63,100,1,12.42,700,1,14.64,100,1,ARL,325176373
1678,2025-07-17T16:02:20.663241882Z,2025-07-17T16:02:20.663241882Z,10,2,1108,C,A,0,14.530000000,700,130,164979,271676275,13.27,10,1,13.83,15,1,13.26,100,1,13.92,2,1,13.03,100,1,14.28,100,1,12.91,2,1,14.45,100,1,12.73,100,1,14.51,100,1,12.71,100,1,14.56,800,1,12.5,700,1,14.6,700,1,12.46,200,1,14.63,100,1,12.43,700,1,14.64,100,1,12.42,700,1,14.68,700,1,ARL,325714545
1679,2025-07-17T16:02:20.663261632Z,2025-07-17T16:02:20.663261632Z,10,2,1108,A,A,0,14.110000000,100,130,165342,271676276,13.27,10,1,13.83,15,1,13.26,100,1,13.92,2,1,13.03,100,1,14.11,100,1,12.91,2,1,14.28,100,1,12.73,100,1,14.45,100,1,12.71,100,1,14.51,100,1,12.5,700,1,14.56,800,1,12.46,200,1,14.6,700,1,12.43,700,1,14.63,100,1,12.42,700,1,14.64,100,1,ARL,325714905
1680,2025-07-17T16:02:20.663394059Z,2025-07-17T16:02:20.663394059Z,10,2,1108,A,A,0,15.940000000,100,130,165407,271676277,13.27,10,1,13.83,15,1,13.26,100,1,13.92,2,1,13.03,100,1,14.11,100,1,12.91,2,1,14.28,100,1,12.73,100,1,14.45,100,1,12.71,100,1,14.51,100,1,12.5,700,1,14.56,800,1,12.46,200,1,14.6,700,1,12.43,700,1,14.63,100,1,12.42,700,1,14.64,100,1,ARL,325714909
1681,2025-07-17T16:02:20.663407337Z,2025-07-17T16:02:20.663407337Z,10,2,1108,C,A,0,15.590000000,100,130,165297,271676278,13.27,10,1,13.83,15,1,13.26,100,1,13.92,2,1,13.03,100,1,14.11,100,1,12.91,2,1,14.28,100,1,12.73,100,1,14.45,100,1,12.71,100,1,14.51,100,1,12.5,700,1,14.56,800,1,12.46,200,1,14.6,700,1,12.43,700,1,14.63,100,1,12.42,700,1,14.64,100,1,ARL,323730697
1682,2025-07-17T16:02:20.664790768Z,2025-07-17T16:02:20.664790768Z,10,2,1108,C,A,0,17.570000000,100,0,165632,271676310,13.27,10,1,13.83,15,1,13.26,100,1,13.92,2,1,13.03,100,1,14.11,100,1,12.91,2,1,14.28,100,1,12.73,100,1,14.45,100,1,12.71,100,1,14.51,100,1,12.5,700,1,14.56,800,1,12.46,200,1,14.6,700,1,12.43,700,1,14.63,100,1,12.42,700,1,14.64,100,1,ARL,325714589
1683,2025-07-17T16:02:20.664790768Z,2025-07-17T16:02:20.664790768Z,10,2,1108,A,A,0,17.760000000,100,130,165632,271676310,13.27,10,1,13.83,15,1,13.26,100,1,13.92,2,1,13.03,100,1,14.11,100,1,12.91,2,1,14.28,100,1,12.73,100,1,14.45,100,1,12.71,100,1,14.51,100,1,12.5,700,1,14.56,800,1,12.46,200,1,14.6,700,1,12.43,700,1,14.63,100,1,12.42,700,1,14.64,100,1,ARL,325714949
1684,2025-07-17T16:02:20.664963386Z,2025-07-17T16:02:20.664963386Z,10,2,1108,C,A,0,14.800000000,100,0,165893,271676320,13.27,10,1,13.83,15,1,13.26,100,1,13.92,2,1,13.03,100,1,14.11,100,1,12.91,2,1,14.28,100,1,12.73,100,1,14.45,100,1,12.71,100,1,14.51,100,1,12.5,700,1,14.56,800,1,12.46,200,1,14.6,700,1,12.43,700,1,14.63,100,1,12.42,700,1,14.64,100,1,ARL,325714629
1685,2025-07-17T16:02:20.664963386Z,2025-07-17T16:02:20.664963386Z,10,2,1108,A,A,0,14.960000000,100,130,165893,271676320,13.27,10,1,13.83,15,1,13.26,100,1,13.92,2,1,13.03,100,1,14.11,100,1,12.91,2,1,14.28,100,1,12.73,100,1,14.45,100,1,12.71,100,1,14.51,100,1,12.5,700,1,14.56,800,1,12.46,200,1,14.6,700,1,12.43,700,1,14.63,100,1,12.42,700,1,14.64,100,1,ARL,325714953
1686,2025-07-17T16:02:20.665034825Z,2025-07-17T16:02:20.665034825Z,10,2,1108,C,A,0,15.910000000,100,0,165567,271676330,13.27,10,1,13.83,15,1,13.26,100,1,13.92,2,1,13.03,100,1,14.11,100,1,12.91,2,1,14.28,100,1,12.73,100,1,14.45,100,1,12.71,100,1,14.51,100,1,12.5,700,1,14.56,800,1,12.46,200,1,14.6,700,1,12.43,700,1,14.63,100,1,12.42,700,1,14.64,100,1,ARL,325714633
1687,2025-07-17T16:02:20.665034825Z,2025-07-17T16:02:20.665034825Z,10,2,1108,A,A,0,16.080000000,100,130,165567,271676330,13.27,10,1,13.83,15,1,13.26,100,1,13.92,2,1,13.03,100,1,14.11,100,1,12.91,2,1,14.28,100,1,12.73,100,1,14.45,100,1,12.71,100,1,14.51,100,1,12.5,700,1,14.56,800,1,12.46,200,1,14.6,700,1,12.43,700,1,14.63,100,1,12.42,700,1,14.64,100,1,ARL,325714957
1688,2025-07-17T16:02:20.665292049Z,2025-07-17T16:02:20.665292049Z,10,2,1108,C,A,0,14.940000000,100,0,165546,271676355,13.27,10,1,13.83,15,1,13.26,100,1,13.92,2,1,13.03,100,1,14.11,100,1,12.91,2,1,14.28,100,1,12.73,100,1,14.45,100,1,12.71,100,1,14.51,100,1,12.5,700,1,14.56,800,1,12.46,200,1,14.6,700,1,12.43,700,1,14.63,100,1,12.42,700,1,14.64,100,1,ARL,324942277
1689,2025-07-17T16:02:20.665292049Z,2025-07-17T16:02:20.665292049Z,10,2,1108,A,A,0,15.380000000,100,130,165546,271676355,13.27,10,1,13.83,15,1,13.26,100,1,13.92,2,1,13.03,100,1,14.11,100,1,12.91,2,1,14.28,100,1,12.73,100,1,14.45,100,1,12.71,100,1,14.51,100,1,12.5,700,1,14.56,800,1,12.46,200,1,14.6,700,1,12.43,700,1,14.63,100,1,12.42,700,1,14.64,100,1,ARL,325714965
1690,2025-07-17T16:02:20.669536385Z,2025-07-17T16:02:20.669536385Z,10,2,1108,C,A,0,14.110000000,100,130,165067,271676398,13.27,10,1,13.83,15,1,13.26,100,1,13.92,2,1,13.03,100,1,14.28,100,1,12.91,2,1,14.45,100,1,12.73,100,1,14.51,100,1,12.71,100,1,14.56,800,1,12.5,700,1,14.6,700,1,12.46,200,1,14.63,100,1,12.43,700,1,14.64,100,1,12.42,700,1,14.68,700,1,ARL,325714905
1691,2025-07-17T16:02:20.669583810Z,2025-07-17T16:02:20.669583810Z,10,2,1108,A,A,0,14.260000000,100,130,165144,271676399,13.27,10,1,13.83,15,1,13.26,100,1,13.92,2,1,13.03,100,1,14.26,100,1,12.91,2,1,14.28,100,1,12.73,100,1,14.45,100,1,12.71,100,1,14.51,100,1,12.5,700,1,14.56,800,1,12.46,200,1,14.6,700,1,12.43,700,1,14.63,100,1,12.42,700,1,14.64,100,1,ARL,325715045
1692,2025-07-17T16:02:20.669587514Z,2025-07-17T16:02:20.669587514Z,10,2,1108,C,A,0,14.510000000,100,0,165465,271676400,13.27,10,1,13.83,15,1,13.26,100,1,13.92,2,1,13.03,100,1,14.26,100,1,12.91,2,1,14.28,100,1,12.73,100,1,14.45,100,1,12.71,100,1,14.56,800,1,12.5,700,1,14.6,700,1,12.46,200,1,14.63,100,1,12.43,700,1,14.64,100,1,12.42,700,1,14.68,700,1,ARL,325177757
1693,2025-07-17T16:02:20.669587514Z,2025-07-17T16:02:20.669587514Z,10,2,1108,A,A,0,14.960000000,100,130,165465,271676400,13.27,10,1,13.83,15,1,13.26,100,1,13.92,2,1,13.03,100,1,14.26,100,1,12.91,2,1,14.28,100,1,12.73,100,1,14.45,100,1,12.71,100,1,14.56,800,1,12.5,700,1,14.6,700,1,12.46,200,1,14.63,100,1,12.43,700,1,14.64,100,1,12.42,700,1,14.68,700,1,ARL,325715053
1694,2025-07-17T16:02:20.685086585Z,2025-07-17T16:02:20.685086585Z,10,2,1108,C,A,0,14.640000000,100,0,165464,271676621,13.27,10,1,13.83,15,1,13.26,100,1,13.92,2,1,13.03,100,1,14.26,100,1,12.91,2,1,14.28,100,1,12.73,100,1,14.45,100,1,12.71,100,1,14.56,800,1,12.5,700,1,14.6,700,1,12.46,200,1,14.63,100,1,12.43,700,1,14.68,700,1,12.42,700,1,14.73,200,1,ARL,325714169
1695,2025-07-17T16:02:20.685086585Z,2025-07-17T16:02:20.685086585Z,10,2,1108,A,A,0,15.060000000,100,130,165464,271676621,13.27,10,1,13.83,15,1,13.26,100,1,13.92,2,1,13.03,100,1,14.26,100,1,12.91,2,1,14.28,100,1,12.73,100,1,14.45,100,1,12.71,100,1,14.56,800,1,12.5,700,1,14.6,700,1,12.46,200,1,14.63,100,1,12.43,700,1,14.68,700,1,12.42,700,1,14.73,200,1,ARL,325715113
1696,2025-07-17T16:02:20.831947250Z,2025-07-17T16:02:20.831947250Z,10,2,1108,A,A,0,14.680000000,700,130,165387,271678584,13.27,10,1,13.83,15,1,13.26,100,1,13.92,2,1,13.03,100,1,14.26,100,1,12.91,2,1,14.28,100,1,12.73,100,1,14.45,100,1,12.71,100,1,14.56,800,1,12.5,700,1,14.6,700,1,12.46,200,1,14.63,100,1,12.43,700,1,14.68,1400,1,12.42,700,1,14.73,200,1,ARL,325716945
1697,2025-07-17T16:02:20.936622241Z,2025-07-17T16:02:20.936622241Z,10,2,1108,C,B,0,13.260000000,100,130,165177,271679553,13.27,10,1,13.83,15,1,13.03,100,1,13.92,2,1,12.91,2,1,14.26,100,1,12.73,100,1,14.28,100,1,12.71,100,1,14.45,100,1,12.5,700,1,14.56,800,1,12.46,200,1,14.6,700,1,12.43,700,1,14.63,100,1,12.42,700,1,14.68,1400,1,12.37,700,1,14.73,200,1,ARL,325714729
1698,2025-07-17T16:02:20.936672130Z,2025-07-17T16:02:20.936672130Z,10,2,1108,A,A,0,13.910000000,5,130,165481,271679555,13.27,10,1,13.83,15,1,13.03,100,1,13.91,5,1,12.91,2,1,13.92,2,1,12.73,100,1,14.26,100,1,12.71,100,1,14.28,100,1,12.5,700,1,14.45,100,1,12.46,200,1,14.56,800,1,12.43,700,1,14.6,700,1,12.42,700,1,14.63,100,1,12.37,700,1,14.68,1400,1,ARL,325718477
1699,2025-07-17T16:02:20.936748894Z,2025-07-17T16:02:20.936748894Z,10,2,1108,T,N,0,13.280000000,11,130,166007,271679557,13.27,10,1,13.83,15,1,13.03,100,1,13.91,5,1,12.91,2,1,13.92,2,1,12.73,100,1,14.26,100,1,12.71,100,1,14.28,100,1,12.5,700,1,14.45,100,1,12.46,200,1,14.56,800,1,12.43,700,1,14.6,700,1,12.42,700,1,14.63,100,1,12.37,700,1,14.68,1400,1,ARL,0
1700,2025-07-17T16:02:20.936833988Z,2025-07-17T16:02:20.936833988Z,10,2,1108,A,A,0,13.840000000,100,130,165223,271679558,13.27,10,1,13.83,15,1,13.03,100,1,13.84,100,1,12.91,2,1,13.91,5,1,12.73,100,1,13.92,2,1,12.71,100,1,14.26,100,1,12.5,700,1,14.28,100,1,12.46,200,1,14.45,100,1,12.43,700,1,14.56,800,1,12.42,700,1,14.6,700,1,12.37,700,1,14.63,100,1,ARL,325718485
1701,2025-07-17T16:02:20.937142186Z,2025-07-17T16:02:20.937142186Z,10,2,1108,T,N,0,13.280000000,11,130,165749,271679562,13.27,10,1,13.83,15,1,13.03,100,1,13.84,100,1,12.91,2,1,13.91,5,1,12.73,100,1,13.92,2,1,12.71,100,1,14.26,100,1,12.5,700,1,14.28,100,1,12.46,200,1,14.45,100,1,12.43,700,1,14.56,800,1,12.42,700,1,14.6,700,1,12.37,700,1,14.63,100,1,ARL,0
1702,2025-07-17T16:02:20.937578907Z,2025-07-17T16:02:20.937578907Z,10,2,1108,C,A,0,15.060000000,100,0,165357,271679565,13.27,10,1,13.83,15,1,13.03,100,1,13.84,100,1,12.91,2,1,13.91,5,1,12.73,100,1,13.92,2,1,12.71,100,1,14.26,100,1,12.5,700,1,14.28,100,1,12.46,200,1,14.45,100,1,12.43,700,1,14.56,800,1,12.42,700,1,14.6,700,1,12.37,700,1,14.63,100,1,ARL,325715113
1703,2025-07-17T16:02:20.937578907Z,2025-07-17T16:02:20.937578907Z,10,2,1108,A,A,0,14.910000000,100,130,165357,271679565,13.27,10,1,13.83,15,1,13.03,100,1,13.84,100,1,12.91,2,1,13.91,5,1,12.73,100,1,13.92,2,1,12.71,100,1,14.26,100,1,12.5,700,1,14.28,100,1,12.46,200,1,14.45,100,1,12.43,700,1,14.56,800,1,12.42,700,1,14.6,700,1,12.37,700,1,14.63,100,1,ARL,325718509
1704,2025-07-17T16:02:20.937736247Z,2025-07-17T16:02:20.937736247Z,10,2,1108,C,A,0,13.910000000,5,130,165046,271679567,13.27,10,1,13.83,15,1,13.03,100,1,13.84,100,1,12.91,2,1,13.92,2,1,12.73,100,1,14.26,100,1,12.71,100,1,14.28,100,1,12.5,700,1,14.45,100,1,12.46,200,1,14.56,800,1,12.43,700,1,14.6,700,1,12.42,700,1,14.63,100,1,12.37,700,1,14.68,1400,1,ARL,325718477
1705,2025-07-17T16:02:20.937927380Z,2025-07-17T16:02:20.937927380Z,10,2,1108,C,A,0,14.960000000,100,0,165906,271679569,13.27,10,1,13.83,15,1,13.03,100,1,13.84,100,1,12.91,2,1,13.92,2,1,12.73,100,1,14.26,100,1,12.71,100,1,14.28,100,1,12.5,700,1,14.45,100,1,12.46,200,1,14.56,800,1,12.43,700,1,14.6,700,1,12.42,700,1,14.63,100,1,12.37,700,1,14.68,1400,1,ARL,325715053
1706,2025-07-17T16:02:20.937927380Z,2025-07-17T16:02:20.937927380Z,10,2,1108,A,A,0,14.810000000,100,130,165906,271679569,13.27,10,1,13.83,15,1,13.03,100,1,13.84,100,1,12.91,2,1,13.92,2,1,12.73,100,1,14.26,100,1,12.71,100,1,14.28,100,1,12.5,700,1,14.45,100,1,12.46,200,1,14.56,800,1,12.43,700,1,14.6,700,1,12.42,700,1,14.63,100,1,12.37,700,1,14.68,1400,1,ARL,325718517
1707,2025-07-17T16:02:20.938132716Z,2025-07-17T16:02:20.938132716Z,10,2,1108,C,A,0,16.080000000,100,0,165123,271679571,13.27,10,1,13.83,15,1,13.03,100,1,13.84,100,1,12.91,2,1,13.92,2,1,12.73,100,1,14.26,100,1,12.71,100,1,14.28,100,1,12.5,700,1,14.45,100,1,12.46,200,1,14.56,800,1,12.43,700,1,14.6,700,1,12.42,700,1,14.63,100,1,12.37,700,1,14.68,1400,1,ARL,325714957
1708,2025-07-17T16:02:20.938132716Z,2025-07-17T16:02:20.938132716Z,10,2,1108,A,A,0,15.920000000,100,130,165123,271679571,13.27,10,1,13.83,15,1,13.03,100,1,13.84,100,1,12.91,2,1,13.92,2,1,12.73,100,1,14.26,100,1,12.71,100,1,14.28,100,1,12.5,700,1,14.45,100,1,12.46,200,1,14.56,800,1,12.43,700,1,14.6,700,1,12.42,700,1,14.63,100,1,12.37,700,1,14.68,1400,1,ARL,325718525
1709,2025-07-17T16:02:20.938451331Z,2025-07-17T16:02:20.938451331Z,10,2,1108,C,A,0,14.960000000,100,0,165323,271679575,13.27,10,1,13.83,15,1,13.03,100,1,13.84,100,1,12.91,2,1,13.92,2,1,12.73,100,1,14.26,100,1,12.71,100,1,14.28,100,1,12.5,700,1,14.45,100,1,12.46,200,1,14.56,800,1,12.43,700,1,14.6,700,1,12.42,700,1,14.63,100,1,12.37,700,1,14.68,1400,1,ARL,325714953
1710,2025-07-17T16:02:20.938451331Z,2025-07-17T16:02:20.938451331Z,10,2,1108,A,A,0,14.810000000,100,130,165323,271679575,13.27,10,1,13.83,15,1,13.03,100,1,13.84,100,1,12.91,2,1,13.92,2,1,12.73,100,1,14.26,100,1,12.71,100,1,14.28,100,1,12.5,700,1,14.45,100,1,12.46,200,1,14.56,800,1,12.43,700,1,14.6,700,1,12.42,700,1,14.63,100,1,12.37,700,1,14.68,1400,1,ARL,325718549
1711,2025-07-17T16:02:20.938724516Z,2025-07-17T16:02:20.938724516Z,10,2,1108,C,A,0,17.760000000,100,0,165303,271679576,13.27,10,1,13.83,15,1,13.03,100,1,13.84,100,1,12.91,2,1,13.92,2,1,12.73,100,1,14.26,100,1,12.71,100,1,14.28,100,1,12.5,700,1,14.45,100,1,12.46,200,1,14.56,800,1,12.43,700,1,14.6,700,1,12.42,700,1,14.63,100,1,12.37,700,1,14.68,1400,1,ARL,325714949
1712,2025-07-17T16:02:20.938724516Z,2025-07-17T16:02:20.938724516Z,10,2,1108,A,A,0,17.580000000,100,130,165303,271679576,13.27,10,1,13.83,15,1,13.03,100,1,13.84,100,1,12.91,2,1,13.92,2,1,12.73,100,1,14.26,100,1,12.71,100,1,14.28,100,1,12.5,700,1,14.45,100,1,12.46,200,1,14.56,800,1,12.43,700,1,14.6,700,1,12.42,700,1,14.63,100,1,12.37,700,1,14.68,1400,1,ARL,325718557
1713,2025-07-17T16:02:20.939389367Z,2025-07-17T16:02:20.939389367Z,10,2,1108,A,B,0,13.020000000,100,130,165319,271679578,13.27,10,1,13.83,15,1,13.03,100,1,13.84,100,1,13.02,100,1,13.92,2,1,12.91,2,1,14.26,100,1,12.73,100,1,14.28,100,1,12.71,100,1,14.45,100,1,12.5,700,1,14.56,800,1,12.46,200,1,14.6,700,1,12.43,700,1,14.63,100,1,12.42,700,1,14.68,1400,1,ARL,325718561
1714,2025-07-17T16:02:20.946240970Z,2025-07-17T16:02:20.946240970Z,10,2,1108,C,A,0,14.260000000,100,130,165232,271679616,13.27,10,1,13.83,15,1,13.03,100,1,13.84,100,1,13.02,100,1,13.92,2,1,12.91,2,1,14.28,100,1,12.73,100,1,14.45,100,1,12.71,100,1,14.56,800,1,12.5,700,1,14.6,700,1,12.46,200,1,14.63,100,1,12.43,700,1,14.68,1400,1,12.42,700,1,14.73,200,1,ARL,325715045
1715,2025-07-17T16:02:20.946291345Z,2025-07-17T16:02:20.946291345Z,10,2,1108,A,A,0,14.120000000,100,130,165441,271679617,13.27,10,1,13.83,15,1,13.03,100,1,13.84,100,1,13.02,100,1,13.92,2,1,12.91,2,1,14.12,100,1,12.73,100,1,14.28,100,1,12.71,100,1,14.45,100,1,12.5,700,1,14.56,800,1,12.46,200,1,14.6,700,1,12.43,700,1,14.63,100,1,12.42,700,1,14.68,1400,1,ARL,325718637
1716,2025-07-17T16:02:20.956886401Z,2025-07-17T16:02:20.956886401Z,10,2,1108,C,B,0,13.020000000,100,0,165212,271679685,13.27,10,1,13.83,15,1,13.03,100,1,13.84,100,1,12.91,2,1,13.92,2,1,12.73,100,1,14.12,100,1,12.71,100,1,14.28,100,1,12.5,700,1,14.45,100,1,12.46,200,1,14.56,800,1,12.43,700,1,14.6,700,1,12.42,700,1,14.63,100,1,12.37,700,1,14.68,1400,1,ARL,325718561
1717,2025-07-17T16:02:20.956886401Z,2025-07-17T16:02:20.956886401Z,10,2,1108,A,B,0,13.260000000,100,130,165212,271679685,13.27,10,1,13.83,15,1,13.26,100,1,13.84,100,1,13.03,100,1,13.92,2,1,12.91,2,1,14.12,100,1,12.73,100,1,14.28,100,1,12.71,100,1,14.45,100,1,12.5,700,1,14.56,800,1,12.46,200,1,14.6,700,1,12.43,700,1,14.63,100,1,12.42,700,1,14.68,1400,1,ARL,325718821
1718,2025-07-17T16:02:20.956923753Z,2025-07-17T16:02:20.956923753Z,10,2,1108,A,B,0,13.120000000,100,130,165390,271679686,13.27,10,1,13.83,15,1,13.26,100,1,13.84,100,1,13.12,100,1,13.92,2,1,13.03,100,1,14.12,100,1,12.91,2,1,14.28,100,1,12.73,100,1,14.45,100,1,12.71,100,1,14.56,800,1,12.5,700,1,14.6,700,1,12.46,200,1,14.63,100,1,12.43,700,1,14.68,1400,1,ARL,325718833
1719,2025-07-17T16:02:20.956925447Z,2025-07-17T16:02:20.956925447Z,10,2,1108,A,B,0,13.120000000,100,130,165037,271679687,13.27,10,1,13.83,15,1,13.26,100,1,13.84,100,1,13.12,200,1,13.92,2,1,13.03,100,1,14.12,100,1,12.91,2,1,14.28,100,1,12.73,100,1,14.45,100,1,12.71,100,1,14.56,800,1,12.5,700,1,14.6,700,1,12.46,200,1,14.63,100,1,12.43,700,1,14.68,1400,1,ARL,325718837
1720,2025-07-17T16:02:20.988490644Z,2025-07-17T16:02:20.988490644Z,10,2,1108,A,A,0,13.980000000,100,130,165226,271679923,13.27,10,1,13.83,15,1,13.26,100,1,13.84,100,1,13.12,200,1,13.92,2,1,13.03,100,1,13.98,100,1,12.91,2,1,14.12,100,1,12.73,100,1,14.28,100,1,12.71,100,1,14.45,100,1,12.5,700,1,14.56,800,1,12.46,200,1,14.6,700,1,12.43,700,1,14.63,100,1,ARL,325719353
1721,2025-07-17T16:02:20.988491826Z,2025-07-17T16:02:20.988491826Z,10,2,1108,A,A,0,13.980000000,100,130,165118,271679924,13.27,10,1,13.83,15,1,13.26,100,1,13.84,100,1,13.12,200,1,13.92,2,1,13.03,100,1,13.98,200,1,12.91,2,1,14.12,100,1,12.73,100,1,14.28,100,1,12.71,100,1,14.45,100,1,12.5,700,1,14.56,800,1,12.46,200,1,14.6,700,1,12.43,700,1,14.63,100,1,ARL,325719357
1722,2025-07-17T16:02:30.805028316Z,2025-07-17T16:02:30.805028316Z,10,2,1108,C,B,0,13.270000000,10,130,165379,271818376,13.26,100,1,13.83,15,1,13.12,200,1,13.84,100,1,13.03,100,1,13.92,2,1,12.91,2,1,13.98,200,1,12.73,100,1,14.12,100,1,12.71,100,1,14.28,100,1,12.5,700,1,14.45,100,1,12.46,200,1,14.56,800,1,12.43,700,1,14.6,700,1,12.42,700,1,14.63,100,1,ARL,325714717
1723,2025-07-17T16:02:34.987005787Z,2025-07-17T16:02:34.987005787Z,10,2,1108,C,B,0,12.910000000,2,0,165610,271871706,13.26,100,1,13.83,15,1,13.12,200,1,13.84,100,1,13.03,100,1,13.92,2,1,12.73,100,1,13.98,200,1,12.71,100,1,14.12,100,1,12.5,700,1,14.28,100,1,12.46,200,1,14.45,100,1,12.43,700,1,14.56,800,1,12.42,700,1,14.6,700,1,12.37,700,1,14.63,100,1,ARL,325714741
1724,2025-07-17T16:02:34.987005787Z,2025-07-17T16:02:34.987005787Z,10,2,1108,A,B,0,13.000000000,2,130,165610,271871706,13.26,100,1,13.83,15,1,13.12,200,1,13.84,100,1,13.03,100,1,13.92,2,1,13,2,1,13.98,200,1,12.73,100,1,14.12,100,1,12.71,100,1,14.28,100,1,12.5,700,1,14.45,100,1,12.46,200,1,14.56,800,1,12.43,700,1,14.6,700,1,12.42,700,1,14.63,100,1,ARL,325967705
1725,2025-07-17T16:02:39.809299504Z,2025-07-17T16:02:39.809299504Z,10,2,1108,A,A,0,13.790000000,15,130,165457,271952021,13.26,100,1,13.79,15,1,13.12,200,1,13.83,15,1,13.03,100,1,13.84,100,1,13,2,1,13.92,2,1,12.73,100,1,13.98,200,1,12.71,100,1,14.12,100,1,12.5,700,1,14.28,100,1,12.46,200,1,14.45,100,1,12.43,700,1,14.56,800,1,12.42,700,1,14.6,700,1,ARL,326077141
1726,2025-07-17T16:02:40.007306432Z,2025-07-17T16:02:40.007306432Z,10,2,1108,C,A,0,13.840000000,100,0,165588,271957331,13.26,100,1,13.79,15,1,13.12,200,1,13.83,15,1,13.03,100,1,13.92,2,1,13,2,1,13.98,200,1,12.73,100,1,14.12,100,1,12.71,100,1,14.28,100,1,12.5,700,1,14.45,100,1,12.46,200,1,14.56,800,1,12.43,700,1,14.6,700,1,12.42,700,1,14.63,100,1,ARL,325718485
1727,2025-07-17T16:02:40.007306432Z,2025-07-17T16:02:40.007306432Z,10,2,1108,A,A,0,13.800000000,100,130,165588,271957331,13.26,100,1,13.79,15,1,13.12,200,1,13.8,100,1,13.03,100,1,13.83,15,1,13,2,1,13.92,2,1,12.73,100,1,13.98,200,1,12.71,100,1,14.12,100,1,12.5,700,1,14.28,100,1,12.46,200,1,14.45,100,1,12.43,700,1,14.56,800,1,12.42,700,1,14.6,700,1,ARL,326082329
1728,2025-07-17T16:02:40.008048023Z,2025-07-17T16:02:40.008048023Z,10,2,1108,C,A,0,14.910000000,100,0,165631,271957349,13.26,100,1,13.79,15,1,13.12,200,1,13.8,100,1,13.03,100,1,13.83,15,1,13,2,1,13.92,2,1,12.73,100,1,13.98,200,1,12.71,100,1,14.12,100,1,12.5,700,1,14.28,100,1,12.46,200,1,14.45,100,1,12.43,700,1,14.56,800,1,12.42,700,1,14.6,700,1,ARL,325718509
1729,2025-07-17T16:02:40.008048023Z,2025-07-17T16:02:40.008048023Z,10,2,1108,A,A,0,14.870000000,100,130,165631,271957349,13.26,100,1,13.79,15,1,13.12,200,1,13.8,100,1,13.03,100,1,13.83,15,1,13,2,1,13.92,2,1,12.73,100,1,13.98,200,1,12.71,100,1,14.12,100,1,12.5,700,1,14.28,100,1,12.46,200,1,14.45,100,1,12.43,700,1,14.56,800,1,12.42,700,1,14.6,700,1,ARL,326082353
1730,2025-07-17T16:02:40.794847674Z,2025-07-17T16:02:40.794847674Z,10,2,1108,C,A,0,13.790000000,15,130,166797,271972417,13.26,100,1,13.8,100,1,13.12,200,1,13.83,15,1,13.03,100,1,13.92,2,1,13,2,1,13.98,200,1,12.73,100,1,14.12,100,1,12.71,100,1,14.28,100,1,12.5,700,1,14.45,100,1,12.46,200,1,14.56,800,1,12.43,700,1,14.6,700,1,12.42,700,1,14.63,100,1,ARL,326077141
1731,2025-07-17T16:02:40.806140621Z,2025-07-17T16:02:40.806140621Z,10,2,1108,C,A,0,13.830000000,15,130,165274,271973288,13.26,100,1,13.8,100,1,13.12,200,1,13.92,2,1,13.03,100,1,13.98,200,1,13,2,1,14.12,100,1,12.73,100,1,14.28,100,1,12.71,100,1,14.45,100,1,12.5,700,1,14.56,800,1,12.46,200,1,14.6,700,1,12.43,700,1,14.63,100,1,12.42,700,1,14.68,1400,1,ARL,325714721
1732,2025-07-17T16:02:43.834262065Z,2025-07-17T16:02:43.834262065Z,10,2,1108,T,N,0,13.280000000,100,130,166097,272014629,13.26,100,1,13.8,100,1,13.12,200,1,13.92,2,1,13.03,100,1,13.98,200,1,13,2,1,14.12,100,1,12.73,100,1,14.28,100,1,12.71,100,1,14.45,100,1,12.5,700,1,14.56,800,1,12.46,200,1,14.6,700,1,12.43,700,1,14.63,100,1,12.42,700,1,14.68,1400,1,ARL,0
1733,2025-07-17T16:02:43.841686908Z,2025-07-17T16:02:43.841686908Z,10,2,1108,C,B,0,13.260000000,100,130,165522,272014658,13.12,200,1,13.8,100,1,13.03,100,1,13.92,2,1,13,2,1,13.98,200,1,12.73,100,1,14.12,100,1,12.71,100,1,14.28,100,1,12.5,700,1,14.45,100,1,12.46,200,1,14.56,800,1,12.43,700,1,14.6,700,1,12.42,700,1,14.63,100,1,12.37,700,1,14.68,1400,1,ARL,325718821
1734,2025-07-17T16:02:43.841746626Z,2025-07-17T16:02:43.841746626Z,10,2,1108,A,A,0,13.900000000,4,130,165427,272014659,13.12,200,1,13.8,100,1,13.03,100,1,13.9,4,1,13,2,1,13.92,2,1,12.73,100,1,13.98,200,1,12.71,100,1,14.12,100,1,12.5,700,1,14.28,100,1,12.46,200,1,14.45,100,1,12.43,700,1,14.56,800,1,12.42,700,1,14.6,700,1,12.37,700,1,14.63,100,1,ARL,326158809
1735,2025-07-17T16:02:43.842130114Z,2025-07-17T16:02:43.842130114Z,10,2,1108,C,A,0,13.800000000,100,130,165313,272014661,13.12,200,1,13.9,4,1,13.03,100,1,13.92,2,1,13,2,1,13.98,200,1,12.73,100,1,14.12,100,1,12.71,100,1,14.28,100,1,12.5,700,1,14.45,100,1,12.46,200,1,14.56,800,1,12.43,700,1,14.6,700,1,12.42,700,1,14.63,100,1,12.37,700,1,14.68,1400,1,ARL,326082329
1736,2025-07-17T16:02:43.842871428Z,2025-07-17T16:02:43.842871428Z,10,2,1108,C,A,0,14.870000000,100,0,165508,272014673,13.12,200,1,13.9,4,1,13.03,100,1,13.92,2,1,13,2,1,13.98,200,1,12.73,100,1,14.12,100,1,12.71,100,1,14.28,100,1,12.5,700,1,14.45,100,1,12.46,200,1,14.56,800,1,12.43,700,1,14.6,700,1,12.42,700,1,14.63,100,1,12.37,700,1,14.68,1400,1,ARL,326082353
1737,2025-07-17T16:02:43.842871428Z,2025-07-17T16:02:43.842871428Z,10,2,1108,A,A,0,14.920000000,100,130,165508,272014673,13.12,200,1,13.9,4,1,13.03,100,1,13.92,2,1,13,2,1,13.98,200,1,12.73,100,1,14.12,100,1,12.71,100,1,14.28,100,1,12.5,700,1,14.45,100,1,12.46,200,1,14.56,800,1,12.43,700,1,14.6,700,1,12.42,700,1,14.63,100,1,12.37,700,1,14.68,1400,1,ARL,326158869
1738,2025-07-17T16:02:43.842941514Z,2025-07-17T16:02:43.842941514Z,10,2,1108,A,B,0,13.110000000,100,130,165235,272014674,13.12,200,1,13.9,4,1,13.11,100,1,13.92,2,1,13.03,100,1,13.98,200,1,13,2,1,14.12,100,1,12.73,100,1,14.28,100,1,12.71,100,1,14.45,100,1,12.5,700,1,14.56,800,1,12.46,200,1,14.6,700,1,12.43,700,1,14.63,100,1,12.42,700,1,14.68,1400,1,ARL,326158877
1739,2025-07-17T16:02:43.842943173Z,2025-07-17T16:02:43.842943173Z,10,2,1108,C,A,0,14.810000000,100,0,165853,272014675,13.12,200,1,13.9,4,1,13.11,100,1,13.92,2,1,13.03,100,1,13.98,200,1,13,2,1,14.12,100,1,12.73,100,1,14.28,100,1,12.71,100,1,14.45,100,1,12.5,700,1,14.56,800,1,12.46,200,1,14.6,700,1,12.43,700,1,14.63,100,1,12.42,700,1,14.68,1400,1,ARL,325718549
1740,2025-07-17T16:02:43.842943173Z,2025-07-17T16:02:43.842943173Z,10,2,1108,A,A,0,14.960000000,100,130,165853,272014675,13.12,200,1,13.9,4,1,13.11,100,1,13.92,2,1,13.03,100,1,13.98,200,1,13,2,1,14.12,100,1,12.73,100,1,14.28,100,1,12.71,100,1,14.45,100,1,12.5,700,1,14.56,800,1,12.46,200,1,14.6,700,1,12.43,700,1,14.63,100,1,12.42,700,1,14.68,1400,1,ARL,326158881
1741,2025-07-17T16:02:43.843039530Z,2025-07-17T16:02:43.843039530Z,10,2,1108,C,A,0,13.900000000,4,130,165162,272014681,13.12,200,1,13.92,2,1,13.11,100,1,13.98,200,1,13.03,100,1,14.12,100,1,13,2,1,14.28,100,1,12.73,100,1,14.45,100,1,12.71,100,1,14.56,800,1,12.5,700,1,14.6,700,1,12.46,200,1,14.63,100,1,12.43,700,1,14.68,1400,1,12.42,700,1,14.73,200,1,ARL,326158809
1742,2025-07-17T16:02:43.843791297Z,2025-07-17T16:02:43.843791297Z,10,2,1108,C,A,0,17.580000000,100,0,165523,272014689,13.12,200,1,13.92,2,1,13.11,100,1,13.98,200,1,13.03,100,1,14.12,100,1,13,2,1,14.28,100,1,12.73,100,1,14.45,100,1,12.71,100,1,14.56,800,1,12.5,700,1,14.6,700,1,12.46,200,1,14.63,100,1,12.43,700,1,14.68,1400,1,12.42,700,1,14.73,200,1,ARL,325718557
1743,2025-07-17T16:02:43.843791297Z,2025-07-17T16:02:43.843791297Z,10,2,1108,A,A,0,17.760000000,100,130,165523,272014689,13.12,200,1,13.92,2,1,13.11,100,1,13.98,200,1,13.03,100,1,14.12,100,1,13,2,1,14.28,100,1,12.73,100,1,14.45,100,1,12.71,100,1,14.56,800,1,12.5,700,1,14.6,700,1,12.46,200,1,14.63,100,1,12.43,700,1,14.68,1400,1,12.42,700,1,14.73,200,1,ARL,326158953
1744,2025-07-17T16:02:43.844487204Z,2025-07-17T16:02:43.844487204Z,10,2,1108,C,A,0,15.920000000,100,0,165810,272014697,13.12,200,1,13.92,2,1,13.11,100,1,13.98,200,1,13.03,100,1,14.12,100,1,13,2,1,14.28,100,1,12.73,100,1,14.45,100,1,12.71,100,1,14.56,800,1,12.5,700,1,14.6,700,1,12.46,200,1,14.63,100,1,12.43,700,1,14.68,1400,1,12.42,700,1,14.73,200,1,ARL,325718525
1745,2025-07-17T16:02:43.844487204Z,2025-07-17T16:02:43.844487204Z,10,2,1108,A,A,0,16.080000000,100,130,165810,272014697,13.12,200,1,13.92,2,1,13.11,100,1,13.98,200,1,13.03,100,1,14.12,100,1,13,2,1,14.28,100,1,12.73,100,1,14.45,100,1,12.71,100,1,14.56,800,1,12.5,700,1,14.6,700,1,12.46,200,1,14.63,100,1,12.43,700,1,14.68,1400,1,12.42,700,1,14.73,200,1,ARL,326158989
1746,2025-07-17T16:02:43.844636465Z,2025-07-17T16:02:43.844636465Z,10,2,1108,C,A,0,14.810000000,100,0,165486,272014698,13.12,200,1,13.92,2,1,13.11,100,1,13.98,200,1,13.03,100,1,14.12,100,1,13,2,1,14.28,100,1,12.73,100,1,14.45,100,1,12.71,100,1,14.56,800,1,12.5,700,1,14.6,700,1,12.46,200,1,14.63,100,1,12.43,700,1,14.68,1400,1,12.42,700,1,14.73,200,1,ARL,325718517
1747,2025-07-17T16:02:43.844636465Z,2025-07-17T16:02:43.844636465Z,10,2,1108,A,A,0,14.960000000,100,130,165486,272014698,13.12,200,1,13.92,2,1,13.11,100,1,13.98,200,1,13.03,100,1,14.12,100,1,13,2,1,14.28,100,1,12.73,100,1,14.45,100,1,12.71,100,1,14.56,800,1,12.5,700,1,14.6,700,1,12.46,200,1,14.63,100,1,12.43,700,1,14.68,1400,1,12.42,700,1,14.73,200,1,ARL,326158997
1748,2025-07-17T16:02:43.846861336Z,2025-07-17T16:02:43.846861336Z,10,2,1108,C,A,0,13.920000000,2,0,165459,272014713,13.12,200,1,13.98,200,1,13.11,100,1,14.12,100,1,13.03,100,1,14.28,100,1,13,2,1,14.45,100,1,12.73,100,1,14.56,800,1,12.71,100,1,14.6,700,1,12.5,700,1,14.63,100,1,12.46,200,1,14.68,1400,1,12.43,700,1,14.73,200,1,12.42,700,1,14.92,100,1,ARL,325297093
1749,2025-07-17T16:02:43.846861336Z,2025-07-17T16:02:43.846861336Z,10,2,1108,A,A,0,14.030000000,2,130,165459,272014713,13.12,200,1,13.98,200,1,13.11,100,1,14.03,2,1,13.03,100,1,14.12,100,1,13,2,1,14.28,100,1,12.73,100,1,14.45,100,1,12.71,100,1,14.56,800,1,12.5,700,1,14.6,700,1,12.46,200,1,14.63,100,1,12.43,700,1,14.68,1400,1,12.42,700,1,14.73,200,1,ARL,326159041
1750,2025-07-17T16:02:43.847666979Z,2025-07-17T16:02:43.847666979Z,10,2,1108,C,A,0,14.730000000,100,0,165279,272014721,13.12,200,1,13.98,200,1,13.11,100,1,14.03,2,1,13.03,100,1,14.12,100,1,13,2,1,14.28,100,1,12.73,100,1,14.45,100,1,12.71,100,1,14.56,800,1,12.5,700,1,14.6,700,1,12.46,200,1,14.63,100,1,12.43,700,1,14.68,1400,1,12.42,700,1,14.73,100,1,ARL,325714613
1751,2025-07-17T16:02:43.847666979Z,2025-07-17T16:02:43.847666979Z,10,2,1108,A,A,0,14.870000000,100,130,165279,272014721,13.12,200,1,13.98,200,1,13.11,100,1,14.03,2,1,13.03,100,1,14.12,100,1,13,2,1,14.28,100,1,12.73,100,1,14.45,100,1,12.71,100,1,14.56,800,1,12.5,700,1,14.6,700,1,12.46,200,1,14.63,100,1,12.43,700,1,14.68,1400,1,12.42,700,1,14.73,100,1,ARL,326159049
1752,2025-07-17T16:02:43.847981726Z,2025-07-17T16:02:43.847981726Z,10,2,1108,C,A,0,14.730000000,100,0,165472,272014724,13.12,200,1,13.98,200,1,13.11,100,1,14.03,2,1,13.03,100,1,14.12,100,1,13,2,1,14.28,100,1,12.73,100,1,14.45,100,1,12.71,100,1,14.56,800,1,12.5,700,1,14.6,700,1,12.46,200,1,14.63,100,1,12.43,700,1,14.68,1400,1,12.42,700,1,14.87,100,1,ARL,325714577
1753,2025-07-17T16:02:43.847981726Z,2025-07-17T16:02:43.847981726Z,10,2,1108,A,A,0,14.870000000,100,130,165472,272014724,13.12,200,1,13.98,200,1,13.11,100,1,14.03,2,1,13.03,100,1,14.12,100,1,13,2,1,14.28,100,1,12.73,100,1,14.45,100,1,12.71,100,1,14.56,800,1,12.5,700,1,14.6,700,1,12.46,200,1,14.63,100,1,12.43,700,1,14.68,1400,1,12.42,700,1,14.87,200,1,ARL,326159061
1754,2025-07-17T16:02:43.860034354Z,2025-07-17T16:02:43.860034354Z,10,2,1108,C,A,0,14.120000000,100,130,165293,272014788,13.12,200,1,13.98,200,1,13.11,100,1,14.03,2,1,13.03,100,1,14.28,100,1,13,2,1,14.45,100,1,12.73,100,1,14.56,800,1,12.71,100,1,14.6,700,1,12.5,700,1,14.63,100,1,12.46,200,1,14.68,1400,1,12.43,700,1,14.87,200,1,12.42,700,1,14.92,100,1,ARL,325718637
1755,2025-07-17T16:02:43.860087215Z,2025-07-17T16:02:43.860087215Z,10,2,1108,A,A,0,14.260000000,100,130,165231,272014789,13.12,200,1,13.98,200,1,13.11,100,1,14.03,2,1,13.03,100,1,14.26,100,1,13,2,1,14.28,100,1,12.73,100,1,14.45,100,1,12.71,100,1,14.56,800,1,12.5,700,1,14.6,700,1,12.46,200,1,14.63,100,1,12.43,700,1,14.68,1400,1,12.42,700,1,14.87,200,1,ARL,326159201
1756,2025-07-17T16:02:43.893011012Z,2025-07-17T16:02:43.893011012Z,10,2,1108,C,A,0,14.920000000,100,0,165300,272014986,13.12,200,1,13.98,200,1,13.11,100,1,14.03,2,1,13.03,100,1,14.26,100,1,13,2,1,14.28,100,1,12.73,100,1,14.45,100,1,12.71,100,1,14.56,800,1,12.5,700,1,14.6,700,1,12.46,200,1,14.63,100,1,12.43,700,1,14.68,1400,1,12.42,700,1,14.87,200,1,ARL,326158869
1757,2025-07-17T16:02:43.893011012Z,2025-07-17T16:02:43.893011012Z,10,2,1108,A,A,0,15.060000000,100,130,165300,272014986,13.12,200,1,13.98,200,1,13.11,100,1,14.03,2,1,13.03,100,1,14.26,100,1,13,2,1,14.28,100,1,12.73,100,1,14.45,100,1,12.71,100,1,14.56,800,1,12.5,700,1,14.6,700,1,12.46,200,1,14.63,100,1,12.43,700,1,14.68,1400,1,12.42,700,1,14.87,200,1,ARL,326159425
1758,2025-07-17T16:02:43.946801538Z,2025-07-17T16:02:43.946801538Z,10,2,1108,C,A,0,14.630000000,100,0,165599,272015584,13.12,200,1,13.98,200,1,13.11,100,1,14.03,2,1,13.03,100,1,14.26,100,1,13,2,1,14.28,100,1,12.73,100,1,14.45,100,1,12.71,100,1,14.56,800,1,12.5,700,1,14.6,700,1,12.46,200,1,14.68,1400,1,12.43,700,1,14.87,200,1,12.42,700,1,14.96,200,1,ARL,325714653
1759,2025-07-17T16:02:43.946801538Z,2025-07-17T16:02:43.946801538Z,10,2,1108,A,A,0,14.770000000,100,130,165599,272015584,13.12,200,1,13.98,200,1,13.11,100,1,14.03,2,1,13.03,100,1,14.26,100,1,13,2,1,14.28,100,1,12.73,100,1,14.45,100,1,12.71,100,1,14.56,800,1,12.5,700,1,14.6,700,1,12.46,200,1,14.68,1400,1,12.43,700,1,14.77,100,1,12.42,700,1,14.87,200,1,ARL,326160141
1760,2025-07-17T16:02:44.664054457Z,2025-07-17T16:02:44.664054457Z,10,2,1108,A,A,0,13.990000000,100,130,165327,272021808,13.12,200,1,13.98,200,1,13.11,100,1,13.99,100,1,13.03,100,1,14.03,2,1,13,2,1,14.26,100,1,12.73,100,1,14.28,100,1,12.71,100,1,14.45,100,1,12.5,700,1,14.56,800,1,12.46,200,1,14.6,700,1,12.43,700,1,14.68,1400,1,12.42,700,1,14.77,100,1,ARL,326167529
1761,2025-07-17T16:03:02.985818199Z,2025-07-17T16:03:02.985818199Z,10,2,1108,C,A,0,14.870000000,100,0,169399,272331833,13.12,200,1,13.98,200,1,13.11,100,1,13.99,100,1,13.03,100,1,14.03,2,1,13,2,1,14.26,100,1,12.73,100,1,14.28,100,1,12.71,100,1,14.45,100,1,12.5,700,1,14.56,800,1,12.46,200,1,14.6,700,1,12.43,700,1,14.68,1400,1,12.42,700,1,14.77,100,1,ARL,326159049
1762,2025-07-17T16:03:02.985818199Z,2025-07-17T16:03:02.985818199Z,10,2,1108,A,A,0,14.700000000,100,128,169399,272331833,13.12,200,1,13.98,200,1,13.11,100,1,13.99,100,1,13.03,100,1,14.03,2,1,13,2,1,14.26,100,1,12.73,100,1,14.28,100,1,12.71,100,1,14.45,100,1,12.5,700,1,14.56,800,1,12.46,200,1,14.6,700,1,12.43,700,1,14.68,1400,1,12.42,700,1,14.7,100,1,ARL,326551237
1763,2025-07-17T16:03:02.987797728Z,2025-07-17T16:03:02.987797728Z,10,2,1108,C,A,0,14.870000000,100,0,172001,272332718,13.12,200,1,13.98,200,1,13.11,100,1,13.99,100,1,13.03,100,1,14.03,2,1,13,2,1,14.26,100,1,12.73,100,1,14.28,100,1,12.71,100,1,14.45,100,1,12.5,700,1,14.56,800,1,12.46,200,1,14.6,700,1,12.43,700,1,14.68,1400,1,12.42,700,1,14.7,100,1,ARL,326159061
1764,2025-07-17T16:03:02.987797728Z,2025-07-17T16:03:02.987797728Z,10,2,1108,A,A,0,14.700000000,100,128,172001,272332718,13.12,200,1,13.98,200,1,13.11,100,1,13.99,100,1,13.03,100,1,14.03,2,1,13,2,1,14.26,100,1,12.73,100,1,14.28,100,1,12.71,100,1,14.45,100,1,12.5,700,1,14.56,800,1,12.46,200,1,14.6,700,1,12.43,700,1,14.68,1400,1,12.42,700,1,14.7,200,1,ARL,326551829
1765,2025-07-17T16:03:10.807281669Z,2025-07-17T16:03:10.807281669Z,10,2,1108,A,A,0,13.720000000,15,130,165306,272474575,13.12,200,1,13.72,15,1,13.11,100,1,13.98,200,1,13.03,100,1,13.99,100,1,13,2,1,14.03,2,1,12.73,100,1,14.26,100,1,12.71,100,1,14.28,100,1,12.5,700,1,14.45,100,1,12.46,200,1,14.56,800,1,12.43,700,1,14.6,700,1,12.42,700,1,14.68,1400,1,ARL,326729677
1766,2025-07-17T16:03:10.807548848Z,2025-07-17T16:03:10.807548848Z,10,2,1108,C,A,0,13.990000000,100,0,165573,272474576,13.12,200,1,13.72,15,1,13.11,100,1,13.98,200,1,13.03,100,1,14.03,2,1,13,2,1,14.26,100,1,12.73,100,1,14.28,100,1,12.71,100,1,14.45,100,1,12.5,700,1,14.56,800,1,12.46,200,1,14.6,700,1,12.43,700,1,14.68,1400,1,12.42,700,1,14.7,200,1,ARL,326167529
1767,2025-07-17T16:03:10.807548848Z,2025-07-17T16:03:10.807548848Z,10,2,1108,A,A,0,13.730000000,100,130,165573,272474576,13.12,200,1,13.72,15,1,13.11,100,1,13.73,100,1,13.03,100,1,13.98,200,1,13,2,1,14.03,2,1,12.73,100,1,14.26,100,1,12.71,100,1,14.28,100,1,12.5,700,1,14.45,100,1,12.46,200,1,14.56,800,1,12.43,700,1,14.6,700,1,12.42,700,1,14.68,1400,1,ARL,326729685
1768,2025-07-17T16:03:10.808290914Z,2025-07-17T16:03:10.808290914Z,10,2,1108,C,A,0,15.060000000,100,0,166364,272474580,13.12,200,1,13.72,15,1,13.11,100,1,13.73,100,1,13.03,100,1,13.98,200,1,13,2,1,14.03,2,1,12.73,100,1,14.26,100,1,12.71,100,1,14.28,100,1,12.5,700,1,14.45,100,1,12.46,200,1,14.56,800,1,12.43,700,1,14.6,700,1,12.42,700,1,14.68,1400,1,ARL,326159425
1769,2025-07-17T16:03:10.808290914Z,2025-07-17T16:03:10.808290914Z,10,2,1108,A,A,0,14.790000000,100,128,166364,272474580,13.12,200,1,13.72,15,1,13.11,100,1,13.73,100,1,13.03,100,1,13.98,200,1,13,2,1,14.03,2,1,12.73,100,1,14.26,100,1,12.71,100,1,14.28,100,1,12.5,700,1,14.45,100,1,12.46,200,1,14.56,800,1,12.43,700,1,14.6,700,1,12.42,700,1,14.68,1400,1,ARL,326729705
1770,2025-07-17T16:03:10.809541651Z,2025-07-17T16:03:10.809541651Z,10,2,1108,C,A,0,14.960000000,100,0,165623,272474585,13.12,200,1,13.72,15,1,13.11,100,1,13.73,100,1,13.03,100,1,13.98,200,1,13,2,1,14.03,2,1,12.73,100,1,14.26,100,1,12.71,100,1,14.28,100,1,12.5,700,1,14.45,100,1,12.46,200,1,14.56,800,1,12.43,700,1,14.6,700,1,12.42,700,1,14.68,1400,1,ARL,326158881
1771,2025-07-17T16:03:10.809541651Z,2025-07-17T16:03:10.809541651Z,10,2,1108,A,A,0,14.700000000,100,130,165623,272474585,13.12,200,1,13.72,15,1,13.11,100,1,13.73,100,1,13.03,100,1,13.98,200,1,13,2,1,14.03,2,1,12.73,100,1,14.26,100,1,12.71,100,1,14.28,100,1,12.5,700,1,14.45,100,1,12.46,200,1,14.56,800,1,12.43,700,1,14.6,700,1,12.42,700,1,14.68,1400,1,ARL,326729721
1772,2025-07-17T16:03:10.809771527Z,2025-07-17T16:03:10.809771527Z,10,2,1108,C,A,0,14.770000000,100,130,165294,272474594,13.12,200,1,13.72,15,1,13.11,100,1,13.73,100,1,13.03,100,1,13.98,200,1,13,2,1,14.03,2,1,12.73,100,1,14.26,100,1,12.71,100,1,14.28,100,1,12.5,700,1,14.45,100,1,12.46,200,1,14.56,800,1,12.43,700,1,14.6,700,1,12.42,700,1,14.68,1400,1,ARL,326160141
1773,2025-07-17T16:03:10.809798084Z,2025-07-17T16:03:10.809798084Z,10,2,1108,C,A,0,17.760000000,100,0,165493,272474595,13.12,200,1,13.72,15,1,13.11,100,1,13.73,100,1,13.03,100,1,13.98,200,1,13,2,1,14.03,2,1,12.73,100,1,14.26,100,1,12.71,100,1,14.28,100,1,12.5,700,1,14.45,100,1,12.46,200,1,14.56,800,1,12.43,700,1,14.6,700,1,12.42,700,1,14.68,1400,1,ARL,326158953
1774,2025-07-17T16:03:10.809798084Z,2025-07-17T16:03:10.809798084Z,10,2,1108,A,A,0,17.440000000,100,130,165493,272474595,13.12,200,1,13.72,15,1,13.11,100,1,13.73,100,1,13.03,100,1,13.98,200,1,13,2,1,14.03,2,1,12.73,100,1,14.26,100,1,12.71,100,1,14.28,100,1,12.5,700,1,14.45,100,1,12.46,200,1,14.56,800,1,12.43,700,1,14.6,700,1,12.42,700,1,14.68,1400,1,ARL,326729725
1775,2025-07-17T16:03:10.809894317Z,2025-07-17T16:03:10.809894317Z,10,2,1108,A,A,0,14.520000000,100,130,165125,272474597,13.12,200,1,13.72,15,1,13.11,100,1,13.73,100,1,13.03,100,1,13.98,200,1,13,2,1,14.03,2,1,12.73,100,1,14.26,100,1,12.71,100,1,14.28,100,1,12.5,700,1,14.45,100,1,12.46,200,1,14.52,100,1,12.43,700,1,14.56,800,1,12.42,700,1,14.6,700,1,ARL,326729729
1776,2025-07-17T16:03:10.810312923Z,2025-07-17T16:03:10.810312923Z,10,2,1108,C,A,0,16.080000000,100,0,165601,272474600,13.12,200,1,13.72,15,1,13.11,100,1,13.73,100,1,13.03,100,1,13.98,200,1,13,2,1,14.03,2,1,12.73,100,1,14.26,100,1,12.71,100,1,14.28,100,1,12.5,700,1,14.45,100,1,12.46,200,1,14.52,100,1,12.43,700,1,14.56,800,1,12.42,700,1,14.6,700,1,ARL,326158989
1777,2025-07-17T16:03:10.810312923Z,2025-07-17T16:03:10.810312923Z,10,2,1108,A,A,0,15.790000000,100,130,165601,272474600,13.12,200,1,13.72,15,1,13.11,100,1,13.73,100,1,13.03,100,1,13.98,200,1,13,2,1,14.03,2,1,12.73,100,1,14.26,100,1,12.71,100,1,14.28,100,1,12.5,700,1,14.45,100,1,12.46,200,1,14.52,100,1,12.43,700,1,14.56,800,1,12.42,700,1,14.6,700,1,ARL,326729733
1778,2025-07-17T16:03:10.814480532Z,2025-07-17T16:03:10.814480532Z,10,2,1108,C,A,0,14.960000000,100,0,165738,272474635,13.12,200,1,13.72,15,1,13.11,100,1,13.73,100,1,13.03,100,1,13.98,200,1,13,2,1,14.03,2,1,12.73,100,1,14.26,100,1,12.71,100,1,14.28,100,1,12.5,700,1,14.45,100,1,12.46,200,1,14.52,100,1,12.43,700,1,14.56,800,1,12.42,700,1,14.6,700,1,ARL,326158997
1779,2025-07-17T16:03:10.814480532Z,2025-07-17T16:03:10.814480532Z,10,2,1108,A,A,0,14.700000000,100,130,165738,272474635,13.12,200,1,13.72,15,1,13.11,100,1,13.73,100,1,13.03,100,1,13.98,200,1,13,2,1,14.03,2,1,12.73,100,1,14.26,100,1,12.71,100,1,14.28,100,1,12.5,700,1,14.45,100,1,12.46,200,1,14.52,100,1,12.43,700,1,14.56,800,1,12.42,700,1,14.6,700,1,ARL,326729821
1780,2025-07-17T16:03:10.817700664Z,2025-07-17T16:03:10.817700664Z,10,2,1108,C,A,0,14.260000000,100,130,165402,272474675,13.12,200,1,13.72,15,1,13.11,100,1,13.73,100,1,13.03,100,1,13.98,200,1,13,2,1,14.03,2,1,12.73,100,1,14.28,100,1,12.71,100,1,14.45,100,1,12.5,700,1,14.52,100,1,12.46,200,1,14.56,800,1,12.43,700,1,14.6,700,1,12.42,700,1,14.68,1400,1,ARL,326159201
1781,2025-07-17T16:03:10.817754737Z,2025-07-17T16:03:10.817754737Z,10,2,1108,A,A,0,14.000000000,100,130,165233,272474676,13.12,200,1,13.72,15,1,13.11,100,1,13.73,100,1,13.03,100,1,13.98,200,1,13,2,1,14,100,1,12.73,100,1,14.03,2,1,12.71,100,1,14.28,100,1,12.5,700,1,14.45,100,1,12.46,200,1,14.52,100,1,12.43,700,1,14.56,800,1,12.42,700,1,14.6,700,1,ARL,326729929
1782,2025-07-17T16:03:10.843172549Z,2025-07-17T16:03:10.843172549Z,10,2,1108,A,A,0,15.660000000,100,130,165296,272474826,13.12,200,1,13.72,15,1,13.11,100,1,13.73,100,1,13.03,100,1,13.98,200,1,13,2,1,14,100,1,12.73,100,1,14.03,2,1,12.71,100,1,14.28,100,1,12.5,700,1,14.45,100,1,12.46,200,1,14.52,100,1,12.43,700,1,14.56,800,1,12.42,700,1,14.6,700,1,ARL,326730513
1783,2025-07-17T16:03:10.843184785Z,2025-07-17T16:03:10.843184785Z,10,2,1108,C,A,0,15.940000000,100,130,165375,272474827,13.12,200,1,13.72,15,1,13.11,100,1,13.73,100,1,13.03,100,1,13.98,200,1,13,2,1,14,100,1,12.73,100,1,14.03,2,1,12.71,100,1,14.28,100,1,12.5,700,1,14.45,100,1,12.46,200,1,14.52,100,1,12.43,700,1,14.56,800,1,12.42,700,1,14.6,700,1,ARL,325714909
1784,2025-07-17T16:03:10.843448998Z,2025-07-17T16:03:10.843448998Z,10,2,1108,C,A,0,13.980000000,100,0,166539,272474828,13.12,200,1,13.72,15,1,13.11,100,1,13.73,100,1,13.03,100,1,13.98,100,1,13,2,1,14,100,1,12.73,100,1,14.03,2,1,12.71,100,1,14.28,100,1,12.5,700,1,14.45,100,1,12.46,200,1,14.52,100,1,12.43,700,1,14.56,800,1,12.42,700,1,14.6,700,1,ARL,325719357
1785,2025-07-17T16:03:10.843449402Z,2025-07-17T16:03:10.843449402Z,10,2,1108,C,A,0,13.980000000,100,130,166135,272474829,13.12,200,1,13.72,15,1,13.11,100,1,13.73,100,1,13.03,100,1,14,100,1,13,2,1,14.03,2,1,12.73,100,1,14.28,100,1,12.71,100,1,14.45,100,1,12.5,700,1,14.52,100,1,12.46,200,1,14.56,800,1,12.43,700,1,14.6,700,1,12.42,700,1,14.68,1400,1,ARL,325719353
1786,2025-07-17T16:03:10.843462898Z,2025-07-17T16:03:10.843462898Z,10,2,1108,A,A,0,13.870000000,100,130,165348,272474830,13.12,200,1,13.72,15,1,13.11,100,1,13.73,100,1,13.03,100,1,13.87,100,1,13,2,1,14,100,1,12.73,100,1,14.03,2,1,12.71,100,1,14.28,100,1,12.5,700,1,14.45,100,1,12.46,200,1,14.52,100,1,12.43,700,1,14.56,800,1,12.42,700,1,14.6,700,1,ARL,326730517
1787,2025-07-17T16:03:10.843464369Z,2025-07-17T16:03:10.843464369Z,10,2,1108,A,A,0,13.870000000,100,130,165264,272474831,13.12,200,1,13.72,15,1,13.11,100,1,13.73,100,1,13.03,100,1,13.87,200,1,13,2,1,14,100,1,12.73,100,1,14.03,2,1,12.71,100,1,14.28,100,1,12.5,700,1,14.45,100,1,12.46,200,1,14.52,100,1,12.43,700,1,14.56,800,1,12.42,700,1,14.6,700,1,ARL,326730521
1788,2025-07-17T16:03:16.348023740Z,2025-07-17T16:03:16.348023740Z,10,2,1108,A,A,0,13.690000000,15,130,165337,272557172,13.12,200,1,13.69,15,1,13.11,100,1,13.72,15,1,13.03,100,1,13.73,100,1,13,2,1,13.87,200,1,12.73,100,1,14,100,1,12.71,100,1,14.03,2,1,12.5,700,1,14.28,100,1,12.46,200,1,14.45,100,1,12.43,700,1,14.52,100,1,12.42,700,1,14.56,800,1,ARL,326835877
1789,2025-07-17T16:03:16.348302787Z,2025-07-17T16:03:16.348302787Z,10,2,1108,C,A,0,14.700000000,100,0,166037,272557230,13.12,200,1,13.69,15,1,13.11,100,1,13.72,15,1,13.03,100,1,13.73,100,1,13,2,1,13.87,200,1,12.73,100,1,14,100,1,12.71,100,1,14.03,2,1,12.5,700,1,14.28,100,1,12.46,200,1,14.45,100,1,12.43,700,1,14.52,100,1,12.42,700,1,14.56,800,1,ARL,326551829
1790,2025-07-17T16:03:16.348302787Z,2025-07-17T16:03:16.348302787Z,10,2,1108,A,A,0,14.580000000,100,130,166037,272557230,13.12,200,1,13.69,15,1,13.11,100,1,13.72,15,1,13.03,100,1,13.73,100,1,13,2,1,13.87,200,1,12.73,100,1,14,100,1,12.71,100,1,14.03,2,1,12.5,700,1,14.28,100,1,12.46,200,1,14.45,100,1,12.43,700,1,14.52,100,1,12.42,700,1,14.56,800,1,ARL,326835885
1791,2025-07-17T16:03:16.349513354Z,2025-07-17T16:03:16.349513354Z,10,2,1108,C,A,0,14.700000000,100,0,166595,272557430,13.12,200,1,13.69,15,1,13.11,100,1,13.72,15,1,13.03,100,1,13.73,100,1,13,2,1,13.87,200,1,12.73,100,1,14,100,1,12.71,100,1,14.03,2,1,12.5,700,1,14.28,100,1,12.46,200,1,14.45,100,1,12.43,700,1,14.52,100,1,12.42,700,1,14.56,800,1,ARL,326551237
1792,2025-07-17T16:03:16.349513354Z,2025-07-17T16:03:16.349513354Z,10,2,1108,A,A,0,14.580000000,100,130,166595,272557430,13.12,200,1,13.69,15,1,13.11,100,1,13.72,15,1,13.03,100,1,13.73,100,1,13,2,1,13.87,200,1,12.73,100,1,14,100,1,12.71,100,1,14.03,2,1,12.5,700,1,14.28,100,1,12.46,200,1,14.45,100,1,12.43,700,1,14.52,100,1,12.42,700,1,14.56,800,1,ARL,326836085
1793,2025-07-17T16:03:16.351845457Z,2025-07-17T16:03:16.351845457Z,10,2,1108,C,A,0,13.730000000,100,0,166374,272557789,13.12,200,1,13.69,15,1,13.11,100,1,13.72,15,1,13.03,100,1,13.87,200,1,13,2,1,14,100,1,12.73,100,1,14.03,2,1,12.71,100,1,14.28,100,1,12.5,700,1,14.45,100,1,12.46,200,1,14.52,100,1,12.43,700,1,14.56,800,1,12.42,700,1,14.58,200,1,ARL,326729685
1794,2025-07-17T16:03:16.351845457Z,2025-07-17T16:03:16.351845457Z,10,2,1108,A,A,0,13.700000000,100,130,166374,272557789,13.12,200,1,13.69,15,1,13.11,100,1,13.7,100,1,13.03,100,1,13.72,15,1,13,2,1,13.87,200,1,12.73,100,1,14,100,1,12.71,100,1,14.03,2,1,12.5,700,1,14.28,100,1,12.46,200,1,14.45,100,1,12.43,700,1,14.52,100,1,12.42,700,1,14.56,800,1,ARL,326836533
1795,2025-07-17T16:03:16.365819243Z,2025-07-17T16:03:16.365819243Z,10,2,1108,C,A,0,15.380000000,100,0,165919,272559024,13.12,200,1,13.69,15,1,13.11,100,1,13.7,100,1,13.03,100,1,13.72,15,1,13,2,1,13.87,200,1,12.73,100,1,14,100,1,12.71,100,1,14.03,2,1,12.5,700,1,14.28,100,1,12.46,200,1,14.45,100,1,12.43,700,1,14.52,100,1,12.42,700,1,14.56,800,1,ARL,325714965
1796,2025-07-17T16:03:16.365819243Z,2025-07-17T16:03:16.365819243Z,10,2,1108,A,A,0,15.070000000,100,130,165919,272559024,13.12,200,1,13.69,15,1,13.11,100,1,13.7,100,1,13.03,100,1,13.72,15,1,13,2,1,13.87,200,1,12.73,100,1,14,100,1,12.71,100,1,14.03,2,1,12.5,700,1,14.28,100,1,12.46,200,1,14.45,100,1,12.43,700,1,14.52,100,1,12.42,700,1,14.56,800,1,ARL,326837501
1797,2025-07-17T16:03:18.804159952Z,2025-07-17T16:03:18.804159952Z,10,2,1108,C,A,0,13.690000000,15,130,165126,272609485,13.12,200,1,13.7,100,1,13.11,100,1,13.72,15,1,13.03,100,1,13.87,200,1,13,2,1,14,100,1,12.73,100,1,14.03,2,1,12.71,100,1,14.28,100,1,12.5,700,1,14.45,100,1,12.46,200,1,14.52,100,1,12.43,700,1,14.56,800,1,12.42,700,1,14.58,200,1,ARL,326835877
1798,2025-07-17T16:03:18.804202246Z,2025-07-17T16:03:18.804202246Z,10,2,1108,C,A,0,13.700000000,100,130,165314,272609486,13.12,200,1,13.72,15,1,13.11,100,1,13.87,200,1,13.03,100,1,14,100,1,13,2,1,14.03,2,1,12.73,100,1,14.28,100,1,12.71,100,1,14.45,100,1,12.5,700,1,14.52,100,1,12.46,200,1,14.56,800,1,12.43,700,1,14.58,200,1,12.42,700,1,14.6,700,1,ARL,326836533
1799,2025-07-17T16:03:18.804933488Z,2025-07-17T16:03:18.804933488Z,10,2,1108,C,A,0,14.790000000,100,0,165630,272609510,13.12,200,1,13.72,15,1,13.11,100,1,13.87,200,1,13.03,100,1,14,100,1,13,2,1,14.03,2,1,12.73,100,1,14.28,100,1,12.71,100,1,14.45,100,1,12.5,700,1,14.52,100,1,12.46,200,1,14.56,800,1,12.43,700,1,14.58,200,1,12.42,700,1,14.6,700,1,ARL,326729705
1800,2025-07-17T16:03:18.804933488Z,2025-07-17T16:03:18.804933488Z,10,2,1108,A,A,0,14.950000000,100,130,165630,272609510,13.12,200,1,13.72,15,1,13.11,100,1,13.87,200,1,13.03,100,1,14,100,1,13,2,1,14.03,2,1,12.73,100,1,14.28,100,1,12.71,100,1,14.45,100,1,12.5,700,1,14.52,100,1,12.46,200,1,14.56,800,1,12.43,700,1,14.58,200,1,12.42,700,1,14.6,700,1,ARL,326892717
1801,2025-07-17T16:03:18.805126035Z,2025-07-17T16:03:18.805126035Z,10,2,1108,C,A,0,14.700000000,100,0,165594,272609526,13.12,200,1,13.72,15,1,13.11,100,1,13.87,200,1,13.03,100,1,14,100,1,13,2,1,14.03,2,1,12.73,100,1,14.28,100,1,12.71,100,1,14.45,100,1,12.5,700,1,14.52,100,1,12.46,200,1,14.56,800,1,12.43,700,1,14.58,200,1,12.42,700,1,14.6,700,1,ARL,326729721
1802,2025-07-17T16:03:18.805126035Z,2025-07-17T16:03:18.805126035Z,10,2,1108,A,A,0,14.850000000,100,130,165594,272609526,13.12,200,1,13.72,15,1,13.11,100,1,13.87,200,1,13.03,100,1,14,100,1,13,2,1,14.03,2,1,12.73,100,1,14.28,100,1,12.71,100,1,14.45,100,1,12.5,700,1,14.52,100,1,12.46,200,1,14.56,800,1,12.43,700,1,14.58,200,1,12.42,700,1,14.6,700,1,ARL,326892721
1803,2025-07-17T16:03:18.805283236Z,2025-07-17T16:03:18.805283236Z,10,2,1108,C,A,0,13.720000000,15,130,165853,272609541,13.12,200,1,13.87,200,1,13.11,100,1,14,100,1,13.03,100,1,14.03,2,1,13,2,1,14.28,100,1,12.73,100,1,14.45,100,1,12.71,100,1,14.52,100,1,12.5,700,1,14.56,800,1,12.46,200,1,14.58,200,1,12.43,700,1,14.6,700,1,12.42,700,1,14.68,1400,1,ARL,326729677
1804,2025-07-17T16:03:18.806370373Z,2025-07-17T16:03:18.806370373Z,10,2,1108,C,A,0,14.580000000,100,0,165530,272609577,13.12,200,1,13.87,200,1,13.11,100,1,14,100,1,13.03,100,1,14.03,2,1,13,2,1,14.28,100,1,12.73,100,1,14.45,100,1,12.71,100,1,14.52,100,1,12.5,700,1,14.56,800,1,12.46,200,1,14.58,100,1,12.43,700,1,14.6,700,1,12.42,700,1,14.68,1400,1,ARL,326835885
1805,2025-07-17T16:03:18.806370373Z,2025-07-17T16:03:18.806370373Z,10,2,1108,A,A,0,14.760000000,100,130,165530,272609577,13.12,200,1,13.87,200,1,13.11,100,1,14,100,1,13.03,100,1,14.03,2,1,13,2,1,14.28,100,1,12.73,100,1,14.45,100,1,12.71,100,1,14.52,100,1,12.5,700,1,14.56,800,1,12.46,200,1,14.58,100,1,12.43,700,1,14.6,700,1,12.42,700,1,14.68,1400,1,ARL,326892817
1806,2025-07-17T16:03:18.806637004Z,2025-07-17T16:03:18.806637004Z,10,2,1108,C,A,0,14.580000000,100,0,165585,272609583,13.12,200,1,13.87,200,1,13.11,100,1,14,100,1,13.03,100,1,14.03,2,1,13,2,1,14.28,100,1,12.73,100,1,14.45,100,1,12.71,100,1,14.52,100,1,12.5,700,1,14.56,800,1,12.46,200,1,14.6,700,1,12.43,700,1,14.68,1400,1,12.42,700,1,14.7,100,1,ARL,326836085
1807,2025-07-17T16:03:18.806637004Z,2025-07-17T16:03:18.806637004Z,10,2,1108,A,A,0,14.760000000,100,130,165585,272609583,13.12,200,1,13.87,200,1,13.11,100,1,14,100,1,13.03,100,1,14.03,2,1,13,2,1,14.28,100,1,12.73,100,1,14.45,100,1,12.71,100,1,14.52,100,1,12.5,700,1,14.56,800,1,12.46,200,1,14.6,700,1,12.43,700,1,14.68,1400,1,12.42,700,1,14.7,100,1,ARL,326892825
1808,2025-07-17T16:03:18.809540733Z,2025-07-17T16:03:18.809540733Z,10,2,1108,C,A,0,14.520000000,100,0,165601,272609656,13.12,200,1,13.87,200,1,13.11,100,1,14,100,1,13.03,100,1,14.03,2,1,13,2,1,14.28,100,1,12.73,100,1,14.45,100,1,12.71,100,1,14.56,800,1,12.5,700,1,14.6,700,1,12.46,200,1,14.68,1400,1,12.43,700,1,14.7,100,1,12.42,700,1,14.76,200,1,ARL,326729729
1809,2025-07-17T16:03:18.809540733Z,2025-07-17T16:03:18.809540733Z,10,2,1108,A,A,0,14.660000000,100,130,165601,272609656,13.12,200,1,13.87,200,1,13.11,100,1,14,100,1,13.03,100,1,14.03,2,1,13,2,1,14.28,100,1,12.73,100,1,14.45,100,1,12.71,100,1,14.56,800,1,12.5,700,1,14.6,700,1,12.46,200,1,14.66,100,1,12.43,700,1,14.68,1400,1,12.42,700,1,14.7,100,1,ARL,326892885
1810,2025-07-17T16:03:18.809683187Z,2025-07-17T16:03:18.809683187Z,10,2,1108,C,A,0,15.790000000,100,0,165478,272609658,13.12,200,1,13.87,200,1,13.11,100,1,14,100,1,13.03,100,1,14.03,2,1,13,2,1,14.28,100,1,12.73,100,1,14.45,100,1,12.71,100,1,14.56,800,1,12.5,700,1,14.6,700,1,12.46,200,1,14.66,100,1,12.43,700,1,14.68,1400,1,12.42,700,1,14.7,100,1,ARL,326729733
1811,2025-07-17T16:03:18.809683187Z,2025-07-17T16:03:18.809683187Z,10,2,1108,A,A,0,15.960000000,100,130,165478,272609658,13.12,200,1,13.87,200,1,13.11,100,1,14,100,1,13.03,100,1,14.03,2,1,13,2,1,14.28,100,1,12.73,100,1,14.45,100,1,12.71,100,1,14.56,800,1,12.5,700,1,14.6,700,1,12.46,200,1,14.66,100,1,12.43,700,1,14.68,1400,1,12.42,700,1,14.7,100,1,ARL,326892889
1812,2025-07-17T16:03:18.811941680Z,2025-07-17T16:03:18.811941680Z,10,2,1108,C,A,0,17.440000000,100,0,165526,272609679,13.12,200,1,13.87,200,1,13.11,100,1,14,100,1,13.03,100,1,14.03,2,1,13,2,1,14.28,100,1,12.73,100,1,14.45,100,1,12.71,100,1,14.56,800,1,12.5,700,1,14.6,700,1,12.46,200,1,14.66,100,1,12.43,700,1,14.68,1400,1,12.42,700,1,14.7,100,1,ARL,326729725
1813,2025-07-17T16:03:18.811941680Z,2025-07-17T16:03:18.811941680Z,10,2,1108,A,A,0,17.620000000,100,130,165526,272609679,13.12,200,1,13.87,200,1,13.11,100,1,14,100,1,13.03,100,1,14.03,2,1,13,2,1,14.28,100,1,12.73,100,1,14.45,100,1,12.71,100,1,14.56,800,1,12.5,700,1,14.6,700,1,12.46,200,1,14.66,100,1,12.43,700,1,14.68,1400,1,12.42,700,1,14.7,100,1,ARL,326892921
1814,2025-07-17T16:03:18.818080239Z,2025-07-17T16:03:18.818080239Z,10,2,1108,C,A,0,14.000000000,100,130,165390,272609768,13.12,200,1,13.87,200,1,13.11,100,1,14.03,2,1,13.03,100,1,14.28,100,1,13,2,1,14.45,100,1,12.73,100,1,14.56,800,1,12.71,100,1,14.6,700,1,12.5,700,1,14.66,100,1,12.46,200,1,14.68,1400,1,12.43,700,1,14.7,100,1,12.42,700,1,14.76,200,1,ARL,326729929
1815,2025-07-17T16:03:18.818135688Z,2025-07-17T16:03:18.818135688Z,10,2,1108,A,A,0,14.150000000,100,130,165455,272609769,13.12,200,1,13.87,200,1,13.11,100,1,14.03,2,1,13.03,100,1,14.15,100,1,13,2,1,14.28,100,1,12.73,100,1,14.45,100,1,12.71,100,1,14.56,800,1,12.5,700,1,14.6,700,1,12.46,200,1,14.66,100,1,12.43,700,1,14.68,1400,1,12.42,700,1,14.7,100,1,ARL,326893213
1816,2025-07-17T16:03:18.868254768Z,2025-07-17T16:03:18.868254768Z,10,2,1108,C,A,0,14.700000000,100,0,165735,272610397,13.12,200,1,13.87,200,1,13.11,100,1,14.03,2,1,13.03,100,1,14.15,100,1,13,2,1,14.28,100,1,12.73,100,1,14.45,100,1,12.71,100,1,14.56,800,1,12.5,700,1,14.6,700,1,12.46,200,1,14.66,100,1,12.43,700,1,14.68,1400,1,12.42,700,1,14.76,200,1,ARL,326729821
1817,2025-07-17T16:03:18.868254768Z,2025-07-17T16:03:18.868254768Z,10,2,1108,A,A,0,14.850000000,100,130,165735,272610397,13.12,200,1,13.87,200,1,13.11,100,1,14.03,2,1,13.03,100,1,14.15,100,1,13,2,1,14.28,100,1,12.73,100,1,14.45,100,1,12.71,100,1,14.56,800,1,12.5,700,1,14.6,700,1,12.46,200,1,14.66,100,1,12.43,700,1,14.68,1400,1,12.42,700,1,14.76,200,1,ARL,326893961
1818,2025-07-17T16:03:19.191054306Z,2025-07-17T16:03:19.191054306Z,10,2,1108,A,A,0,13.880000000,100,130,165201,272614303,13.12,200,1,13.87,200,1,13.11,100,1,13.88,100,1,13.03,100,1,14.03,2,1,13,2,1,14.15,100,1,12.73,100,1,14.28,100,1,12.71,100,1,14.45,100,1,12.5,700,1,14.56,800,1,12.46,200,1,14.6,700,1,12.43,700,1,14.66,100,1,12.42,700,1,14.68,1400,1,ARL,326899125
1819,2025-07-17T16:03:27.433791643Z,2025-07-17T16:03:27.433791643Z,10,2,1108,T,N,0,13.280000000,40,130,166289,272788756,13.12,200,1,13.87,200,1,13.11,100,1,13.88,100,1,13.03,100,1,14.03,2,1,13,2,1,14.15,100,1,12.73,100,1,14.28,100,1,12.71,100,1,14.45,100,1,12.5,700,1,14.56,800,1,12.46,200,1,14.6,700,1,12.43,700,1,14.66,100,1,12.42,700,1,14.68,1400,1,ARL,0
1820,2025-07-17T16:03:27.436158395Z,2025-07-17T16:03:27.436158395Z,10,2,1108,A,A,0,14.250000000,53,130,165556,272788767,13.12,200,1,13.87,200,1,13.11,100,1,13.88,100,1,13.03,100,1,14.03,2,1,13,2,1,14.15,100,1,12.73,100,1,14.25,53,1,12.71,100,1,14.28,100,1,12.5,700,1,14.45,100,1,12.46,200,1,14.56,800,1,12.43,700,1,14.6,700,1,12.42,700,1,14.66,100,1,ARL,327112281
1821,2025-07-17T16:03:27.436715001Z,2025-07-17T16:03:27.436715001Z,10,2,1108,C,B,0,12.230000000,100,0,165767,272788774,13.12,200,1,13.87,200,1,13.11,100,1,13.88,100,1,13.03,100,1,14.03,2,1,13,2,1,14.15,100,1,12.73,100,1,14.25,53,1,12.71,100,1,14.28,100,1,12.5,700,1,14.45,100,1,12.46,200,1,14.56,800,1,12.43,700,1,14.6,700,1,12.42,700,1,14.66,100,1,ARL,291964745
1822,2025-07-17T16:03:27.436715001Z,2025-07-17T16:03:27.436715001Z,10,2,1108,A,B,0,12.100000000,100,130,165767,272788774,13.12,200,1,13.87,200,1,13.11,100,1,13.88,100,1,13.03,100,1,14.03,2,1,13,2,1,14.15,100,1,12.73,100,1,14.25,53,1,12.71,100,1,14.28,100,1,12.5,700,1,14.45,100,1,12.46,200,1,14.56,800,1,12.43,700,1,14.6,700,1,12.42,700,1,14.66,100,1,ARL,327112289
1823,2025-07-17T16:03:27.438400828Z,2025-07-17T16:03:27.438400828Z,10,2,1108,C,B,0,12.340000000,100,0,166143,272788792,13.12,200,1,13.87,200,1,13.11,100,1,13.88,100,1,13.03,100,1,14.03,2,1,13,2,1,14.15,100,1,12.73,100,1,14.25,53,1,12.71,100,1,14.28,100,1,12.5,700,1,14.45,100,1,12.46,200,1,14.56,800,1,12.43,700,1,14.6,700,1,12.42,700,1,14.66,100,1,ARL,285586113
1824,2025-07-17T16:03:27.438400828Z,2025-07-17T16:03:27.438400828Z,10,2,1108,A,B,0,12.200000000,100,130,166143,272788792,13.12,200,1,13.87,200,1,13.11,100,1,13.88,100,1,13.03,100,1,14.03,2,1,13,2,1,14.15,100,1,12.73,100,1,14.25,53,1,12.71,100,1,14.28,100,1,12.5,700,1,14.45,100,1,12.46,200,1,14.56,800,1,12.43,700,1,14.6,700,1,12.42,700,1,14.66,100,1,ARL,327112385
1825,2025-07-17T16:03:27.438437969Z,2025-07-17T16:03:27.438437969Z,10,2,1108,C,B,0,12.340000000,100,0,165595,272788793,13.12,200,1,13.87,200,1,13.11,100,1,13.88,100,1,13.03,100,1,14.03,2,1,13,2,1,14.15,100,1,12.73,100,1,14.25,53,1,12.71,100,1,14.28,100,1,12.5,700,1,14.45,100,1,12.46,200,1,14.56,800,1,12.43,700,1,14.6,700,1,12.42,700,1,14.66,100,1,ARL,285586189
1826,2025-07-17T16:03:27.438437969Z,2025-07-17T16:03:27.438437969Z,10,2,1108,A,B,0,12.200000000,100,130,165595,272788793,13.12,200,1,13.87,200,1,13.11,100,1,13.88,100,1,13.03,100,1,14.03,2,1,13,2,1,14.15,100,1,12.73,100,1,14.25,53,1,12.71,100,1,14.28,100,1,12.5,700,1,14.45,100,1,12.46,200,1,14.56,800,1,12.43,700,1,14.6,700,1,12.42,700,1,14.66,100,1,ARL,327112393
1827,2025-07-17T16:03:27.453845141Z,2025-07-17T16:03:27.453845141Z,10,2,1108,C,B,0,13.030000000,100,130,165214,272788897,13.12,200,1,13.87,200,1,13.11,100,1,13.88,100,1,13,2,1,14.03,2,1,12.73,100,1,14.15,100,1,12.71,100,1,14.25,53,1,12.5,700,1,14.28,100,1,12.46,200,1,14.45,100,1,12.43,700,1,14.56,800,1,12.42,700,1,14.6,700,1,12.37,700,1,14.66,100,1,ARL,285586293
1828,2025-07-17T16:03:27.453894425Z,2025-07-17T16:03:27.453894425Z,10,2,1108,A,B,0,12.950000000,100,130,165294,272788898,13.12,200,1,13.87,200,1,13.11,100,1,13.88,100,1,13,2,1,14.03,2,1,12.95,100,1,14.15,100,1,12.73,100,1,14.25,53,1,12.71,100,1,14.28,100,1,12.5,700,1,14.45,100,1,12.46,200,1,14.56,800,1,12.43,700,1,14.6,700,1,12.42,700,1,14.66,100,1,ARL,327112565
1829,2025-07-17T16:03:27.454726901Z,2025-07-17T16:03:27.454726901Z,10,2,1108,C,B,0,12.950000000,100,130,165420,272788942,13.12,200,1,13.87,200,1,13.11,100,1,13.88,100,1,13,2,1,14.03,2,1,12.73,100,1,14.15,100,1,12.71,100,1,14.25,53,1,12.5,700,1,14.28,100,1,12.46,200,1,14.45,100,1,12.43,700,1,14.56,800,1,12.42,700,1,14.6,700,1,12.37,700,1,14.66,100,1,ARL,327112565
1830,2025-07-17T16:03:27.454773691Z,2025-07-17T16:03:27.454773691Z,10,2,1108,A,B,0,12.860000000,100,130,165909,272788943,13.12,200,1,13.87,200,1,13.11,100,1,13.88,100,1,13,2,1,14.03,2,1,12.86,100,1,14.15,100,1,12.73,100,1,14.25,53,1,12.71,100,1,14.28,100,1,12.5,700,1,14.45,100,1,12.46,200,1,14.56,800,1,12.43,700,1,14.6,700,1,12.42,700,1,14.66,100,1,ARL,327112577
1831,2025-07-17T16:03:27.517585374Z,2025-07-17T16:03:27.517585374Z,10,2,1108,C,B,0,12.460000000,100,130,165896,272790695,13.12,200,1,13.87,200,1,13.11,100,1,13.88,100,1,13,2,1,14.03,2,1,12.86,100,1,14.15,100,1,12.73,100,1,14.25,53,1,12.71,100,1,14.28,100,1,12.5,700,1,14.45,100,1,12.46,100,1,14.56,800,1,12.43,700,1,14.6,700,1,12.42,700,1,14.66,100,1,ARL,285587281
1832,2025-07-17T16:03:27.517699408Z,2025-07-17T16:03:27.517699408Z,10,2,1108,A,B,0,12.330000000,100,130,165267,272790696,13.12,200,1,13.87,200,1,13.11,100,1,13.88,100,1,13,2,1,14.03,2,1,12.86,100,1,14.15,100,1,12.73,100,1,14.25,53,1,12.71,100,1,14.28,100,1,12.5,700,1,14.45,100,1,12.46,100,1,14.56,800,1,12.43,700,1,14.6,700,1,12.42,700,1,14.66,100,1,ARL,327114465
1833,2025-07-17T16:03:27.536178718Z,2025-07-17T16:03:27.536178718Z,10,2,1108,C,A,0,14.250000000,53,130,165225,272791410,13.12,200,1,13.87,200,1,13.11,100,1,13.88,100,1,13,2,1,14.03,2,1,12.86,100,1,14.15,100,1,12.73,100,1,14.28,100,1,12.71,100,1,14.45,100,1,12.5,700,1,14.56,800,1,12.46,100,1,14.6,700,1,12.43,700,1,14.66,100,1,12.42,700,1,14.68,1400,1,ARL,327112281
1834,2025-07-17T16:03:56.548182793Z,2025-07-17T16:03:56.548182793Z,10,2,1108,A,A,0,13.800000000,15,130,165254,273208310,13.12,200,1,13.8,15,1,13.11,100,1,13.87,200,1,13,2,1,13.88,100,1,12.86,100,1,14.03,2,1,12.73,100,1,14.15,100,1,12.71,100,1,14.28,100,1,12.5,700,1,14.45,100,1,12.46,100,1,14.56,800,1,12.43,700,1,14.6,700,1,12.42,700,1,14.66,100,1,ARL,327675057
1835,2025-07-17T16:03:56.548446336Z,2025-07-17T16:03:56.548446336Z,10,2,1108,C,A,0,13.880000000,100,0,165380,273208316,13.12,200,1,13.8,15,1,13.11,100,1,13.87,200,1,13,2,1,14.03,2,1,12.86,100,1,14.15,100,1,12.73,100,1,14.28,100,1,12.71,100,1,14.45,100,1,12.5,700,1,14.56,800,1,12.46,100,1,14.6,700,1,12.43,700,1,14.66,100,1,12.42,700,1,14.68,1400,1,ARL,326899125
1836,2025-07-17T16:03:56.548446336Z,2025-07-17T16:03:56.548446336Z,10,2,1108,A,A,0,13.810000000,100,130,165380,273208316,13.12,200,1,13.8,15,1,13.11,100,1,13.81,100,1,13,2,1,13.87,200,1,12.86,100,1,14.03,2,1,12.73,100,1,14.15,100,1,12.71,100,1,14.28,100,1,12.5,700,1,14.45,100,1,12.46,100,1,14.56,800,1,12.43,700,1,14.6,700,1,12.42,700,1,14.66,100,1,ARL,327675065
1837,2025-07-17T16:03:56.549188993Z,2025-07-17T16:03:56.549188993Z,10,2,1108,C,A,0,14.950000000,100,0,165412,273208325,13.12,200,1,13.8,15,1,13.11,100,1,13.81,100,1,13,2,1,13.87,200,1,12.86,100,1,14.03,2,1,12.73,100,1,14.15,100,1,12.71,100,1,14.28,100,1,12.5,700,1,14.45,100,1,12.46,100,1,14.56,800,1,12.43,700,1,14.6,700,1,12.42,700,1,14.66,100,1,ARL,326892717
1838,2025-07-17T16:03:56.549188993Z,2025-07-17T16:03:56.549188993Z,10,2,1108,A,A,0,14.880000000,100,130,165412,273208325,13.12,200,1,13.8,15,1,13.11,100,1,13.81,100,1,13,2,1,13.87,200,1,12.86,100,1,14.03,2,1,12.73,100,1,14.15,100,1,12.71,100,1,14.28,100,1,12.5,700,1,14.45,100,1,12.46,100,1,14.56,800,1,12.43,700,1,14.6,700,1,12.42,700,1,14.66,100,1,ARL,327675093
1839,2025-07-17T16:04:06.233692491Z,2025-07-17T16:04:06.233692491Z,10,2,1108,C,A,0,14.760000000,100,0,166120,273345719,13.12,200,1,13.8,15,1,13.11,100,1,13.81,100,1,13,2,1,13.87,200,1,12.86,100,1,14.03,2,1,12.73,100,1,14.15,100,1,12.71,100,1,14.28,100,1,12.5,700,1,14.45,100,1,12.46,100,1,14.56,800,1,12.43,700,1,14.6,700,1,12.42,700,1,14.66,100,1,ARL,326892825
1840,2025-07-17T16:04:06.233692491Z,2025-07-17T16:04:06.233692491Z,10,2,1108,A,A,0,14.640000000,100,130,166120,273345719,13.12,200,1,13.8,15,1,13.11,100,1,13.81,100,1,13,2,1,13.87,200,1,12.86,100,1,14.03,2,1,12.73,100,1,14.15,100,1,12.71,100,1,14.28,100,1,12.5,700,1,14.45,100,1,12.46,100,1,14.56,800,1,12.43,700,1,14.6,700,1,12.42,700,1,14.64,100,1,ARL,327856297
1841,2025-07-17T16:04:06.234433294Z,2025-07-17T16:04:06.234433294Z,10,2,1108,C,A,0,14.760000000,100,0,166904,273345721,13.12,200,1,13.8,15,1,13.11,100,1,13.81,100,1,13,2,1,13.87,200,1,12.86,100,1,14.03,2,1,12.73,100,1,14.15,100,1,12.71,100,1,14.28,100,1,12.5,700,1,14.45,100,1,12.46,100,1,14.56,800,1,12.43,700,1,14.6,700,1,12.42,700,1,14.64,100,1,ARL,326892817
1842,2025-07-17T16:04:06.234433294Z,2025-07-17T16:04:06.234433294Z,10,2,1108,A,A,0,14.640000000,100,130,166904,273345721,13.12,200,1,13.8,15,1,13.11,100,1,13.81,100,1,13,2,1,13.87,200,1,12.86,100,1,14.03,2,1,12.73,100,1,14.15,100,1,12.71,100,1,14.28,100,1,12.5,700,1,14.45,100,1,12.46,100,1,14.56,800,1,12.43,700,1,14.6,700,1,12.42,700,1,14.64,200,1,ARL,327856309
1843,2025-07-17T16:04:06.510748731Z,2025-07-17T16:04:06.510748731Z,10,2,1108,A,A,0,13.720000000,15,130,165370,273352664,13.12,200,1,13.72,15,1,13.11,100,1,13.8,15,1,13,2,1,13.81,100,1,12.86,100,1,13.87,200,1,12.73,100,1,14.03,2,1,12.71,100,1,14.15,100,1,12.5,700,1,14.28,100,1,12.46,100,1,14.45,100,1,12.43,700,1,14.56,800,1,12.42,700,1,14.6,700,1,ARL,327863853
1844,2025-07-17T16:04:06.512244746Z,2025-07-17T16:04:06.512244746Z,10,2,1108,C,A,0,13.810000000,100,0,168356,273352888,13.12,200,1,13.72,15,1,13.11,100,1,13.8,15,1,13,2,1,13.87,200,1,12.86,100,1,14.03,2,1,12.73,100,1,14.15,100,1,12.71,100,1,14.28,100,1,12.5,700,1,14.45,100,1,12.46,100,1,14.56,800,1,12.43,700,1,14.6,700,1,12.42,700,1,14.64,200,1,ARL,327675065
1845,2025-07-17T16:04:06.512244746Z,2025-07-17T16:04:06.512244746Z,10,2,1108,A,A,0,13.730000000,100,128,168356,273352888,13.12,200,1,13.72,15,1,13.11,100,1,13.73,100,1,13,2,1,13.8,15,1,12.86,100,1,13.87,200,1,12.73,100,1,14.03,2,1,12.71,100,1,14.15,100,1,12.5,700,1,14.28,100,1,12.46,100,1,14.45,100,1,12.43,700,1,14.56,800,1,12.42,700,1,14.6,700,1,ARL,327864137
1846,2025-07-17T16:04:06.513497276Z,2025-07-17T16:04:06.513497276Z,10,2,1108,C,A,0,14.880000000,100,0,178023,273353923,13.12,200,1,13.72,15,1,13.11,100,1,13.73,100,1,13,2,1,13.8,15,1,12.86,100,1,13.87,200,1,12.73,100,1,14.03,2,1,12.71,100,1,14.15,100,1,12.5,700,1,14.28,100,1,12.46,100,1,14.45,100,1,12.43,700,1,14.56,800,1,12.42,700,1,14.6,700,1,ARL,327675093
1847,2025-07-17T16:04:06.513497276Z,2025-07-17T16:04:06.513497276Z,10,2,1108,A,A,0,14.790000000,100,128,178023,273353923,13.12,200,1,13.72,15,1,13.11,100,1,13.73,100,1,13,2,1,13.8,15,1,12.86,100,1,13.87,200,1,12.73,100,1,14.03,2,1,12.71,100,1,14.15,100,1,12.5,700,1,14.28,100,1,12.46,100,1,14.45,100,1,12.43,700,1,14.56,800,1,12.42,700,1,14.6,700,1,ARL,327864893
1848,2025-07-17T16:04:06.522687474Z,2025-07-17T16:04:06.522687474Z,10,2,1108,C,A,0,14.850000000,100,0,165687,273357758,13.12,200,1,13.72,15,1,13.11,100,1,13.73,100,1,13,2,1,13.8,15,1,12.86,100,1,13.87,200,1,12.73,100,1,14.03,2,1,12.71,100,1,14.15,100,1,12.5,700,1,14.28,100,1,12.46,100,1,14.45,100,1,12.43,700,1,14.56,800,1,12.42,700,1,14.6,700,1,ARL,326892721
1849,2025-07-17T16:04:06.522687474Z,2025-07-17T16:04:06.522687474Z,10,2,1108,A,A,0,14.700000000,100,130,165687,273357758,13.12,200,1,13.72,15,1,13.11,100,1,13.73,100,1,13,2,1,13.8,15,1,12.86,100,1,13.87,200,1,12.73,100,1,14.03,2,1,12.71,100,1,14.15,100,1,12.5,700,1,14.28,100,1,12.46,100,1,14.45,100,1,12.43,700,1,14.56,800,1,12.42,700,1,14.6,700,1,ARL,327868421
1850,2025-07-17T16:04:06.525385108Z,2025-07-17T16:04:06.525385108Z,10,2,1108,C,A,0,14.150000000,100,130,165707,273358260,13.12,200,1,13.72,15,1,13.11,100,1,13.73,100,1,13,2,1,13.8,15,1,12.86,100,1,13.87,200,1,12.73,100,1,14.03,2,1,12.71,100,1,14.28,100,1,12.5,700,1,14.45,100,1,12.46,100,1,14.56,800,1,12.43,700,1,14.6,700,1,12.42,700,1,14.64,200,1,ARL,326893213
1851,2025-07-17T16:04:06.525442486Z,2025-07-17T16:04:06.525442486Z,10,2,1108,A,A,0,14.000000000,100,128,166260,273358273,13.12,200,1,13.72,15,1,13.11,100,1,13.73,100,1,13,2,1,13.8,15,1,12.86,100,1,13.87,200,1,12.73,100,1,14,100,1,12.71,100,1,14.03,2,1,12.5,700,1,14.28,100,1,12.46,100,1,14.45,100,1,12.43,700,1,14.56,800,1,12.42,700,1,14.6,700,1,ARL,327869193
1852,2025-07-17T16:04:06.528043934Z,2025-07-17T16:04:06.528043934Z,10,2,1108,C,A,0,14.660000000,100,130,166821,273358598,13.12,200,1,13.72,15,1,13.11,100,1,13.73,100,1,13,2,1,13.8,15,1,12.86,100,1,13.87,200,1,12.73,100,1,14,100,1,12.71,100,1,14.03,2,1,12.5,700,1,14.28,100,1,12.46,100,1,14.45,100,1,12.43,700,1,14.56,800,1,12.42,700,1,14.6,700,1,ARL,326892885
1853,2025-07-17T16:04:06.528161631Z,2025-07-17T16:04:06.528161631Z,10,2,1108,A,A,0,14.520000000,100,128,167417,273358642,13.12,200,1,13.72,15,1,13.11,100,1,13.73,100,1,13,2,1,13.8,15,1,12.86,100,1,13.87,200,1,12.73,100,1,14,100,1,12.71,100,1,14.03,2,1,12.5,700,1,14.28,100,1,12.46,100,1,14.45,100,1,12.43,700,1,14.52,100,1,12.42,700,1,14.56,800,1,ARL,327869529
1854,2025-07-17T16:04:06.543314706Z,2025-07-17T16:04:06.543314706Z,10,2,1108,C,A,0,17.620000000,100,0,165606,273359491,13.12,200,1,13.72,15,1,13.11,100,1,13.73,100,1,13,2,1,13.8,15,1,12.86,100,1,13.87,200,1,12.73,100,1,14,100,1,12.71,100,1,14.03,2,1,12.5,700,1,14.28,100,1,12.46,100,1,14.45,100,1,12.43,700,1,14.52,100,1,12.42,700,1,14.56,800,1,ARL,326892921
1855,2025-07-17T16:04:06.543314706Z,2025-07-17T16:04:06.543314706Z,10,2,1108,A,A,0,17.440000000,100,130,165606,273359491,13.12,200,1,13.72,15,1,13.11,100,1,13.73,100,1,13,2,1,13.8,15,1,12.86,100,1,13.87,200,1,12.73,100,1,14,100,1,12.71,100,1,14.03,2,1,12.5,700,1,14.28,100,1,12.46,100,1,14.45,100,1,12.43,700,1,14.52,100,1,12.42,700,1,14.56,800,1,ARL,327870217
1856,2025-07-17T16:04:06.548778200Z,2025-07-17T16:04:06.548778200Z,10,2,1108,C,A,0,15.960000000,100,0,167039,273359672,13.12,200,1,13.72,15,1,13.11,100,1,13.73,100,1,13,2,1,13.8,15,1,12.86,100,1,13.87,200,1,12.73,100,1,14,100,1,12.71,100,1,14.03,2,1,12.5,700,1,14.28,100,1,12.46,100,1,14.45,100,1,12.43,700,1,14.52,100,1,12.42,700,1,14.56,800,1,ARL,326892889
1857,2025-07-17T16:04:06.548778200Z,2025-07-17T16:04:06.548778200Z,10,2,1108,A,A,0,15.790000000,100,130,167039,273359672,13.12,200,1,13.72,15,1,13.11,100,1,13.73,100,1,13,2,1,13.8,15,1,12.86,100,1,13.87,200,1,12.73,100,1,14,100,1,12.71,100,1,14.03,2,1,12.5,700,1,14.28,100,1,12.46,100,1,14.45,100,1,12.43,700,1,14.52,100,1,12.42,700,1,14.56,800,1,ARL,327870361
1858,2025-07-17T16:04:06.647944313Z,2025-07-17T16:04:06.647944313Z,10,2,1108,C,A,0,14.850000000,100,0,165516,273361957,13.12,200,1,13.72,15,1,13.11,100,1,13.73,100,1,13,2,1,13.8,15,1,12.86,100,1,13.87,200,1,12.73,100,1,14,100,1,12.71,100,1,14.03,2,1,12.5,700,1,14.28,100,1,12.46,100,1,14.45,100,1,12.43,700,1,14.52,100,1,12.42,700,1,14.56,800,1,ARL,326893961
1859,2025-07-17T16:04:06.647944313Z,2025-07-17T16:04:06.647944313Z,10,2,1108,A,A,0,14.700000000,100,130,165516,273361957,13.12,200,1,13.72,15,1,13.11,100,1,13.73,100,1,13,2,1,13.8,15,1,12.86,100,1,13.87,200,1,12.73,100,1,14,100,1,12.71,100,1,14.03,2,1,12.5,700,1,14.28,100,1,12.46,100,1,14.45,100,1,12.43,700,1,14.52,100,1,12.42,700,1,14.56,800,1,ARL,327873009
1860,2025-07-17T16:04:06.805335354Z,2025-07-17T16:04:06.805335354Z,10,2,1108,C,A,0,13.720000000,15,130,165169,273364089,13.12,200,1,13.73,100,1,13.11,100,1,13.8,15,1,13,2,1,13.87,200,1,12.86,100,1,14,100,1,12.73,100,1,14.03,2,1,12.71,100,1,14.28,100,1,12.5,700,1,14.45,100,1,12.46,100,1,14.52,100,1,12.43,700,1,14.56,800,1,12.42,700,1,14.6,700,1,ARL,327863853
1861,2025-07-17T16:04:06.806052396Z,2025-07-17T16:04:06.806052396Z,10,2,1108,C,A,0,13.800000000,15,130,165188,273364090,13.12,200,1,13.73,100,1,13.11,100,1,13.87,200,1,13,2,1,14,100,1,12.86,100,1,14.03,2,1,12.73,100,1,14.28,100,1,12.71,100,1,14.45,100,1,12.5,700,1,14.52,100,1,12.46,100,1,14.56,800,1,12.43,700,1,14.6,700,1,12.42,700,1,14.64,200,1,ARL,327675057
1862,2025-07-17T16:04:21.276976977Z,2025-07-17T16:04:21.276976977Z,10,2,1108,A,A,0,13.770000000,100,130,165685,273687857,13.12,200,1,13.73,100,1,13.11,100,1,13.77,100,1,13,2,1,13.87,200,1,12.86,100,1,14,100,1,12.73,100,1,14.03,2,1,12.71,100,1,14.28,100,1,12.5,700,1,14.45,100,1,12.46,100,1,14.52,100,1,12.43,700,1,14.56,800,1,12.42,700,1,14.6,700,1,ARL,328239293
1863,2025-07-17T16:04:27.790889618Z,2025-07-17T16:04:27.790889618Z,10,2,1108,C,A,0,14.030000000,2,0,165528,273775264,13.12,200,1,13.73,100,1,13.11,100,1,13.77,100,1,13,2,1,13.87,200,1,12.86,100,1,14,100,1,12.73,100,1,14.28,100,1,12.71,100,1,14.45,100,1,12.5,700,1,14.52,100,1,12.46,100,1,14.56,800,1,12.43,700,1,14.6,700,1,12.42,700,1,14.64,200,1,ARL,326159041
1864,2025-07-17T16:04:27.790889618Z,2025-07-17T16:04:27.790889618Z,10,2,1108,A,A,0,13.940000000,2,130,165528,273775264,13.12,200,1,13.73,100,1,13.11,100,1,13.77,100,1,13,2,1,13.87,200,1,12.86,100,1,13.94,2,1,12.73,100,1,14,100,1,12.71,100,1,14.28,100,1,12.5,700,1,14.45,100,1,12.46,100,1,14.52,100,1,12.43,700,1,14.56,800,1,12.42,700,1,14.6,700,1,ARL,328351217
1865,2025-07-17T16:04:31.231887784Z,2025-07-17T16:04:31.231887784Z,10,2,1108,A,A,0,13.680000000,15,130,165370,273846737,13.12,200,1,13.68,15,1,13.11,100,1,13.73,100,1,13,2,1,13.77,100,1,12.86,100,1,13.87,200,1,12.73,100,1,13.94,2,1,12.71,100,1,14,100,1,12.5,700,1,14.28,100,1,12.46,100,1,14.45,100,1,12.43,700,1,14.52,100,1,12.42,700,1,14.56,800,1,ARL,328437797
1866,2025-07-17T16:04:31.232440773Z,2025-07-17T16:04:31.232440773Z,10,2,1108,A,A,0,13.720000000,100,130,165667,273846745,13.12,200,1,13.68,15,1,13.11,100,1,13.72,100,1,13,2,1,13.73,100,1,12.86,100,1,13.77,100,1,12.73,100,1,13.87,200,1,12.71,100,1,13.94,2,1,12.5,700,1,14,100,1,12.46,100,1,14.28,100,1,12.43,700,1,14.45,100,1,12.42,700,1,14.52,100,1,ARL,328437805
1867,2025-07-17T16:04:31.246515467Z,2025-07-17T16:04:31.246515467Z,10,2,1108,C,A,0,13.770000000,100,130,165695,273847000,13.12,200,1,13.68,15,1,13.11,100,1,13.72,100,1,13,2,1,13.73,100,1,12.86,100,1,13.87,200,1,12.73,100,1,13.94,2,1,12.71,100,1,14,100,1,12.5,700,1,14.28,100,1,12.46,100,1,14.45,100,1,12.43,700,1,14.52,100,1,12.42,700,1,14.56,800,1,ARL,328239293
1868,2025-07-17T16:04:32.836635838Z,2025-07-17T16:04:32.836635838Z,10,2,1108,C,A,0,13.730000000,100,0,166273,273882084,13.12,200,1,13.68,15,1,13.11,100,1,13.72,100,1,13,2,1,13.87,200,1,12.86,100,1,13.94,2,1,12.73,100,1,14,100,1,12.71,100,1,14.28,100,1,12.5,700,1,14.45,100,1,12.46,100,1,14.52,100,1,12.43,700,1,14.56,800,1,12.42,700,1,14.6,700,1,ARL,327864137
1869,2025-07-17T16:04:32.836635838Z,2025-07-17T16:04:32.836635838Z,10,2,1108,A,A,0,13.690000000,100,130,166273,273882084,13.12,200,1,13.68,15,1,13.11,100,1,13.69,100,1,13,2,1,13.72,100,1,12.86,100,1,13.87,200,1,12.73,100,1,13.94,2,1,12.71,100,1,14,100,1,12.5,700,1,14.28,100,1,12.46,100,1,14.45,100,1,12.43,700,1,14.52,100,1,12.42,700,1,14.56,800,1,ARL,328489153
1870,2025-07-17T16:04:32.837000154Z,2025-07-17T16:04:32.837000154Z,10,2,1108,C,B,0,13.120000000,100,130,165277,273882201,13.12,100,1,13.68,15,1,13.11,100,1,13.69,100,1,13,2,1,13.72,100,1,12.86,100,1,13.87,200,1,12.73,100,1,13.94,2,1,12.71,100,1,14,100,1,12.5,700,1,14.28,100,1,12.46,100,1,14.45,100,1,12.43,700,1,14.52,100,1,12.42,700,1,14.56,800,1,ARL,325718833
1871,2025-07-17T16:04:32.837002825Z,2025-07-17T16:04:32.837002825Z,10,2,1108,C,B,0,13.120000000,100,128,166258,273882202,13.11,100,1,13.68,15,1,13,2,1,13.69,100,1,12.86,100,1,13.72,100,1,12.73,100,1,13.87,200,1,12.71,100,1,13.94,2,1,12.5,700,1,14,100,1,12.46,100,1,14.28,100,1,12.43,700,1,14.45,100,1,12.42,700,1,14.52,100,1,12.37,700,1,14.56,800,1,ARL,325718837
1872,2025-07-17T16:04:32.837013456Z,2025-07-17T16:04:32.837013456Z,10,2,1108,A,B,0,12.980000000,100,130,166112,273882207,13.11,100,1,13.68,15,1,13,2,1,13.69,100,1,12.98,100,1,13.72,100,1,12.86,100,1,13.87,200,1,12.73,100,1,13.94,2,1,12.71,100,1,14,100,1,12.5,700,1,14.28,100,1,12.46,100,1,14.45,100,1,12.43,700,1,14.52,100,1,12.42,700,1,14.56,800,1,ARL,328489377
1873,2025-07-17T16:04:32.837016087Z,2025-07-17T16:04:32.837016087Z,10,2,1108,A,B,0,12.980000000,100,130,165495,273882208,13.11,100,1,13.68,15,1,13,2,1,13.69,100,1,12.98,200,1,13.72,100,1,12.86,100,1,13.87,200,1,12.73,100,1,13.94,2,1,12.71,100,1,14,100,1,12.5,700,1,14.28,100,1,12.46,100,1,14.45,100,1,12.43,700,1,14.52,100,1,12.42,700,1,14.56,800,1,ARL,328489385
1874,2025-07-17T16:04:32.837369811Z,2025-07-17T16:04:32.837369811Z,10,2,1108,C,A,0,14.790000000,100,0,166623,273882286,13.11,100,1,13.68,15,1,13,2,1,13.69,100,1,12.98,200,1,13.72,100,1,12.86,100,1,13.87,200,1,12.73,100,1,13.94,2,1,12.71,100,1,14,100,1,12.5,700,1,14.28,100,1,12.46,100,1,14.45,100,1,12.43,700,1,14.52,100,1,12.42,700,1,14.56,800,1,ARL,327864893
1875,2025-07-17T16:04:32.837369811Z,2025-07-17T16:04:32.837369811Z,10,2,1108,A,A,0,14.750000000,100,128,166623,273882286,13.11,100,1,13.68,15,1,13,2,1,13.69,100,1,12.98,200,1,13.72,100,1,12.86,100,1,13.87,200,1,12.73,100,1,13.94,2,1,12.71,100,1,14,100,1,12.5,700,1,14.28,100,1,12.46,100,1,14.45,100,1,12.43,700,1,14.52,100,1,12.42,700,1,14.56,800,1,ARL,328489481
1876,2025-07-17T16:04:36.810551890Z,2025-07-17T16:04:36.810551890Z,10,2,1108,A,A,0,13.650000000,15,130,165256,273963456,13.11,100,1,13.65,15,1,13,2,1,13.68,15,1,12.98,200,1,13.69,100,1,12.86,100,1,13.72,100,1,12.73,100,1,13.87,200,1,12.71,100,1,13.94,2,1,12.5,700,1,14,100,1,12.46,100,1,14.28,100,1,12.43,700,1,14.45,100,1,12.42,700,1,14.52,100,1,ARL,328603377
1877,2025-07-17T16:04:37.026771973Z,2025-07-17T16:04:37.026771973Z,10,2,1108,A,A,0,13.690000000,100,130,165520,273965417,13.11,100,1,13.65,15,1,13,2,1,13.68,15,1,12.98,200,1,13.69,200,1,12.86,100,1,13.72,100,1,12.73,100,1,13.87,200,1,12.71,100,1,13.94,2,1,12.5,700,1,14,100,1,12.46,100,1,14.28,100,1,12.43,700,1,14.45,100,1,12.42,700,1,14.52,100,1,ARL,328606289
1878,2025-07-17T16:04:37.033389265Z,2025-07-17T16:04:37.033389265Z,10,2,1108,C,A,0,13.720000000,100,130,165292,273965562,13.11,100,1,13.65,15,1,13,2,1,13.68,15,1,12.98,200,1,13.69,200,1,12.86,100,1,13.87,200,1,12.73,100,1,13.94,2,1,12.71,100,1,14,100,1,12.5,700,1,14.28,100,1,12.46,100,1,14.45,100,1,12.43,700,1,14.52,100,1,12.42,700,1,14.56,800,1,ARL,328437805
1879,2025-07-17T16:04:37.542795711Z,2025-07-17T16:04:37.542795711Z,10,2,1108,C,A,0,13.690000000,100,0,165450,273971021,13.11,100,1,13.65,15,1,13,2,1,13.68,15,1,12.98,200,1,13.69,100,1,12.86,100,1,13.87,200,1,12.73,100,1,13.94,2,1,12.71,100,1,14,100,1,12.5,700,1,14.28,100,1,12.46,100,1,14.45,100,1,12.43,700,1,14.52,100,1,12.42,700,1,14.56,800,1,ARL,328489153
1880,2025-07-17T16:04:37.542795711Z,2025-07-17T16:04:37.542795711Z,10,2,1108,A,A,0,13.660000000,100,130,165450,273971021,13.11,100,1,13.65,15,1,13,2,1,13.66,100,1,12.98,200,1,13.68,15,1,12.86,100,1,13.69,100,1,12.73,100,1,13.87,200,1,12.71,100,1,13.94,2,1,12.5,700,1,14,100,1,12.46,100,1,14.28,100,1,12.43,700,1,14.45,100,1,12.42,700,1,14.52,100,1,ARL,328614509
1881,2025-07-17T16:04:37.543063240Z,2025-07-17T16:04:37.543063240Z,10,2,1108,C,A,0,13.870000000,100,0,167440,273971035,13.11,100,1,13.65,15,1,13,2,1,13.66,100,1,12.98,200,1,13.68,15,1,12.86,100,1,13.69,100,1,12.73,100,1,13.87,100,1,12.71,100,1,13.94,2,1,12.5,700,1,14,100,1,12.46,100,1,14.28,100,1,12.43,700,1,14.45,100,1,12.42,700,1,14.52,100,1,ARL,326730517
1882,2025-07-17T16:04:37.543064690Z,2025-07-17T16:04:37.543064690Z,10,2,1108,C,A,0,13.870000000,100,130,165990,273971037,13.11,100,1,13.65,15,1,13,2,1,13.66,100,1,12.98,200,1,13.68,15,1,12.86,100,1,13.69,100,1,12.73,100,1,13.94,2,1,12.71,100,1,14,100,1,12.5,700,1,14.28,100,1,12.46,100,1,14.45,100,1,12.43,700,1,14.52,100,1,12.42,700,1,14.56,800,1,ARL,326730521
1883,2025-07-17T16:04:37.543077174Z,2025-07-17T16:04:37.543077174Z,10,2,1108,A,A,0,13.800000000,100,130,165216,273971040,13.11,100,1,13.65,15,1,13,2,1,13.66,100,1,12.98,200,1,13.68,15,1,12.86,100,1,13.69,100,1,12.73,100,1,13.8,100,1,12.71,100,1,13.94,2,1,12.5,700,1,14,100,1,12.46,100,1,14.28,100,1,12.43,700,1,14.45,100,1,12.42,700,1,14.52,100,1,ARL,328614525
1884,2025-07-17T16:04:37.543078532Z,2025-07-17T16:04:37.543078532Z,10,2,1108,A,A,0,13.800000000,100,130,165661,273971041,13.11,100,1,13.65,15,1,13,2,1,13.66,100,1,12.98,200,1,13.68,15,1,12.86,100,1,13.69,100,1,12.73,100,1,13.8,200,1,12.71,100,1,13.94,2,1,12.5,700,1,14,100,1,12.46,100,1,14.28,100,1,12.43,700,1,14.45,100,1,12.42,700,1,14.52,100,1,ARL,328614529
1885,2025-07-17T16:04:37.549519006Z,2025-07-17T16:04:37.549519006Z,10,2,1108,C,A,0,14.000000000,100,130,165707,273973481,13.11,100,1,13.65,15,1,13,2,1,13.66,100,1,12.98,200,1,13.68,15,1,12.86,100,1,13.69,100,1,12.73,100,1,13.8,200,1,12.71,100,1,13.94,2,1,12.5,700,1,14.28,100,1,12.46,100,1,14.45,100,1,12.43,700,1,14.52,100,1,12.42,700,1,14.56,800,1,ARL,327869193
1886,2025-07-17T16:04:37.549570649Z,2025-07-17T16:04:37.549570649Z,10,2,1108,A,A,0,13.930000000,100,130,165175,273973485,13.11,100,1,13.65,15,1,13,2,1,13.66,100,1,12.98,200,1,13.68,15,1,12.86,100,1,13.69,100,1,12.73,100,1,13.8,200,1,12.71,100,1,13.93,100,1,12.5,700,1,13.94,2,1,12.46,100,1,14.28,100,1,12.43,700,1,14.45,100,1,12.42,700,1,14.52,100,1,ARL,328616925
1887,2025-07-17T16:04:44.524360626Z,2025-07-17T16:04:44.524360626Z,10,2,1108,C,A,0,13.680000000,15,130,165919,274066152,13.11,100,1,13.65,15,1,13,2,1,13.66,100,1,12.98,200,1,13.69,100,1,12.86,100,1,13.8,200,1,12.73,100,1,13.93,100,1,12.71,100,1,13.94,2,1,12.5,700,1,14.28,100,1,12.46,100,1,14.45,100,1,12.43,700,1,14.52,100,1,12.42,700,1,14.56,800,1,ARL,328437797
1888,2025-07-17T16:04:45.527835033Z,2025-07-17T16:04:45.527835033Z,10,2,1108,A,A,0,13.630000000,15,130,165110,274088918,13.11,100,1,13.63,15,1,13,2,1,13.65,15,1,12.98,200,1,13.66,100,1,12.86,100,1,13.69,100,1,12.73,100,1,13.8,200,1,12.71,100,1,13.93,100,1,12.5,700,1,13.94,2,1,12.46,100,1,14.28,100,1,12.43,700,1,14.45,100,1,12.42,700,1,14.52,100,1,ARL,328780565
1889,2025-07-17T16:04:45.528464092Z,2025-07-17T16:04:45.528464092Z,10,2,1108,C,A,0,14.640000000,100,0,165521,274088922,13.11,100,1,13.63,15,1,13,2,1,13.65,15,1,12.98,200,1,13.66,100,1,12.86,100,1,13.69,100,1,12.73,100,1,13.8,200,1,12.71,100,1,13.93,100,1,12.5,700,1,13.94,2,1,12.46,100,1,14.28,100,1,12.43,700,1,14.45,100,1,12.42,700,1,14.52,100,1,ARL,327856309
1890,2025-07-17T16:04:45.528464092Z,2025-07-17T16:04:45.528464092Z,10,2,1108,A,A,0,14.520000000,100,130,165521,274088922,13.11,100,1,13.63,15,1,13,2,1,13.65,15,1,12.98,200,1,13.66,100,1,12.86,100,1,13.69,100,1,12.73,100,1,13.8,200,1,12.71,100,1,13.93,100,1,12.5,700,1,13.94,2,1,12.46,100,1,14.28,100,1,12.43,700,1,14.45,100,1,12.42,700,1,14.52,200,1,ARL,328780577
1891,2025-07-17T16:04:45.530252804Z,2025-07-17T16:04:45.530252804Z,10,2,1108,C,A,0,14.640000000,100,0,165474,274088937,13.11,100,1,13.63,15,1,13,2,1,13.65,15,1,12.98,200,1,13.66,100,1,12.86,100,1,13.69,100,1,12.73,100,1,13.8,200,1,12.71,100,1,13.93,100,1,12.5,700,1,13.94,2,1,12.46,100,1,14.28,100,1,12.43,700,1,14.45,100,1,12.42,700,1,14.52,200,1,ARL,327856297
1892,2025-07-17T16:04:45.530252804Z,2025-07-17T16:04:45.530252804Z,10,2,1108,A,A,0,14.520000000,100,130,165474,274088937,13.11,100,1,13.63,15,1,13,2,1,13.65,15,1,12.98,200,1,13.66,100,1,12.86,100,1,13.69,100,1,12.73,100,1,13.8,200,1,12.71,100,1,13.93,100,1,12.5,700,1,13.94,2,1,12.46,100,1,14.28,100,1,12.43,700,1,14.45,100,1,12.42,700,1,14.52,300,1,ARL,328780597
1893,2025-07-17T16:04:45.532901874Z,2025-07-17T16:04:45.532901874Z,10,2,1108,C,A,0,13.660000000,100,0,165155,274088955,13.11,100,1,13.63,15,1,13,2,1,13.65,15,1,12.98,200,1,13.69,100,1,12.86,100,1,13.8,200,1,12.73,100,1,13.93,100,1,12.71,100,1,13.94,2,1,12.5,700,1,14.28,100,1,12.46,100,1,14.45,100,1,12.43,700,1,14.52,300,1,12.42,700,1,14.56,800,1,ARL,328614509
1894,2025-07-17T16:04:45.532901874Z,2025-07-17T16:04:45.532901874Z,10,2,1108,A,A,0,13.640000000,100,130,165155,274088955,13.11,100,1,13.63,15,1,13,2,1,13.64,100,1,12.98,200,1,13.65,15,1,12.86,100,1,13.69,100,1,12.73,100,1,13.8,200,1,12.71,100,1,13.93,100,1,12.5,700,1,13.94,2,1,12.46,100,1,14.28,100,1,12.43,700,1,14.45,100,1,12.42,700,1,14.52,300,1,ARL,328780669
1895,2025-07-17T16:04:45.533639142Z,2025-07-17T16:04:45.533639142Z,10,2,1108,C,A,0,14.750000000,100,0,165626,274088957,13.11,100,1,13.63,15,1,13,2,1,13.64,100,1,12.98,200,1,13.65,15,1,12.86,100,1,13.69,100,1,12.73,100,1,13.8,200,1,12.71,100,1,13.93,100,1,12.5,700,1,13.94,2,1,12.46,100,1,14.28,100,1,12.43,700,1,14.45,100,1,12.42,700,1,14.52,300,1,ARL,328489481
1896,2025-07-17T16:04:45.533639142Z,2025-07-17T16:04:45.533639142Z,10,2,1108,A,A,0,14.700000000,100,130,165626,274088957,13.11,100,1,13.63,15,1,13,2,1,13.64,100,1,12.98,200,1,13.65,15,1,12.86,100,1,13.69,100,1,12.73,100,1,13.8,200,1,12.71,100,1,13.93,100,1,12.5,700,1,13.94,2,1,12.46,100,1,14.28,100,1,12.43,700,1,14.45,100,1,12.42,700,1,14.52,300,1,ARL,328780685
1897,2025-07-17T16:04:45.533705428Z,2025-07-17T16:04:45.533705428Z,10,2,1108,A,A,0,13.670000000,100,130,165283,274088959,13.11,100,1,13.63,15,1,13,2,1,13.64,100,1,12.98,200,1,13.65,15,1,12.86,100,1,13.67,100,1,12.73,100,1,13.69,100,1,12.71,100,1,13.8,200,1,12.5,700,1,13.93,100,1,12.46,100,1,13.94,2,1,12.43,700,1,14.28,100,1,12.42,700,1,14.45,100,1,ARL,328780689
1898,2025-07-17T16:04:45.562972204Z,2025-07-17T16:04:45.562972204Z,10,2,1108,C,A,0,13.690000000,100,130,165239,274089319,13.11,100,1,13.63,15,1,13,2,1,13.64,100,1,12.98,200,1,13.65,15,1,12.86,100,1,13.67,100,1,12.73,100,1,13.8,200,1,12.71,100,1,13.93,100,1,12.5,700,1,13.94,2,1,12.46,100,1,14.28,100,1,12.43,700,1,14.45,100,1,12.42,700,1,14.52,300,1,ARL,328606289
1899,2025-07-17T16:04:56.809584701Z,2025-07-17T16:04:56.809584701Z,10,2,1108,C,A,0,13.650000000,15,130,165272,274293432,13.11,100,1,13.63,15,1,13,2,1,13.64,100,1,12.98,200,1,13.67,100,1,12.86,100,1,13.8,200,1,12.73,100,1,13.93,100,1,12.71,100,1,13.94,2,1,12.5,700,1,14.28,100,1,12.46,100,1,14.45,100,1,12.43,700,1,14.52,300,1,12.42,700,1,14.56,800,1,ARL,328603377
1900,2025-07-17T16:04:57.826913717Z,2025-07-17T16:04:57.826913717Z,10,2,1108,A,A,0,13.610000000,15,130,165292,274310244,13.11,100,1,13.61,15,1,13,2,1,13.63,15,1,12.98,200,1,13.64,100,1,12.86,100,1,13.67,100,1,12.73,100,1,13.8,200,1,12.71,100,1,13.93,100,1,12.5,700,1,13.94,2,1,12.46,100,1,14.28,100,1,12.43,700,1,14.45,100,1,12.42,700,1,14.52,300,1,ARL,329068341
1901,2025-07-17T16:04:57.970451236Z,2025-07-17T16:04:57.970451236Z,10,2,1108,C,A,0,13.640000000,100,0,165374,274316281,13.11,100,1,13.61,15,1,13,2,1,13.63,15,1,12.98,200,1,13.67,100,1,12.86,100,1,13.8,200,1,12.73,100,1,13.93,100,1,12.71,100,1,13.94,2,1,12.5,700,1,14.28,100,1,12.46,100,1,14.45,100,1,12.43,700,1,14.52,300,1,12.42,700,1,14.56,800,1,ARL,328780669
1902,2025-07-17T16:04:57.970451236Z,2025-07-17T16:04:57.970451236Z,10,2,1108,A,A,0,13.620000000,100,130,165374,274316281,13.11,100,1,13.61,15,1,13,2,1,13.62,100,1,12.98,200,1,13.63,15,1,12.86,100,1,13.67,100,1,12.73,100,1,13.8,200,1,12.71,100,1,13.93,100,1,12.5,700,1,13.94,2,1,12.46,100,1,14.28,100,1,12.43,700,1,14.45,100,1,12.42,700,1,14.52,300,1,ARL,329074609
1903,2025-07-17T16:04:57.971193734Z,2025-07-17T16:04:57.971193734Z,10,2,1108,C,A,0,14.450000000,100,128,166610,274316507,13.11,100,1,13.61,15,1,13,2,1,13.62,100,1,12.98,200,1,13.63,15,1,12.86,100,1,13.67,100,1,12.73,100,1,13.8,200,1,12.71,100,1,13.93,100,1,12.5,700,1,13.94,2,1,12.46,100,1,14.28,100,1,12.43,700,1,14.52,300,1,12.42,700,1,14.56,800,1,ARL,325714601
1904,2025-07-17T16:04:57.971552262Z,2025-07-17T16:04:57.971552262Z,10,2,1108,A,A,0,14.230000000,100,130,165249,274316527,13.11,100,1,13.61,15,1,13,2,1,13.62,100,1,12.98,200,1,13.63,15,1,12.86,100,1,13.67,100,1,12.73,100,1,13.8,200,1,12.71,100,1,13.93,100,1,12.5,700,1,13.94,2,1,12.46,100,1,14.23,100,1,12.43,700,1,14.28,100,1,12.42,700,1,14.52,300,1,ARL,329074833
1905,2025-07-17T16:04:57.991966904Z,2025-07-17T16:04:57.991966904Z,10,2,1108,C,A,0,13.610000000,15,130,164974,274318490,13.11,100,1,13.62,100,1,13,2,1,13.63,15,1,12.98,200,1,13.67,100,1,12.86,100,1,13.8,200,1,12.73,100,1,13.93,100,1,12.71,100,1,13.94,2,1,12.5,700,1,14.23,100,1,12.46,100,1,14.28,100,1,12.43,700,1,14.52,300,1,12.42,700,1,14.56,800,1,ARL,329068341
1906,2025-07-17T16:04:57.992976406Z,2025-07-17T16:04:57.992976406Z,10,2,1108,C,A,0,13.620000000,100,130,165032,274318579,13.11,100,1,13.63,15,1,13,2,1,13.67,100,1,12.98,200,1,13.8,200,1,12.86,100,1,13.93,100,1,12.73,100,1,13.94,2,1,12.71,100,1,14.23,100,1,12.5,700,1,14.28,100,1,12.46,100,1,14.52,300,1,12.43,700,1,14.56,800,1,12.42,700,1,14.6,700,1,ARL,329074609
1907,2025-07-17T16:04:57.993143873Z,2025-07-17T16:04:57.993143873Z,10,2,1108,C,A,0,13.630000000,15,130,165688,274318603,13.11,100,1,13.67,100,1,13,2,1,13.8,200,1,12.98,200,1,13.93,100,1,12.86,100,1,13.94,2,1,12.73,100,1,14.23,100,1,12.71,100,1,14.28,100,1,12.5,700,1,14.52,300,1,12.46,100,1,14.56,800,1,12.43,700,1,14.6,700,1,12.42,700,1,14.68,1400,1,ARL,328780565
1908,2025-07-17T16:04:58.002094377Z,2025-07-17T16:04:58.002094377Z,10,2,1108,C,A,0,13.670000000,100,130,165338,274319058,13.11,100,1,13.8,200,1,13,2,1,13.93,100,1,12.98,200,1,13.94,2,1,12.86,100,1,14.23,100,1,12.73,100,1,14.28,100,1,12.71,100,1,14.52,300,1,12.5,700,1,14.56,800,1,12.46,100,1,14.6,700,1,12.43,700,1,14.68,1400,1,12.42,700,1,14.7,300,1,ARL,328780689
1909,2025-07-17T16:04:58.002823841Z,2025-07-17T16:04:58.002823841Z,10,2,1108,C,A,0,14.700000000,100,0,165589,274319069,13.11,100,1,13.8,200,1,13,2,1,13.93,100,1,12.98,200,1,13.94,2,1,12.86,100,1,14.23,100,1,12.73,100,1,14.28,100,1,12.71,100,1,14.52,300,1,12.5,700,1,14.56,800,1,12.46,100,1,14.6,700,1,12.43,700,1,14.68,1400,1,12.42,700,1,14.7,200,1,ARL,328780685
1910,2025-07-17T16:04:58.002823841Z,2025-07-17T16:04:58.002823841Z,10,2,1108,A,A,0,14.870000000,100,130,165589,274319069,13.11,100,1,13.8,200,1,13,2,1,13.93,100,1,12.98,200,1,13.94,2,1,12.86,100,1,14.23,100,1,12.73,100,1,14.28,100,1,12.71,100,1,14.52,300,1,12.5,700,1,14.56,800,1,12.46,100,1,14.6,700,1,12.43,700,1,14.68,1400,1,12.42,700,1,14.7,200,1,ARL,329078553
1911,2025-07-17T16:04:58.013739242Z,2025-07-17T16:04:58.013739242Z,10,2,1108,C,A,0,13.930000000,100,130,165455,274319298,13.11,100,1,13.8,200,1,13,2,1,13.94,2,1,12.98,200,1,14.23,100,1,12.86,100,1,14.28,100,1,12.73,100,1,14.52,300,1,12.71,100,1,14.56,800,1,12.5,700,1,14.6,700,1,12.46,100,1,14.68,1400,1,12.43,700,1,14.7,200,1,12.42,700,1,14.87,100,1,ARL,328616925
1912,2025-07-17T16:04:58.013793974Z,2025-07-17T16:04:58.013793974Z,10,2,1108,A,A,0,14.080000000,100,130,165259,274319304,13.11,100,1,13.8,200,1,13,2,1,13.94,2,1,12.98,200,1,14.08,100,1,12.86,100,1,14.23,100,1,12.73,100,1,14.28,100,1,12.71,100,1,14.52,300,1,12.5,700,1,14.56,800,1,12.46,100,1,14.6,700,1,12.43,700,1,14.68,1400,1,12.42,700,1,14.7,200,1,ARL,329078953
1913,2025-07-17T16:04:58.536452621Z,2025-07-17T16:04:58.536452621Z,10,2,1108,A,A,0,13.810000000,100,130,165296,274326535,13.11,100,1,13.8,200,1,13,2,1,13.81,100,1,12.98,200,1,13.94,2,1,12.86,100,1,14.08,100,1,12.73,100,1,14.23,100,1,12.71,100,1,14.28,100,1,12.5,700,1,14.52,300,1,12.46,100,1,14.56,800,1,12.43,700,1,14.6,700,1,12.42,700,1,14.68,1400,1,ARL,329088265
1914,2025-07-17T16:05:46.593966383Z,2025-07-17T16:05:46.593966383Z,10,2,1108,A,A,0,13.760000000,100,130,165281,275083968,13.11,100,1,13.76,100,1,13,2,1,13.8,200,1,12.98,200,1,13.81,100,1,12.86,100,1,13.94,2,1,12.73,100,1,14.08,100,1,12.71,100,1,14.23,100,1,12.5,700,1,14.28,100,1,12.46,100,1,14.52,300,1,12.43,700,1,14.56,800,1,12.42,700,1,14.6,700,1,ARL,330066537
1915,2025-07-17T16:05:46.594705962Z,2025-07-17T16:05:46.594705962Z,10,2,1108,C,A,0,14.870000000,100,0,165374,275083970,13.11,100,1,13.76,100,1,13,2,1,13.8,200,1,12.98,200,1,13.81,100,1,12.86,100,1,13.94,2,1,12.73,100,1,14.08,100,1,12.71,100,1,14.23,100,1,12.5,700,1,14.28,100,1,12.46,100,1,14.52,300,1,12.43,700,1,14.56,800,1,12.42,700,1,14.6,700,1,ARL,329078553
1916,2025-07-17T16:05:46.594705962Z,2025-07-17T16:05:46.594705962Z,10,2,1108,A,A,0,14.830000000,100,130,165374,275083970,13.11,100,1,13.76,100,1,13,2,1,13.8,200,1,12.98,200,1,13.81,100,1,12.86,100,1,13.94,2,1,12.73,100,1,14.08,100,1,12.71,100,1,14.23,100,1,12.5,700,1,14.28,100,1,12.46,100,1,14.52,300,1,12.43,700,1,14.56,800,1,12.42,700,1,14.6,700,1,ARL,330066553
1917,2025-07-17T16:05:46.995837526Z,2025-07-17T16:05:46.995837526Z,10,2,1108,C,A,0,13.810000000,100,0,166026,275092978,13.11,100,1,13.76,100,1,13,2,1,13.8,200,1,12.98,200,1,13.94,2,1,12.86,100,1,14.08,100,1,12.73,100,1,14.23,100,1,12.71,100,1,14.28,100,1,12.5,700,1,14.52,300,1,12.46,100,1,14.56,800,1,12.43,700,1,14.6,700,1,12.42,700,1,14.68,1400,1,ARL,329088265
1918,2025-07-17T16:05:46.995837526Z,2025-07-17T16:05:46.995837526Z,10,2,1108,A,A,0,13.770000000,100,130,166026,275092978,13.11,100,1,13.76,100,1,13,2,1,13.77,100,1,12.98,200,1,13.8,200,1,12.86,100,1,13.94,2,1,12.73,100,1,14.08,100,1,12.71,100,1,14.23,100,1,12.5,700,1,14.28,100,1,12.46,100,1,14.52,300,1,12.43,700,1,14.56,800,1,12.42,700,1,14.6,700,1,ARL,330075425
1919,2025-07-17T16:05:50.680167632Z,2025-07-17T16:05:50.680167632Z,10,2,1108,A,A,0,13.680000000,15,130,165519,275152014,13.11,100,1,13.68,15,1,13,2,1,13.76,100,1,12.98,200,1,13.77,100,1,12.86,100,1,13.8,200,1,12.73,100,1,13.94,2,1,12.71,100,1,14.08,100,1,12.5,700,1,14.23,100,1,12.46,100,1,14.28,100,1,12.43,700,1,14.52,300,1,12.42,700,1,14.56,800,1,ARL,330143813
1920,2025-07-17T16:05:50.697005084Z,2025-07-17T16:05:50.697005084Z,10,2,1108,A,A,0,13.720000000,100,130,165236,275152383,13.11,100,1,13.68,15,1,13,2,1,13.72,100,1,12.98,200,1,13.76,100,1,12.86,100,1,13.77,100,1,12.73,100,1,13.8,200,1,12.71,100,1,13.94,2,1,12.5,700,1,14.08,100,1,12.46,100,1,14.23,100,1,12.43,700,1,14.28,100,1,12.42,700,1,14.52,300,1,ARL,330144301
1921,2025-07-17T16:05:50.697739933Z,2025-07-17T16:05:50.697739933Z,10,2,1108,C,A,0,14.830000000,100,0,165439,275152385,13.11,100,1,13.68,15,1,13,2,1,13.72,100,1,12.98,200,1,13.76,100,1,12.86,100,1,13.77,100,1,12.73,100,1,13.8,200,1,12.71,100,1,13.94,2,1,12.5,700,1,14.08,100,1,12.46,100,1,14.23,100,1,12.43,700,1,14.28,100,1,12.42,700,1,14.52,300,1,ARL,330066553
1922,2025-07-17T16:05:50.697739933Z,2025-07-17T16:05:50.697739933Z,10,2,1108,A,A,0,14.780000000,100,130,165439,275152385,13.11,100,1,13.68,15,1,13,2,1,13.72,100,1,12.98,200,1,13.76,100,1,12.86,100,1,13.77,100,1,12.73,100,1,13.8,200,1,12.71,100,1,13.94,2,1,12.5,700,1,14.08,100,1,12.46,100,1,14.23,100,1,12.43,700,1,14.28,100,1,12.42,700,1,14.52,300,1,ARL,330144321
1923,2025-07-17T16:05:50.704366332Z,2025-07-17T16:05:50.704366332Z,10,2,1108,C,A,0,13.760000000,100,130,165416,275152443,13.11,100,1,13.68,15,1,13,2,1,13.72,100,1,12.98,200,1,13.77,100,1,12.86,100,1,13.8,200,1,12.73,100,1,13.94,2,1,12.71,100,1,14.08,100,1,12.5,700,1,14.23,100,1,12.46,100,1,14.28,100,1,12.43,700,1,14.52,300,1,12.42,700,1,14.56,800,1,ARL,330066537
1924,2025-07-17T16:05:50.708714027Z,2025-07-17T16:05:50.708714027Z,10,2,1108,C,A,0,14.080000000,100,130,165284,275152465,13.11,100,1,13.68,15,1,13,2,1,13.72,100,1,12.98,200,1,13.77,100,1,12.86,100,1,13.8,200,1,12.73,100,1,13.94,2,1,12.71,100,1,14.23,100,1,12.5,700,1,14.28,100,1,12.46,100,1,14.52,300,1,12.43,700,1,14.56,800,1,12.42,700,1,14.6,700,1,ARL,329078953
1925,2025-07-17T16:05:50.708766050Z,2025-07-17T16:05:50.708766050Z,10,2,1108,A,A,0,13.990000000,100,130,165139,275152466,13.11,100,1,13.68,15,1,13,2,1,13.72,100,1,12.98,200,1,13.77,100,1,12.86,100,1,13.8,200,1,12.73,100,1,13.94,2,1,12.71,100,1,13.99,100,1,12.5,700,1,14.23,100,1,12.46,100,1,14.28,100,1,12.43,700,1,14.52,300,1,12.42,700,1,14.56,800,1,ARL,330144513
1926,2025-07-17T16:05:50.913310799Z,2025-07-17T16:05:50.913310799Z,10,2,1108,C,A,0,13.770000000,100,0,165469,275159685,13.11,100,1,13.68,15,1,13,2,1,13.72,100,1,12.98,200,1,13.8,200,1,12.86,100,1,13.94,2,1,12.73,100,1,13.99,100,1,12.71,100,1,14.23,100,1,12.5,700,1,14.28,100,1,12.46,100,1,14.52,300,1,12.43,700,1,14.56,800,1,12.42,700,1,14.6,700,1,ARL,330075425
1927,2025-07-17T16:05:50.913310799Z,2025-07-17T16:05:50.913310799Z,10,2,1108,A,A,0,13.690000000,100,130,165469,275159685,13.11,100,1,13.68,15,1,13,2,1,13.69,100,1,12.98,200,1,13.72,100,1,12.86,100,1,13.8,200,1,12.73,100,1,13.94,2,1,12.71,100,1,13.99,100,1,12.5,700,1,14.23,100,1,12.46,100,1,14.28,100,1,12.43,700,1,14.52,300,1,12.42,700,1,14.56,800,1,ARL,330151389
1928,2025-07-17T16:05:59.704790753Z,2025-07-17T16:05:59.704790753Z,10,2,1108,A,A,0,13.640000000,15,130,165217,275325555,13.11,100,1,13.64,15,1,13,2,1,13.68,15,1,12.98,200,1,13.69,100,1,12.86,100,1,13.72,100,1,12.73,100,1,13.8,200,1,12.71,100,1,13.94,2,1,12.5,700,1,13.99,100,1,12.46,100,1,14.23,100,1,12.43,700,1,14.28,100,1,12.42,700,1,14.52,300,1,ARL,330357473
1929,2025-07-17T16:05:59.714925412Z,2025-07-17T16:05:59.714925412Z,10,2,1108,A,A,0,13.680000000,100,130,165250,275325807,13.11,100,1,13.64,15,1,13,2,1,13.68,115,1,12.98,200,1,13.69,100,1,12.86,100,1,13.72,100,1,12.73,100,1,13.8,200,1,12.71,100,1,13.94,2,1,12.5,700,1,13.99,100,1,12.46,100,1,14.23,100,1,12.43,700,1,14.28,100,1,12.42,700,1,14.52,300,1,ARL,330357633
1930,2025-07-17T16:05:59.722730507Z,2025-07-17T16:05:59.722730507Z,10,2,1108,C,A,0,13.720000000,100,130,165243,275325854,13.11,100,1,13.64,15,1,13,2,1,13.68,115,1,12.98,200,1,13.69,100,1,12.86,100,1,13.8,200,1,12.73,100,1,13.94,2,1,12.71,100,1,13.99,100,1,12.5,700,1,14.23,100,1,12.46,100,1,14.28,100,1,12.43,700,1,14.52,300,1,12.42,700,1,14.56,800,1,ARL,330144301
1931,2025-07-17T16:05:59.802596747Z,2025-07-17T16:05:59.802596747Z,10,2,1108,C,A,0,13.690000000,100,0,165340,275327082,13.11,100,1,13.64,15,1,13,2,1,13.68,115,1,12.98,200,1,13.8,200,1,12.86,100,1,13.94,2,1,12.73,100,1,13.99,100,1,12.71,100,1,14.23,100,1,12.5,700,1,14.28,100,1,12.46,100,1,14.52,300,1,12.43,700,1,14.56,800,1,12.42,700,1,14.6,700,1,ARL,330151389
1932,2025-07-17T16:05:59.802596747Z,2025-07-17T16:05:59.802596747Z,10,2,1108,A,A,0,13.650000000,100,130,165340,275327082,13.11,100,1,13.64,15,1,13,2,1,13.65,100,1,12.98,200,1,13.68,115,1,12.86,100,1,13.8,200,1,12.73,100,1,13.94,2,1,12.71,100,1,13.99,100,1,12.5,700,1,14.23,100,1,12.46,100,1,14.28,100,1,12.43,700,1,14.52,300,1,12.42,700,1,14.56,800,1,ARL,330359197
1933,2025-07-17T16:05:59.803338996Z,2025-07-17T16:05:59.803338996Z,10,2,1108,C,A,0,14.780000000,100,0,165662,275327093,13.11,100,1,13.64,15,1,13,2,1,13.65,100,1,12.98,200,1,13.68,115,1,12.86,100,1,13.8,200,1,12.73,100,1,13.94,2,1,12.71,100,1,13.99,100,1,12.5,700,1,14.23,100,1,12.46,100,1,14.28,100,1,12.43,700,1,14.52,300,1,12.42,700,1,14.56,800,1,ARL,330144321
1934,2025-07-17T16:05:59.803338996Z,2025-07-17T16:05:59.803338996Z,10,2,1108,A,A,0,14.710000000,100,130,165662,275327093,13.11,100,1,13.64,15,1,13,2,1,13.65,100,1,12.98,200,1,13.68,115,1,12.86,100,1,13.8,200,1,12.73,100,1,13.94,2,1,12.71,100,1,13.99,100,1,12.5,700,1,14.23,100,1,12.46,100,1,14.28,100,1,12.43,700,1,14.52,300,1,12.42,700,1,14.56,800,1,ARL,330359225
1935,2025-07-17T16:05:59.827622529Z,2025-07-17T16:05:59.827622529Z,10,2,1108,C,A,0,13.990000000,100,130,165308,275327416,13.11,100,1,13.64,15,1,13,2,1,13.65,100,1,12.98,200,1,13.68,115,1,12.86,100,1,13.8,200,1,12.73,100,1,13.94,2,1,12.71,100,1,14.23,100,1,12.5,700,1,14.28,100,1,12.46,100,1,14.52,300,1,12.43,700,1,14.56,800,1,12.42,700,1,14.6,700,1,ARL,330144513
1936,2025-07-17T16:05:59.827674437Z,2025-07-17T16:05:59.827674437Z,10,2,1108,A,A,0,13.920000000,100,130,165365,275327417,13.11,100,1,13.64,15,1,13,2,1,13.65,100,1,12.98,200,1,13.68,115,1,12.86,100,1,13.8,200,1,12.73,100,1,13.92,100,1,12.71,100,1,13.94,2,1,12.5,700,1,14.23,100,1,12.46,100,1,14.28,100,1,12.43,700,1,14.52,300,1,12.42,700,1,14.56,800,1,ARL,330359625
1937,2025-07-17T16:06:02.724280161Z,2025-07-17T16:06:02.724280161Z,10,2,1108,C,A,0,13.680000000,15,128,166176,275430576,13.11,100,1,13.64,15,1,13,2,1,13.65,100,1,12.98,200,1,13.68,100,1,12.86,100,1,13.8,200,1,12.73,100,1,13.92,100,1,12.71,100,1,13.94,2,1,12.5,700,1,14.23,100,1,12.46,100,1,14.28,100,1,12.43,700,1,14.52,300,1,12.42,700,1,14.56,800,1,ARL,330143813
1938,2025-07-17T16:06:03.729212428Z,2025-07-17T16:06:03.729212428Z,10,2,1108,A,A,0,13.620000000,15,130,165342,275517342,13.11,100,1,13.62,15,1,13,2,1,13.64,15,1,12.98,200,1,13.65,100,1,12.86,100,1,13.68,100,1,12.73,100,1,13.8,200,1,12.71,100,1,13.92,100,1,12.5,700,1,13.94,2,1,12.46,100,1,14.23,100,1,12.43,700,1,14.28,100,1,12.42,700,1,14.52,300,1,ARL,330577045
1939,2025-07-17T16:06:03.738332427Z,2025-07-17T16:06:03.738332427Z,10,2,1108,A,A,0,13.650000000,100,130,165218,275517997,13.11,100,1,13.62,15,1,13,2,1,13.64,15,1,12.98,200,1,13.65,200,1,12.86,100,1,13.68,100,1,12.73,100,1,13.8,200,1,12.71,100,1,13.92,100,1,12.5,700,1,13.94,2,1,12.46,100,1,14.23,100,1,12.43,700,1,14.28,100,1,12.42,700,1,14.52,300,1,ARL,330577773
1940,2025-07-17T16:06:03.747330178Z,2025-07-17T16:06:03.747330178Z,10,2,1108,C,A,0,13.680000000,100,130,165491,275518621,13.11,100,1,13.62,15,1,13,2,1,13.64,15,1,12.98,200,1,13.65,200,1,12.86,100,1,13.8,200,1,12.73,100,1,13.92,100,1,12.71,100,1,13.94,2,1,12.5,700,1,14.23,100,1,12.46,100,1,14.28,100,1,12.43,700,1,14.52,300,1,12.42,700,1,14.56,800,1,ARL,330357633
1941,2025-07-17T16:06:03.887107153Z,2025-07-17T16:06:03.887107153Z,10,2,1108,C,A,0,13.650000000,100,0,167517,275532429,13.11,100,1,13.62,15,1,13,2,1,13.64,15,1,12.98,200,1,13.65,100,1,12.86,100,1,13.8,200,1,12.73,100,1,13.92,100,1,12.71,100,1,13.94,2,1,12.5,700,1,14.23,100,1,12.46,100,1,14.28,100,1,12.43,700,1,14.52,300,1,12.42,700,1,14.56,800,1,ARL,330359197
1942,2025-07-17T16:06:03.887107153Z,2025-07-17T16:06:03.887107153Z,10,2,1108,A,A,0,13.630000000,100,130,167517,275532429,13.11,100,1,13.62,15,1,13,2,1,13.63,100,1,12.98,200,1,13.64,15,1,12.86,100,1,13.65,100,1,12.73,100,1,13.8,200,1,12.71,100,1,13.92,100,1,12.5,700,1,13.94,2,1,12.46,100,1,14.23,100,1,12.43,700,1,14.28,100,1,12.42,700,1,14.52,300,1,ARL,330592465
1943,2025-07-17T16:06:07.509885114Z,2025-07-17T16:06:07.509885114Z,10,2,1108,C,A,0,13.640000000,15,130,165644,275647392,13.11,100,1,13.62,15,1,13,2,1,13.63,100,1,12.98,200,1,13.65,100,1,12.86,100,1,13.8,200,1,12.73,100,1,13.92,100,1,12.71,100,1,13.94,2,1,12.5,700,1,14.23,100,1,12.46,100,1,14.28,100,1,12.43,700,1,14.52,300,1,12.42,700,1,14.56,800,1,ARL,330357473
1944,2025-07-17T16:06:09.884978592Z,2025-07-17T16:06:09.884978592Z,10,2,1108,A,A,0,13.600000000,15,130,165317,275699092,13.11,100,1,13.6,15,1,13,2,1,13.62,15,1,12.98,200,1,13.63,100,1,12.86,100,1,13.65,100,1,12.73,100,1,13.8,200,1,12.71,100,1,13.92,100,1,12.5,700,1,13.94,2,1,12.46,100,1,14.23,100,1,12.43,700,1,14.28,100,1,12.42,700,1,14.52,300,1,ARL,330788421
1945,2025-07-17T16:06:09.967442600Z,2025-07-17T16:06:09.967442600Z,10,2,1108,C,A,0,13.630000000,100,0,165461,275700261,13.11,100,1,13.6,15,1,13,2,1,13.62,15,1,12.98,200,1,13.65,100,1,12.86,100,1,13.8,200,1,12.73,100,1,13.92,100,1,12.71,100,1,13.94,2,1,12.5,700,1,14.23,100,1,12.46,100,1,14.28,100,1,12.43,700,1,14.52,300,1,12.42,700,1,14.56,800,1,ARL,330592465
1946,2025-07-17T16:06:09.967442600Z,2025-07-17T16:06:09.967442600Z,10,2,1108,A,A,0,13.610000000,100,130,165461,275700261,13.11,100,1,13.6,15,1,13,2,1,13.61,100,1,12.98,200,1,13.62,15,1,12.86,100,1,13.65,100,1,12.73,100,1,13.8,200,1,12.71,100,1,13.92,100,1,12.5,700,1,13.94,2,1,12.46,100,1,14.23,100,1,12.43,700,1,14.28,100,1,12.42,700,1,14.52,300,1,ARL,330789481
1947,2025-07-17T16:06:09.968186617Z,2025-07-17T16:06:09.968186617Z,10,2,1108,C,A,0,14.710000000,100,0,165449,275700270,13.11,100,1,13.6,15,1,13,2,1,13.61,100,1,12.98,200,1,13.62,15,1,12.86,100,1,13.65,100,1,12.73,100,1,13.8,200,1,12.71,100,1,13.92,100,1,12.5,700,1,13.94,2,1,12.46,100,1,14.23,100,1,12.43,700,1,14.28,100,1,12.42,700,1,14.52,300,1,ARL,330359225
1948,2025-07-17T16:06:09.968186617Z,2025-07-17T16:06:09.968186617Z,10,2,1108,A,A,0,14.670000000,100,130,165449,275700270,13.11,100,1,13.6,15,1,13,2,1,13.61,100,1,12.98,200,1,13.62,15,1,12.86,100,1,13.65,100,1,12.73,100,1,13.8,200,1,12.71,100,1,13.92,100,1,12.5,700,1,13.94,2,1,12.46,100,1,14.23,100,1,12.43,700,1,14.28,100,1,12.42,700,1,14.52,300,1,ARL,330789501
1949,2025-07-17T16:06:09.969875190Z,2025-07-17T16:06:09.969875190Z,10,2,1108,C,A,0,17.440000000,100,0,165496,275700282,13.11,100,1,13.6,15,1,13,2,1,13.61,100,1,12.98,200,1,13.62,15,1,12.86,100,1,13.65,100,1,12.73,100,1,13.8,200,1,12.71,100,1,13.92,100,1,12.5,700,1,13.94,2,1,12.46,100,1,14.23,100,1,12.43,700,1,14.28,100,1,12.42,700,1,14.52,300,1,ARL,327870217
1950,2025-07-17T16:06:09.969875190Z,2025-07-17T16:06:09.969875190Z,10,2,1108,A,A,0,17.290000000,100,130,165496,275700282,13.11,100,1,13.6,15,1,13,2,1,13.61,100,1,12.98,200,1,13.62,15,1,12.86,100,1,13.65,100,1,12.73,100,1,13.8,200,1,12.71,100,1,13.92,100,1,12.5,700,1,13.94,2,1,12.46,100,1,14.23,100,1,12.43,700,1,14.28,100,1,12.42,700,1,14.52,300,1,ARL,330789509
1951,2025-07-17T16:06:20.470724464Z,2025-07-17T16:06:20.470724464Z,10,2,1108,A,A,0,13.630000000,100,130,165387,275896138,13.11,100,1,13.6,15,1,13,2,1,13.61,100,1,12.98,200,1,13.62,15,1,12.86,100,1,13.63,100,1,12.73,100,1,13.65,100,1,12.71,100,1,13.8,200,1,12.5,700,1,13.92,100,1,12.46,100,1,13.94,2,1,12.43,700,1,14.23,100,1,12.42,700,1,14.28,100,1,ARL,331018065
1952,2025-07-17T16:06:20.477432988Z,2025-07-17T16:06:20.477432988Z,10,2,1108,C,A,0,13.650000000,100,130,165590,275896242,13.11,100,1,13.6,15,1,13,2,1,13.61,100,1,12.98,200,1,13.62,15,1,12.86,100,1,13.63,100,1,12.73,100,1,13.8,200,1,12.71,100,1,13.92,100,1,12.5,700,1,13.94,2,1,12.46,100,1,14.23,100,1,12.43,700,1,14.28,100,1,12.42,700,1,14.52,300,1,ARL,330577773
1953,2025-07-17T16:06:20.810998706Z,2025-07-17T16:06:20.810998706Z,10,2,1108,C,A,0,13.620000000,15,130,165472,275900161,13.11,100,1,13.6,15,1,13,2,1,13.61,100,1,12.98,200,1,13.63,100,1,12.86,100,1,13.8,200,1,12.73,100,1,13.92,100,1,12.71,100,1,13.94,2,1,12.5,700,1,14.23,100,1,12.46,100,1,14.28,100,1,12.43,700,1,14.52,300,1,12.42,700,1,14.56,800,1,ARL,330577045
1954,2025-07-17T16:06:22.151057292Z,2025-07-17T16:06:22.151057292Z,10,2,1108,A,A,0,13.580000000,15,130,165527,275926927,13.11,100,1,13.58,15,1,13,2,1,13.6,15,1,12.98,200,1,13.61,100,1,12.86,100,1,13.63,100,1,12.73,100,1,13.8,200,1,12.71,100,1,13.92,100,1,12.5,700,1,13.94,2,1,12.46,100,1,14.23,100,1,12.43,700,1,14.28,100,1,12.42,700,1,14.52,300,1,ARL,331050981
1955,2025-07-17T16:06:22.151326300Z,2025-07-17T16:06:22.151326300Z,10,2,1108,C,A,0,13.610000000,100,0,165532,275926940,13.11,100,1,13.58,15,1,13,2,1,13.6,15,1,12.98,200,1,13.63,100,1,12.86,100,1,13.8,200,1,12.73,100,1,13.92,100,1,12.71,100,1,13.94,2,1,12.5,700,1,14.23,100,1,12.46,100,1,14.28,100,1,12.43,700,1,14.52,300,1,12.42,700,1,14.56,800,1,ARL,330789481
1956,2025-07-17T16:06:22.151326300Z,2025-07-17T16:06:22.151326300Z,10,2,1108,A,A,0,13.590000000,100,130,165532,275926940,13.11,100,1,13.58,15,1,13,2,1,13.59,100,1,12.98,200,1,13.6,15,1,12.86,100,1,13.63,100,1,12.73,100,1,13.8,200,1,12.71,100,1,13.92,100,1,12.5,700,1,13.94,2,1,12.46,100,1,14.23,100,1,12.43,700,1,14.28,100,1,12.42,700,1,14.52,300,1,ARL,331050989
1957,2025-07-17T16:06:22.151595415Z,2025-07-17T16:06:22.151595415Z,10,2,1108,C,A,0,13.800000000,100,0,165914,275926966,13.11,100,1,13.58,15,1,13,2,1,13.59,100,1,12.98,200,1,13.6,15,1,12.86,100,1,13.63,100,1,12.73,100,1,13.8,100,1,12.71,100,1,13.92,100,1,12.5,700,1,13.94,2,1,12.46,100,1,14.23,100,1,12.43,700,1,14.28,100,1,12.42,700,1,14.52,300,1,ARL,328614525
1958,2025-07-17T16:06:22.151595781Z,2025-07-17T16:06:22.151595781Z,10,2,1108,C,A,0,13.800000000,100,130,165548,275926967,13.11,100,1,13.58,15,1,13,2,1,13.59,100,1,12.98,200,1,13.6,15,1,12.86,100,1,13.63,100,1,12.73,100,1,13.92,100,1,12.71,100,1,13.94,2,1,12.5,700,1,14.23,100,1,12.46,100,1,14.28,100,1,12.43,700,1,14.52,300,1,12.42,700,1,14.56,800,1,ARL,328614529
1959,2025-07-17T16:06:22.152983326Z,2025-07-17T16:06:22.152983326Z,10,2,1108,C,A,0,15.790000000,100,0,165567,275927034,13.11,100,1,13.58,15,1,13,2,1,13.59,100,1,12.98,200,1,13.6,15,1,12.86,100,1,13.63,100,1,12.73,100,1,13.92,100,1,12.71,100,1,13.94,2,1,12.5,700,1,14.23,100,1,12.46,100,1,14.28,100,1,12.43,700,1,14.52,300,1,12.42,700,1,14.56,800,1,ARL,327870361
1960,2025-07-17T16:06:22.152983326Z,2025-07-17T16:06:22.152983326Z,10,2,1108,A,A,0,15.630000000,100,130,165567,275927034,13.11,100,1,13.58,15,1,13,2,1,13.59,100,1,12.98,200,1,13.6,15,1,12.86,100,1,13.63,100,1,12.73,100,1,13.92,100,1,12.71,100,1,13.94,2,1,12.5,700,1,14.23,100,1,12.46,100,1,14.28,100,1,12.43,700,1,14.52,300,1,12.42,700,1,14.56,800,1,ARL,331051145
1961,2025-07-17T16:06:22.153749481Z,2025-07-17T16:06:22.153749481Z,10,2,1108,C,A,0,14.700000000,100,0,166688,275927046,13.11,100,1,13.58,15,1,13,2,1,13.59,100,1,12.98,200,1,13.6,15,1,12.86,100,1,13.63,100,1,12.73,100,1,13.92,100,1,12.71,100,1,13.94,2,1,12.5,700,1,14.23,100,1,12.46,100,1,14.28,100,1,12.43,700,1,14.52,300,1,12.42,700,1,14.56,800,1,ARL,327868421
1962,2025-07-17T16:06:22.153749481Z,2025-07-17T16:06:22.153749481Z,10,2,1108,A,A,0,14.550000000,100,130,166688,275927046,13.11,100,1,13.58,15,1,13,2,1,13.59,100,1,12.98,200,1,13.6,15,1,12.86,100,1,13.63,100,1,12.73,100,1,13.92,100,1,12.71,100,1,13.94,2,1,12.5,700,1,14.23,100,1,12.46,100,1,14.28,100,1,12.43,700,1,14.52,300,1,12.42,700,1,14.55,100,1,ARL,331051173
1963,2025-07-17T16:06:22.155905240Z,2025-07-17T16:06:22.155905240Z,10,2,1108,C,A,0,14.520000000,100,0,165458,275927117,13.11,100,1,13.58,15,1,13,2,1,13.59,100,1,12.98,200,1,13.6,15,1,12.86,100,1,13.63,100,1,12.73,100,1,13.92,100,1,12.71,100,1,13.94,2,1,12.5,700,1,14.23,100,1,12.46,100,1,14.28,100,1,12.43,700,1,14.52,200,1,12.42,700,1,14.55,100,1,ARL,327869529
1964,2025-07-17T16:06:22.155905240Z,2025-07-17T16:06:22.155905240Z,10,2,1108,A,A,0,14.380000000,100,130,165458,275927117,13.11,100,1,13.58,15,1,13,2,1,13.59,100,1,12.98,200,1,13.6,15,1,12.86,100,1,13.63,100,1,12.73,100,1,13.92,100,1,12.71,100,1,13.94,2,1,12.5,700,1,14.23,100,1,12.46,100,1,14.28,100,1,12.43,700,1,14.38,100,1,12.42,700,1,14.52,200,1,ARL,331051369
1965,2025-07-17T16:06:22.177879233Z,2025-07-17T16:06:22.177879233Z,10,2,1108,C,A,0,14.700000000,100,0,165442,275927444,13.11,100,1,13.58,15,1,13,2,1,13.59,100,1,12.98,200,1,13.6,15,1,12.86,100,1,13.63,100,1,12.73,100,1,13.92,100,1,12.71,100,1,13.94,2,1,12.5,700,1,14.23,100,1,12.46,100,1,14.28,100,1,12.43,700,1,14.38,100,1,12.42,700,1,14.52,200,1,ARL,327873009
1966,2025-07-17T16:06:22.177879233Z,2025-07-17T16:06:22.177879233Z,10,2,1108,A,A,0,14.550000000,100,130,165442,275927444,13.11,100,1,13.58,15,1,13,2,1,13.59,100,1,12.98,200,1,13.6,15,1,12.86,100,1,13.63,100,1,12.73,100,1,13.92,100,1,12.71,100,1,13.94,2,1,12.5,700,1,14.23,100,1,12.46,100,1,14.28,100,1,12.43,700,1,14.38,100,1,12.42,700,1,14.52,200,1,ARL,331052197
1967,2025-07-17T16:06:24.519345743Z,2025-07-17T16:06:24.519345743Z,10,2,1108,A,A,0,13.600000000,100,130,165385,275968354,13.11,100,1,13.58,15,1,13,2,1,13.59,100,1,12.98,200,1,13.6,115,1,12.86,100,1,13.63,100,1,12.73,100,1,13.92,100,1,12.71,100,1,13.94,2,1,12.5,700,1,14.23,100,1,12.46,100,1,14.28,100,1,12.43,700,1,14.38,100,1,12.42,700,1,14.52,200,1,ARL,331104725
1968,2025-07-17T16:06:24.526194457Z,2025-07-17T16:06:24.526194457Z,10,2,1108,C,A,0,13.630000000,100,130,165259,275968393,13.11,100,1,13.58,15,1,13,2,1,13.59,100,1,12.98,200,1,13.6,115,1,12.86,100,1,13.92,100,1,12.73,100,1,13.94,2,1,12.71,100,1,14.23,100,1,12.5,700,1,14.28,100,1,12.46,100,1,14.38,100,1,12.43,700,1,14.52,200,1,12.42,700,1,14.55,200,1,ARL,331018065
1969,2025-07-17T16:06:26.610180184Z,2025-07-17T16:06:26.610180184Z,10,2,1108,C,A,0,13.940000000,2,0,165616,276013080,13.11,100,1,13.58,15,1,13,2,1,13.59,100,1,12.98,200,1,13.6,115,1,12.86,100,1,13.92,100,1,12.73,100,1,14.23,100,1,12.71,100,1,14.28,100,1,12.5,700,1,14.38,100,1,12.46,100,1,14.52,200,1,12.43,700,1,14.55,200,1,12.42,700,1,14.56,800,1,ARL,328351217
1970,2025-07-17T16:06:26.610180184Z,2025-07-17T16:06:26.610180184Z,10,2,1108,A,A,0,13.850000000,2,130,165616,276013080,13.11,100,1,13.58,15,1,13,2,1,13.59,100,1,12.98,200,1,13.6,115,1,12.86,100,1,13.85,2,1,12.73,100,1,13.92,100,1,12.71,100,1,14.23,100,1,12.5,700,1,14.28,100,1,12.46,100,1,14.38,100,1,12.43,700,1,14.52,200,1,12.42,700,1,14.55,200,1,ARL,331155889
1971,2025-07-17T16:06:30.625711923Z,2025-07-17T16:06:30.625711923Z,10,2,1108,A,A,0,14.270000000,700,130,165291,276103282,13.11,100,1,13.58,15,1,13,2,1,13.59,100,1,12.98,200,1,13.6,115,1,12.86,100,1,13.85,2,1,12.73,100,1,13.92,100,1,12.71,100,1,14.23,100,1,12.5,700,1,14.27,700,1,12.46,100,1,14.28,100,1,12.43,700,1,14.38,100,1,12.42,700,1,14.52,200,1,ARL,331257169
1972,2025-07-17T16:06:30.625790910Z,2025-07-17T16:06:30.625790910Z,10,2,1108,C,A,0,14.680000000,700,130,165397,276103283,13.11,100,1,13.58,15,1,13,2,1,13.59,100,1,12.98,200,1,13.6,115,1,12.86,100,1,13.85,2,1,12.73,100,1,13.92,100,1,12.71,100,1,14.23,100,1,12.5,700,1,14.27,700,1,12.46,100,1,14.28,100,1,12.43,700,1,14.38,100,1,12.42,700,1,14.52,200,1,ARL,325716945
1973,2025-07-17T16:06:31.127662311Z,2025-07-17T16:06:31.127662311Z,10,2,1108,A,A,0,14.480000000,700,130,165494,276118990,13.11,100,1,13.58,15,1,13,2,1,13.59,100,1,12.98,200,1,13.6,115,1,12.86,100,1,13.85,2,1,12.73,100,1,13.92,100,1,12.71,100,1,14.23,100,1,12.5,700,1,14.27,700,1,12.46,100,1,14.28,100,1,12.43,700,1,14.38,100,1,12.42,700,1,14.48,700,1,ARL,331272997
1974,2025-07-17T16:06:31.128416336Z,2025-07-17T16:06:31.128416336Z,10,2,1108,C,A,0,14.680000000,700,130,165495,276119017,13.11,100,1,13.58,15,1,13,2,1,13.59,100,1,12.98,200,1,13.6,115,1,12.86,100,1,13.85,2,1,12.73,100,1,13.92,100,1,12.71,100,1,14.23,100,1,12.5,700,1,14.27,700,1,12.46,100,1,14.28,100,1,12.43,700,1,14.38,100,1,12.42,700,1,14.48,700,1,ARL,289932801
1975,2025-07-17T16:06:31.990483799Z,2025-07-17T16:06:31.990483799Z,10,2,1108,C,A,0,13.600000000,15,130,165430,276135226,13.11,100,1,13.58,15,1,13,2,1,13.59,100,1,12.98,200,1,13.6,100,1,12.86,100,1,13.85,2,1,12.73,100,1,13.92,100,1,12.71,100,1,14.23,100,1,12.5,700,1,14.27,700,1,12.46,100,1,14.28,100,1,12.43,700,1,14.38,100,1,12.42,700,1,14.48,700,1,ARL,330788421
1976,2025-07-17T16:06:42.812641697Z,2025-07-17T16:06:42.812641697Z,10,2,1108,A,A,0,13.560000000,15,130,165399,276276783,13.11,100,1,13.56,15,1,13,2,1,13.58,15,1,12.98,200,1,13.59,100,1,12.86,100,1,13.6,100,1,12.73,100,1,13.85,2,1,12.71,100,1,13.92,100,1,12.5,700,1,14.23,100,1,12.46,100,1,14.27,700,1,12.43,700,1,14.28,100,1,12.42,700,1,14.38,100,1,ARL,331488089
1977,2025-07-17T16:06:43.012799164Z,2025-07-17T16:06:43.012799164Z,10,2,1108,C,A,0,13.590000000,100,0,166793,276279311,13.11,100,1,13.56,15,1,13,2,1,13.58,15,1,12.98,200,1,13.6,100,1,12.86,100,1,13.85,2,1,12.73,100,1,13.92,100,1,12.71,100,1,14.23,100,1,12.5,700,1,14.27,700,1,12.46,100,1,14.28,100,1,12.43,700,1,14.38,100,1,12.42,700,1,14.48,700,1,ARL,331050989
1978,2025-07-17T16:06:43.012799164Z,2025-07-17T16:06:43.012799164Z,10,2,1108,A,A,0,13.570000000,100,128,166793,276279311,13.11,100,1,13.56,15,1,13,2,1,13.57,100,1,12.98,200,1,13.58,15,1,12.86,100,1,13.6,100,1,12.73,100,1,13.85,2,1,12.71,100,1,13.92,100,1,12.5,700,1,14.23,100,1,12.46,100,1,14.27,700,1,12.43,700,1,14.28,100,1,12.42,700,1,14.38,100,1,ARL,331491049
1979,2025-07-17T16:06:43.013550575Z,2025-07-17T16:06:43.013550575Z,10,2,1108,C,A,0,14.670000000,100,0,165630,276279331,13.11,100,1,13.56,15,1,13,2,1,13.57,100,1,12.98,200,1,13.58,15,1,12.86,100,1,13.6,100,1,12.73,100,1,13.85,2,1,12.71,100,1,13.92,100,1,12.5,700,1,14.23,100,1,12.46,100,1,14.27,700,1,12.43,700,1,14.28,100,1,12.42,700,1,14.38,100,1,ARL,330789501
1980,2025-07-17T16:06:43.013550575Z,2025-07-17T16:06:43.013550575Z,10,2,1108,A,A,0,14.620000000,100,130,165630,276279331,13.11,100,1,13.56,15,1,13,2,1,13.57,100,1,12.98,200,1,13.58,15,1,12.86,100,1,13.6,100,1,12.73,100,1,13.85,2,1,12.71,100,1,13.92,100,1,12.5,700,1,14.23,100,1,12.46,100,1,14.27,700,1,12.43,700,1,14.28,100,1,12.42,700,1,14.38,100,1,ARL,331491077
1981,2025-07-17T16:06:43.024490355Z,2025-07-17T16:06:43.024490355Z,10,2,1108,C,A,0,13.920000000,100,130,165668,276279620,13.11,100,1,13.56,15,1,13,2,1,13.57,100,1,12.98,200,1,13.58,15,1,12.86,100,1,13.6,100,1,12.73,100,1,13.85,2,1,12.71,100,1,14.23,100,1,12.5,700,1,14.27,700,1,12.46,100,1,14.28,100,1,12.43,700,1,14.38,100,1,12.42,700,1,14.48,700,1,ARL,330359625
1982,2025-07-17T16:06:43.024543099Z,2025-07-17T16:06:43.024543099Z,10,2,1108,A,A,0,13.840000000,100,130,165205,276279621,13.11,100,1,13.56,15,1,13,2,1,13.57,100,1,12.98,200,1,13.58,15,1,12.86,100,1,13.6,100,1,12.73,100,1,13.84,100,1,12.71,100,1,13.85,2,1,12.5,700,1,14.23,100,1,12.46,100,1,14.27,700,1,12.43,700,1,14.28,100,1,12.42,700,1,14.38,100,1,ARL,331491269
1983,2025-07-17T16:06:49.613776144Z,2025-07-17T16:06:49.613776144Z,10,2,1108,C,A,0,13.580000000,15,130,165677,276382302,13.11,100,1,13.56,15,1,13,2,1,13.57,100,1,12.98,200,1,13.6,100,1,12.86,100,1,13.84,100,1,12.73,100,1,13.85,2,1,12.71,100,1,14.23,100,1,12.5,700,1,14.27,700,1,12.46,100,1,14.28,100,1,12.43,700,1,14.38,100,1,12.42,700,1,14.48,700,1,ARL,331050981
1984,2025-07-17T16:06:50.618504506Z,2025-07-17T16:06:50.618504506Z,10,2,1108,A,A,0,13.540000000,15,130,165337,276408477,13.11,100,1,13.54,15,1,13,2,1,13.56,15,1,12.98,200,1,13.57,100,1,12.86,100,1,13.6,100,1,12.73,100,1,13.84,100,1,12.71,100,1,13.85,2,1,12.5,700,1,14.23,100,1,12.46,100,1,14.27,700,1,12.43,700,1,14.28,100,1,12.42,700,1,14.38,100,1,ARL,331666961
1985,2025-07-17T16:06:50.626272828Z,2025-07-17T16:06:50.626272828Z,10,2,1108,A,A,0,13.580000000,100,130,165377,276408566,13.11,100,1,13.54,15,1,13,2,1,13.56,15,1,12.98,200,1,13.57,100,1,12.86,100,1,13.58,100,1,12.73,100,1,13.6,100,1,12.71,100,1,13.84,100,1,12.5,700,1,13.85,2,1,12.46,100,1,14.23,100,1,12.43,700,1,14.27,700,1,12.42,700,1,14.28,100,1,ARL,331667121
1986,2025-07-17T16:06:50.632947998Z,2025-07-17T16:06:50.632947998Z,10,2,1108,C,A,0,13.600000000,100,130,165559,276408644,13.11,100,1,13.54,15,1,13,2,1,13.56,15,1,12.98,200,1,13.57,100,1,12.86,100,1,13.58,100,1,12.73,100,1,13.84,100,1,12.71,100,1,13.85,2,1,12.5,700,1,14.23,100,1,12.46,100,1,14.27,700,1,12.43,700,1,14.28,100,1,12.42,700,1,14.38,100,1,ARL,331104725
1987,2025-07-17T16:06:51.754410704Z,2025-07-17T16:06:51.754410704Z,10,2,1108,C,A,0,13.570000000,100,0,165618,276428315,13.11,100,1,13.54,15,1,13,2,1,13.56,15,1,12.98,200,1,13.58,100,1,12.86,100,1,13.84,100,1,12.73,100,1,13.85,2,1,12.71,100,1,14.23,100,1,12.5,700,1,14.27,700,1,12.46,100,1,14.28,100,1,12.43,700,1,14.38,100,1,12.42,700,1,14.48,700,1,ARL,331491049
1988,2025-07-17T16:06:51.754410704Z,2025-07-17T16:06:51.754410704Z,10,2,1108,A,A,0,13.550000000,100,130,165618,276428315,13.11,100,1,13.54,15,1,13,2,1,13.55,100,1,12.98,200,1,13.56,15,1,12.86,100,1,13.58,100,1,12.73,100,1,13.84,100,1,12.71,100,1,13.85,2,1,12.5,700,1,14.23,100,1,12.46,100,1,14.27,700,1,12.43,700,1,14.28,100,1,12.42,700,1,14.38,100,1,ARL,331694265
1989,2025-07-17T16:06:51.757237300Z,2025-07-17T16:06:51.757237300Z,10,2,1108,C,B,0,13.000000000,2,0,165809,276428333,13.11,100,1,13.54,15,1,12.98,200,1,13.55,100,1,12.86,100,1,13.56,15,1,12.73,100,1,13.58,100,1,12.71,100,1,13.84,100,1,12.5,700,1,13.85,2,1,12.46,100,1,14.23,100,1,12.43,700,1,14.27,700,1,12.42,700,1,14.28,100,1,12.37,700,1,14.38,100,1,ARL,325967705
1990,2025-07-17T16:06:51.757237300Z,2025-07-17T16:06:51.757237300Z,10,2,1108,A,B,0,12.900000000,2,130,165809,276428333,13.11,100,1,13.54,15,1,12.98,200,1,13.55,100,1,12.9,2,1,13.56,15,1,12.86,100,1,13.58,100,1,12.73,100,1,13.84,100,1,12.71,100,1,13.85,2,1,12.5,700,1,14.23,100,1,12.46,100,1,14.27,700,1,12.43,700,1,14.28,100,1,12.42,700,1,14.38,100,1,ARL,331694297
1991,2025-07-17T16:06:55.056135380Z,2025-07-17T16:06:55.056135380Z,10,2,1108,C,A,0,13.540000000,15,130,165481,276516227,13.11,100,1,13.55,100,1,12.98,200,1,13.56,15,1,12.9,2,1,13.58,100,1,12.86,100,1,13.84,100,1,12.73,100,1,13.85,2,1,12.71,100,1,14.23,100,1,12.5,700,1,14.27,700,1,12.46,100,1,14.28,100,1,12.43,700,1,14.38,100,1,12.42,700,1,14.48,700,1,ARL,331666961
1992,2025-07-17T16:06:55.056301001Z,2025-07-17T16:06:55.056301001Z,10,2,1108,C,A,0,13.560000000,15,130,165230,276516239,13.11,100,1,13.55,100,1,12.98,200,1,13.58,100,1,12.9,2,1,13.84,100,1,12.86,100,1,13.85,2,1,12.73,100,1,14.23,100,1,12.71,100,1,14.27,700,1,12.5,700,1,14.28,100,1,12.46,100,1,14.38,100,1,12.43,700,1,14.48,700,1,12.42,700,1,14.52,200,1,ARL,331488089
1993,2025-07-17T16:07:00.010829521Z,2025-07-17T16:07:00.010829521Z,10,2,1108,C,A,0,13.550000000,100,130,166037,276611719,13.11,100,1,13.58,100,1,12.98,200,1,13.84,100,1,12.9,2,1,13.85,2,1,12.86,100,1,14.23,100,1,12.73,100,1,14.27,700,1,12.71,100,1,14.28,100,1,12.5,700,1,14.38,100,1,12.46,100,1,14.48,700,1,12.43,700,1,14.52,200,1,12.42,700,1,14.55,200,1,ARL,331694265
1994,2025-07-17T16:07:00.023683961Z,2025-07-17T16:07:00.023683961Z,10,2,1108,C,A,0,13.580000000,100,130,165219,276613073,13.11,100,1,13.84,100,1,12.98,200,1,13.85,2,1,12.9,2,1,14.23,100,1,12.86,100,1,14.27,700,1,12.73,100,1,14.28,100,1,12.71,100,1,14.38,100,1,12.5,700,1,14.48,700,1,12.46,100,1,14.52,200,1,12.43,700,1,14.55,200,1,12.42,700,1,14.56,800,1,ARL,331667121
1995,2025-07-17T16:07:00.023752163Z,2025-07-17T16:07:00.023752163Z,10,2,1108,C,A,0,14.270000000,700,130,165380,276613077,13.11,100,1,13.84,100,1,12.98,200,1,13.85,2,1,12.9,2,1,14.23,100,1,12.86,100,1,14.28,100,1,12.73,100,1,14.38,100,1,12.71,100,1,14.48,700,1,12.5,700,1,14.52,200,1,12.46,100,1,14.55,200,1,12.43,700,1,14.56,800,1,12.42,700,1,14.6,700,1,ARL,331257169
1996,2025-07-17T16:07:00.023815326Z,2025-07-17T16:07:00.023815326Z,10,2,1108,A,A,0,14.510000000,700,130,165479,276613078,13.11,100,1,13.84,100,1,12.98,200,1,13.85,2,1,12.9,2,1,14.23,100,1,12.86,100,1,14.28,100,1,12.73,100,1,14.38,100,1,12.71,100,1,14.48,700,1,12.5,700,1,14.51,700,1,12.46,100,1,14.52,200,1,12.43,700,1,14.55,200,1,12.42,700,1,14.56,800,1,ARL,331926981
1997,2025-07-17T16:07:00.024424816Z,2025-07-17T16:07:00.024424816Z,10,2,1108,C,A,0,14.620000000,100,0,165467,276613110,13.11,100,1,13.84,100,1,12.98,200,1,13.85,2,1,12.9,2,1,14.23,100,1,12.86,100,1,14.28,100,1,12.73,100,1,14.38,100,1,12.71,100,1,14.48,700,1,12.5,700,1,14.51,700,1,12.46,100,1,14.52,200,1,12.43,700,1,14.55,200,1,12.42,700,1,14.56,800,1,ARL,331491077
1998,2025-07-17T16:07:00.024424816Z,2025-07-17T16:07:00.024424816Z,10,2,1108,A,A,0,14.880000000,100,130,165467,276613110,13.11,100,1,13.84,100,1,12.98,200,1,13.85,2,1,12.9,2,1,14.23,100,1,12.86,100,1,14.28,100,1,12.73,100,1,14.38,100,1,12.71,100,1,14.48,700,1,12.5,700,1,14.51,700,1,12.46,100,1,14.52,200,1,12.43,700,1,14.55,200,1,12.42,700,1,14.56,800,1,ARL,331927017
1999,2025-07-17T16:07:00.025064913Z,2025-07-17T16:07:00.025064913Z,10,2,1108,C,A,0,14.230000000,100,130,166251,276613157,13.11,100,1,13.84,100,1,12.98,200,1,13.85,2,1,12.9,2,1,14.28,100,1,12.86,100,1,14.38,100,1,12.73,100,1,14.48,700,1,12.71,100,1,14.51,700,1,12.5,700,1,14.52,200,1,12.46,100,1,14.55,200,1,12.43,700,1,14.56,800,1,12.42,700,1,14.6,700,1,ARL,329074833
2000,2025-07-17T16:07:00.025422082Z,2025-07-17T16:07:00.025422082Z,10,2,1108,A,A,0,14.460000000,100,130,165467,276613175,13.11,100,1,13.84,100,1,12.98,200,1,13.85,2,1,12.9,2,1,14.28,100,1,12.86,100,1,14.38,100,1,12.73,100,1,14.46,100,1,12.71,100,1,14.48,700,1,12.5,700,1,14.51,700,1,12.46,100,1,14.52,200,1,12.43,700,1,14.55,200,1,12.42,700,1,14.56,800,1,ARL,331927161
2001,2025-07-17T16:07:00.025628157Z,2025-07-17T16:07:00.025628157Z,10,2,1108,A,A,0,13.590000000,100,130,165103,276613194,13.11,100,1,13.59,100,1,12.98,200,1,13.84,100,1,12.9,2,1,13.85,2,1,12.86,100,1,14.28,100,1,12.73,100,1,14.38,100,1,12.71,100,1,14.46,100,1,12.5,700,1,14.48,700,1,12.46,100,1,14.51,700,1,12.43,700,1,14.52,200,1,12.42,700,1,14.55,200,1,ARL,331927177
2002,2025-07-17T16:07:00.026833761Z,2025-07-17T16:07:00.026833761Z,10,2,1108,C,A,0,13.590000000,100,130,164934,276613224,13.11,100,1,13.84,100,1,12.98,200,1,13.85,2,1,12.9,2,1,14.28,100,1,12.86,100,1,14.38,100,1,12.73,100,1,14.46,100,1,12.71,100,1,14.48,700,1,12.5,700,1,14.51,700,1,12.46,100,1,14.52,200,1,12.43,700,1,14.55,200,1,12.42,700,1,14.56,800,1,ARL,331927177
2003,2025-07-17T16:07:00.032596898Z,2025-07-17T16:07:00.032596898Z,10,2,1108,C,A,0,14.380000000,100,130,165284,276613329,13.11,100,1,13.84,100,1,12.98,200,1,13.85,2,1,12.9,2,1,14.28,100,1,12.86,100,1,14.46,100,1,12.73,100,1,14.48,700,1,12.71,100,1,14.51,700,1,12.5,700,1,14.52,200,1,12.46,100,1,14.55,200,1,12.43,700,1,14.56,800,1,12.42,700,1,14.6,700,1,ARL,331051369
2004,2025-07-17T16:07:00.032711777Z,2025-07-17T16:07:00.032711777Z,10,2,1108,A,A,0,14.630000000,100,130,165170,276613336,13.11,100,1,13.84,100,1,12.98,200,1,13.85,2,1,12.9,2,1,14.28,100,1,12.86,100,1,14.46,100,1,12.73,100,1,14.48,700,1,12.71,100,1,14.51,700,1,12.5,700,1,14.52,200,1,12.46,100,1,14.55,200,1,12.43,700,1,14.56,800,1,12.42,700,1,14.6,700,1,ARL,331927477
2005,2025-07-17T16:07:00.045359807Z,2025-07-17T16:07:00.045359807Z,10,2,1108,C,A,0,13.840000000,100,130,165240,276613663,13.11,100,1,13.85,2,1,12.98,200,1,14.28,100,1,12.9,2,1,14.46,100,1,12.86,100,1,14.48,700,1,12.73,100,1,14.51,700,1,12.71,100,1,14.52,200,1,12.5,700,1,14.55,200,1,12.46,100,1,14.56,800,1,12.43,700,1,14.6,700,1,12.42,700,1,14.63,100,1,ARL,331491269
2006,2025-07-17T16:07:00.045394317Z,2025-07-17T16:07:00.045394317Z,10,2,1108,C,A,0,14.510000000,700,130,164955,276613664,13.11,100,1,13.85,2,1,12.98,200,1,14.28,100,1,12.9,2,1,14.46,100,1,12.86,100,1,14.48,700,1,12.73,100,1,14.52,200,1,12.71,100,1,14.55,200,1,12.5,700,1,14.56,800,1,12.46,100,1,14.6,700,1,12.43,700,1,14.63,100,1,12.42,700,1,14.88,100,1,ARL,331926981
2007,2025-07-17T16:07:00.045409635Z,2025-07-17T16:07:00.045409635Z,10,2,1108,A,A,0,14.090000000,100,130,165151,276613665,13.11,100,1,13.85,2,1,12.98,200,1,14.09,100,1,12.9,2,1,14.28,100,1,12.86,100,1,14.46,100,1,12.73,100,1,14.48,700,1,12.71,100,1,14.52,200,1,12.5,700,1,14.55,200,1,12.46,100,1,14.56,800,1,12.43,700,1,14.6,700,1,12.42,700,1,14.63,100,1,ARL,331927857
2008,2025-07-17T16:07:00.046672908Z,2025-07-17T16:07:00.046672908Z,10,2,1108,C,A,0,14.090000000,100,130,165694,276613680,13.11,100,1,13.85,2,1,12.98,200,1,14.28,100,1,12.9,2,1,14.46,100,1,12.86,100,1,14.48,700,1,12.73,100,1,14.52,200,1,12.71,100,1,14.55,200,1,12.5,700,1,14.56,800,1,12.46,100,1,14.6,700,1,12.43,700,1,14.63,100,1,12.42,700,1,14.88,100,1,ARL,331927857
2009,2025-07-17T16:07:00.046721624Z,2025-07-17T16:07:00.046721624Z,10,2,1108,A,A,0,13.860000000,100,130,165381,276613681,13.11,100,1,13.85,2,1,12.98,200,1,13.86,100,1,12.9,2,1,14.28,100,1,12.86,100,1,14.46,100,1,12.73,100,1,14.48,700,1,12.71,100,1,14.52,200,1,12.5,700,1,14.55,200,1,12.46,100,1,14.56,800,1,12.43,700,1,14.6,700,1,12.42,700,1,14.63,100,1,ARL,331927877
2010,2025-07-17T16:07:00.047544064Z,2025-07-17T16:07:00.047544064Z,10,2,1108,C,A,0,13.860000000,100,130,164872,276613692,13.11,100,1,13.85,2,1,12.98,200,1,14.28,100,1,12.9,2,1,14.46,100,1,12.86,100,1,14.48,700,1,12.73,100,1,14.52,200,1,12.71,100,1,14.55,200,1,12.5,700,1,14.56,800,1,12.46,100,1,14.6,700,1,12.43,700,1,14.63,100,1,12.42,700,1,14.88,100,1,ARL,331927877
2011,2025-07-17T16:07:00.047590313Z,2025-07-17T16:07:00.047590313Z,10,2,1108,A,A,0,14.120000000,100,130,165185,276613693,13.11,100,1,13.85,2,1,12.98,200,1,14.12,100,1,12.9,2,1,14.28,100,1,12.86,100,1,14.46,100,1,12.73,100,1,14.48,700,1,12.71,100,1,14.52,200,1,12.5,700,1,14.55,200,1,12.46,100,1,14.56,800,1,12.43,700,1,14.6,700,1,12.42,700,1,14.63,100,1,ARL,331927921
2012,2025-07-17T16:07:00.053283700Z,2025-07-17T16:07:00.053283700Z,10,2,1108,C,A,0,14.120000000,100,130,164970,276613731,13.11,100,1,13.85,2,1,12.98,200,1,14.28,100,1,12.9,2,1,14.46,100,1,12.86,100,1,14.48,700,1,12.73,100,1,14.52,200,1,12.71,100,1,14.55,200,1,12.5,700,1,14.56,800,1,12.46,100,1,14.6,700,1,12.43,700,1,14.63,100,1,12.42,700,1,14.88,100,1,ARL,331927921
2013,2025-07-17T16:07:00.053329959Z,2025-07-17T16:07:00.053329959Z,10,2,1108,A,A,0,14.260000000,100,130,165136,276613732,13.11,100,1,13.85,2,1,12.98,200,1,14.26,100,1,12.9,2,1,14.28,100,1,12.86,100,1,14.46,100,1,12.73,100,1,14.48,700,1,12.71,100,1,14.52,200,1,12.5,700,1,14.55,200,1,12.46,100,1,14.56,800,1,12.43,700,1,14.6,700,1,12.42,700,1,14.63,100,1,ARL,331928009
2014,2025-07-17T16:07:00.057644427Z,2025-07-17T16:07:00.057644427Z,10,2,1108,C,A,0,14.550000000,100,0,165430,276613800,13.11,100,1,13.85,2,1,12.98,200,1,14.26,100,1,12.9,2,1,14.28,100,1,12.86,100,1,14.46,100,1,12.73,100,1,14.48,700,1,12.71,100,1,14.52,200,1,12.5,700,1,14.55,100,1,12.46,100,1,14.56,800,1,12.43,700,1,14.6,700,1,12.42,700,1,14.63,100,1,ARL,331052197
2015,2025-07-17T16:07:00.057644427Z,2025-07-17T16:07:00.057644427Z,10,2,1108,A,A,0,14.960000000,100,130,165430,276613800,13.11,100,1,13.85,2,1,12.98,200,1,14.26,100,1,12.9,2,1,14.28,100,1,12.86,100,1,14.46,100,1,12.73,100,1,14.48,700,1,12.71,100,1,14.52,200,1,12.5,700,1,14.55,100,1,12.46,100,1,14.56,800,1,12.43,700,1,14.6,700,1,12.42,700,1,14.63,100,1,ARL,331928129
2016,2025-07-17T16:07:00.070325784Z,2025-07-17T16:07:00.070325784Z,10,2,1108,C,A,0,14.260000000,100,130,165051,276614087,13.11,100,1,13.85,2,1,12.98,200,1,14.28,100,1,12.9,2,1,14.46,100,1,12.86,100,1,14.48,700,1,12.73,100,1,14.52,200,1,12.71,100,1,14.55,100,1,12.5,700,1,14.56,800,1,12.46,100,1,14.6,700,1,12.43,700,1,14.63,100,1,12.42,700,1,14.88,100,1,ARL,331928009
2017,2025-07-17T16:07:00.070373975Z,2025-07-17T16:07:00.070373975Z,10,2,1108,A,A,0,14.140000000,100,130,165247,276614089,13.11,100,1,13.85,2,1,12.98,200,1,14.14,100,1,12.9,2,1,14.28,100,1,12.86,100,1,14.46,100,1,12.73,100,1,14.48,700,1,12.71,100,1,14.52,200,1,12.5,700,1,14.55,100,1,12.46,100,1,14.56,800,1,12.43,700,1,14.6,700,1,12.42,700,1,14.63,100,1,ARL,331929033
2018,2025-07-17T16:07:00.071194493Z,2025-07-17T16:07:00.071194493Z,10,2,1108,C,A,0,14.140000000,100,130,164857,276614094,13.11,100,1,13.85,2,1,12.98,200,1,14.28,100,1,12.9,2,1,14.46,100,1,12.86,100,1,14.48,700,1,12.73,100,1,14.52,200,1,12.71,100,1,14.55,100,1,12.5,700,1,14.56,800,1,12.46,100,1,14.6,700,1,12.43,700,1,14.63,100,1,12.42,700,1,14.88,100,1,ARL,331929033
2019,2025-07-17T16:07:00.071239867Z,2025-07-17T16:07:00.071239867Z,10,2,1108,A,A,0,14.260000000,100,130,165238,276614095,13.11,100,1,13.85,2,1,12.98,200,1,14.26,100,1,12.9,2,1,14.28,100,1,12.86,100,1,14.46,100,1,12.73,100,1,14.48,700,1,12.71,100,1,14.52,200,1,12.5,700,1,14.55,100,1,12.46,100,1,14.56,800,1,12.43,700,1,14.6,700,1,12.42,700,1,14.63,100,1,ARL,331929041
2020,2025-07-17T16:07:00.074415631Z,2025-07-17T16:07:00.074415631Z,10,2,1108,C,A,0,14.880000000,100,0,165315,276614119,13.11,100,1,13.85,2,1,12.98,200,1,14.26,100,1,12.9,2,1,14.28,100,1,12.86,100,1,14.46,100,1,12.73,100,1,14.48,700,1,12.71,100,1,14.52,200,1,12.5,700,1,14.55,100,1,12.46,100,1,14.56,800,1,12.43,700,1,14.6,700,1,12.42,700,1,14.63,100,1,ARL,331927017
2021,2025-07-17T16:07:00.074415631Z,2025-07-17T16:07:00.074415631Z,10,2,1108,A,A,0,15.060000000,100,130,165315,276614119,13.11,100,1,13.85,2,1,12.98,200,1,14.26,100,1,12.9,2,1,14.28,100,1,12.86,100,1,14.46,100,1,12.73,100,1,14.48,700,1,12.71,100,1,14.52,200,1,12.5,700,1,14.55,100,1,12.46,100,1,14.56,800,1,12.43,700,1,14.6,700,1,12.42,700,1,14.63,100,1,ARL,331929065
2022,2025-07-17T16:07:00.084965637Z,2025-07-17T16:07:00.084965637Z,10,2,1108,C,A,0,15.070000000,100,0,165626,276614295,13.11,100,1,13.85,2,1,12.98,200,1,14.26,100,1,12.9,2,1,14.28,100,1,12.86,100,1,14.46,100,1,12.73,100,1,14.48,700,1,12.71,100,1,14.52,200,1,12.5,700,1,14.55,100,1,12.46,100,1,14.56,800,1,12.43,700,1,14.6,700,1,12.42,700,1,14.63,100,1,ARL,326837501
2023,2025-07-17T16:07:00.084965637Z,2025-07-17T16:07:00.084965637Z,10,2,1108,A,A,0,15.380000000,100,130,165626,276614295,13.11,100,1,13.85,2,1,12.98,200,1,14.26,100,1,12.9,2,1,14.28,100,1,12.86,100,1,14.46,100,1,12.73,100,1,14.48,700,1,12.71,100,1,14.52,200,1,12.5,700,1,14.55,100,1,12.46,100,1,14.56,800,1,12.43,700,1,14.6,700,1,12.42,700,1,14.63,100,1,ARL,331929445
2024,2025-07-17T16:07:00.090194106Z,2025-07-17T16:07:00.090194106Z,10,2,1108,C,A,0,14.550000000,100,0,165651,276614378,13.11,100,1,13.85,2,1,12.98,200,1,14.26,100,1,12.9,2,1,14.28,100,1,12.86,100,1,14.46,100,1,12.73,100,1,14.48,700,1,12.71,100,1,14.52,200,1,12.5,700,1,14.56,800,1,12.46,100,1,14.6,700,1,12.43,700,1,14.63,100,1,12.42,700,1,14.96,100,1,ARL,331051173
2025,2025-07-17T16:07:00.090194106Z,2025-07-17T16:07:00.090194106Z,10,2,1108,A,A,0,14.960000000,100,130,165651,276614378,13.11,100,1,13.85,2,1,12.98,200,1,14.26,100,1,12.9,2,1,14.28,100,1,12.86,100,1,14.46,100,1,12.73,100,1,14.48,700,1,12.71,100,1,14.52,200,1,12.5,700,1,14.56,800,1,12.46,100,1,14.6,700,1,12.43,700,1,14.63,100,1,12.42,700,1,14.96,200,1,ARL,331929633
2026,2025-07-17T16:07:00.101927028Z,2025-07-17T16:07:00.101927028Z,10,2,1108,A,A,0,14.680000000,700,130,165119,276614699,13.11,100,1,13.85,2,1,12.98,200,1,14.26,100,1,12.9,2,1,14.28,100,1,12.86,100,1,14.46,100,1,12.73,100,1,14.48,700,1,12.71,100,1,14.52,200,1,12.5,700,1,14.56,800,1,12.46,100,1,14.6,700,1,12.43,700,1,14.63,100,1,12.42,700,1,14.68,700,1,ARL,331929977
2027,2025-07-17T16:07:00.287416733Z,2025-07-17T16:07:00.287416733Z,10,2,1108,C,A,0,17.290000000,100,0,165715,276617288,13.11,100,1,13.85,2,1,12.98,200,1,14.26,100,1,12.9,2,1,14.28,100,1,12.86,100,1,14.46,100,1,12.73,100,1,14.48,700,1,12.71,100,1,14.52,200,1,12.5,700,1,14.56,800,1,12.46,100,1,14.6,700,1,12.43,700,1,14.63,100,1,12.42,700,1,14.68,700,1,ARL,330789509
2028,2025-07-17T16:07:00.287416733Z,2025-07-17T16:07:00.287416733Z,10,2,1108,A,A,0,17.760000000,100,130,165715,276617288,13.11,100,1,13.85,2,1,12.98,200,1,14.26,100,1,12.9,2,1,14.28,100,1,12.86,100,1,14.46,100,1,12.73,100,1,14.48,700,1,12.71,100,1,14.52,200,1,12.5,700,1,14.56,800,1,12.46,100,1,14.6,700,1,12.43,700,1,14.63,100,1,12.42,700,1,14.68,700,1,ARL,331934277
2029,2025-07-17T16:07:00.293454856Z,2025-07-17T16:07:00.293454856Z,10,2,1108,C,A,0,15.630000000,100,0,165578,276617317,13.11,100,1,13.85,2,1,12.98,200,1,14.26,100,1,12.9,2,1,14.28,100,1,12.86,100,1,14.46,100,1,12.73,100,1,14.48,700,1,12.71,100,1,14.52,200,1,12.5,700,1,14.56,800,1,12.46,100,1,14.6,700,1,12.43,700,1,14.63,100,1,12.42,700,1,14.68,700,1,ARL,331051145
2030,2025-07-17T16:07:00.293454856Z,2025-07-17T16:07:00.293454856Z,10,2,1108,A,A,0,16.080000000,100,130,165578,276617317,13.11,100,1,13.85,2,1,12.98,200,1,14.26,100,1,12.9,2,1,14.28,100,1,12.86,100,1,14.46,100,1,12.73,100,1,14.48,700,1,12.71,100,1,14.52,200,1,12.5,700,1,14.56,800,1,12.46,100,1,14.6,700,1,12.43,700,1,14.63,100,1,12.42,700,1,14.68,700,1,ARL,331934377
2031,2025-07-17T16:07:00.494492099Z,2025-07-17T16:07:00.494492099Z,10,2,1108,A,A,0,13.860000000,100,130,165396,276622423,13.11,100,1,13.85,2,1,12.98,200,1,13.86,100,1,12.9,2,1,14.26,100,1,12.86,100,1,14.28,100,1,12.73,100,1,14.46,100,1,12.71,100,1,14.48,700,1,12.5,700,1,14.52,200,1,12.46,100,1,14.56,800,1,12.43,700,1,14.6,700,1,12.42,700,1,14.63,100,1,ARL,331942821
2032,2025-07-17T16:07:00.495152219Z,2025-07-17T16:07:00.495152219Z,10,2,1108,C,B,0,12.360000000,100,0,166026,276622452,13.11,100,1,13.85,2,1,12.98,200,1,13.86,100,1,12.9,2,1,14.26,100,1,12.86,100,1,14.28,100,1,12.73,100,1,14.46,100,1,12.71,100,1,14.48,700,1,12.5,700,1,14.52,200,1,12.46,100,1,14.56,800,1,12.43,700,1,14.6,700,1,12.42,700,1,14.63,100,1,ARL,288723817
2033,2025-07-17T16:07:00.495152219Z,2025-07-17T16:07:00.495152219Z,10,2,1108,A,B,0,12.490000000,100,130,166026,276622452,13.11,100,1,13.85,2,1,12.98,200,1,13.86,100,1,12.9,2,1,14.26,100,1,12.86,100,1,14.28,100,1,12.73,100,1,14.46,100,1,12.71,100,1,14.48,700,1,12.5,700,1,14.52,200,1,12.49,100,1,14.56,800,1,12.46,100,1,14.6,700,1,12.43,700,1,14.63,100,1,ARL,331942901
2034,2025-07-17T16:07:00.495233001Z,2025-07-17T16:07:00.495233001Z,10,2,1108,C,A,0,15.060000000,100,0,165643,276622455,13.11,100,1,13.85,2,1,12.98,200,1,13.86,100,1,12.9,2,1,14.26,100,1,12.86,100,1,14.28,100,1,12.73,100,1,14.46,100,1,12.71,100,1,14.48,700,1,12.5,700,1,14.52,200,1,12.49,100,1,14.56,800,1,12.46,100,1,14.6,700,1,12.43,700,1,14.63,100,1,ARL,331929065
2035,2025-07-17T16:07:00.495233001Z,2025-07-17T16:07:00.495233001Z,10,2,1108,A,A,0,14.930000000,100,130,165643,276622455,13.11,100,1,13.85,2,1,12.98,200,1,13.86,100,1,12.9,2,1,14.26,100,1,12.86,100,1,14.28,100,1,12.73,100,1,14.46,100,1,12.71,100,1,14.48,700,1,12.5,700,1,14.52,200,1,12.49,100,1,14.56,800,1,12.46,100,1,14.6,700,1,12.43,700,1,14.63,100,1,ARL,331942913
2036,2025-07-17T16:07:00.495823953Z,2025-07-17T16:07:00.495823953Z,10,2,1108,C,B,0,12.360000000,100,0,165645,276622469,13.11,100,1,13.85,2,1,12.98,200,1,13.86,100,1,12.9,2,1,14.26,100,1,12.86,100,1,14.28,100,1,12.73,100,1,14.46,100,1,12.71,100,1,14.48,700,1,12.5,700,1,14.52,200,1,12.49,100,1,14.56,800,1,12.46,100,1,14.6,700,1,12.43,700,1,14.63,100,1,ARL,288723813
2037,2025-07-17T16:07:00.495823953Z,2025-07-17T16:07:00.495823953Z,10,2,1108,A,B,0,12.490000000,100,130,165645,276622469,13.11,100,1,13.85,2,1,12.98,200,1,13.86,100,1,12.9,2,1,14.26,100,1,12.86,100,1,14.28,100,1,12.73,100,1,14.46,100,1,12.71,100,1,14.48,700,1,12.5,700,1,14.52,200,1,12.49,200,1,14.56,800,1,12.46,100,1,14.6,700,1,12.43,700,1,14.63,100,1,ARL,331942945
2038,2025-07-17T16:07:00.496317847Z,2025-07-17T16:07:00.496317847Z,10,2,1108,C,A,0,17.760000000,100,0,165613,276622478,13.11,100,1,13.85,2,1,12.98,200,1,13.86,100,1,12.9,2,1,14.26,100,1,12.86,100,1,14.28,100,1,12.73,100,1,14.46,100,1,12.71,100,1,14.48,700,1,12.5,700,1,14.52,200,1,12.49,200,1,14.56,800,1,12.46,100,1,14.6,700,1,12.43,700,1,14.63,100,1,ARL,331934277
2039,2025-07-17T16:07:00.496317847Z,2025-07-17T16:07:00.496317847Z,10,2,1108,A,A,0,17.610000000,100,130,165613,276622478,13.11,100,1,13.85,2,1,12.98,200,1,13.86,100,1,12.9,2,1,14.26,100,1,12.86,100,1,14.28,100,1,12.73,100,1,14.46,100,1,12.71,100,1,14.48,700,1,12.5,700,1,14.52,200,1,12.49,200,1,14.56,800,1,12.46,100,1,14.6,700,1,12.43,700,1,14.63,100,1,ARL,331942981
2040,2025-07-17T16:07:00.499501052Z,2025-07-17T16:07:00.499501052Z,10,2,1108,C,A,0,14.260000000,100,130,165097,276622569,13.11,100,1,13.85,2,1,12.98,200,1,13.86,100,1,12.9,2,1,14.28,100,1,12.86,100,1,14.46,100,1,12.73,100,1,14.48,700,1,12.71,100,1,14.52,200,1,12.5,700,1,14.56,800,1,12.49,200,1,14.6,700,1,12.46,100,1,14.63,100,1,12.43,700,1,14.68,700,1,ARL,331929041
2041,2025-07-17T16:07:00.499549738Z,2025-07-17T16:07:00.499549738Z,10,2,1108,A,A,0,14.140000000,100,130,165180,276622571,13.11,100,1,13.85,2,1,12.98,200,1,13.86,100,1,12.9,2,1,14.14,100,1,12.86,100,1,14.28,100,1,12.73,100,1,14.46,100,1,12.71,100,1,14.48,700,1,12.5,700,1,14.52,200,1,12.49,200,1,14.56,800,1,12.46,100,1,14.6,700,1,12.43,700,1,14.63,100,1,ARL,331943133
2042,2025-07-17T16:07:22.814776694Z,2025-07-17T16:07:22.814776694Z,10,2,1108,A,A,0,13.690000000,15,130,165115,276946179,13.11,100,1,13.69,15,1,12.98,200,1,13.85,2,1,12.9,2,1,13.86,100,1,12.86,100,1,14.14,100,1,12.73,100,1,14.28,100,1,12.71,100,1,14.46,100,1,12.5,700,1,14.48,700,1,12.49,200,1,14.52,200,1,12.46,100,1,14.56,800,1,12.43,700,1,14.6,700,1,ARL,332385317
2043,2025-07-17T16:07:22.814891345Z,2025-07-17T16:07:22.814891345Z,10,2,1108,C,A,0,13.860000000,100,0,166162,276946183,13.11,100,1,13.69,15,1,12.98,200,1,13.85,2,1,12.9,2,1,14.14,100,1,12.86,100,1,14.28,100,1,12.73,100,1,14.46,100,1,12.71,100,1,14.48,700,1,12.5,700,1,14.52,200,1,12.49,200,1,14.56,800,1,12.46,100,1,14.6,700,1,12.43,700,1,14.63,100,1,ARL,331942821
2044,2025-07-17T16:07:22.814891345Z,2025-07-17T16:07:22.814891345Z,10,2,1108,A,A,0,13.700000000,100,130,166162,276946183,13.11,100,1,13.69,15,1,12.98,200,1,13.7,100,1,12.9,2,1,13.85,2,1,12.86,100,1,14.14,100,1,12.73,100,1,14.28,100,1,12.71,100,1,14.46,100,1,12.5,700,1,14.48,700,1,12.49,200,1,14.52,200,1,12.46,100,1,14.56,800,1,12.43,700,1,14.6,700,1,ARL,332385325
2045,2025-07-17T16:07:22.815625345Z,2025-07-17T16:07:22.815625345Z,10,2,1108,C,A,0,14.930000000,100,0,165545,276946264,13.11,100,1,13.69,15,1,12.98,200,1,13.7,100,1,12.9,2,1,13.85,2,1,12.86,100,1,14.14,100,1,12.73,100,1,14.28,100,1,12.71,100,1,14.46,100,1,12.5,700,1,14.48,700,1,12.49,200,1,14.52,200,1,12.46,100,1,14.56,800,1,12.43,700,1,14.6,700,1,ARL,331942913
2046,2025-07-17T16:07:22.815625345Z,2025-07-17T16:07:22.815625345Z,10,2,1108,A,A,0,14.760000000,100,130,165545,276946264,13.11,100,1,13.69,15,1,12.98,200,1,13.7,100,1,12.9,2,1,13.85,2,1,12.86,100,1,14.14,100,1,12.73,100,1,14.28,100,1,12.71,100,1,14.46,100,1,12.5,700,1,14.48,700,1,12.49,200,1,14.52,200,1,12.46,100,1,14.56,800,1,12.43,700,1,14.6,700,1,ARL,332385501
2047,2025-07-17T16:07:22.817341789Z,2025-07-17T16:07:22.817341789Z,10,2,1108,C,A,0,14.960000000,100,0,166020,276946309,13.11,100,1,13.69,15,1,12.98,200,1,13.7,100,1,12.9,2,1,13.85,2,1,12.86,100,1,14.14,100,1,12.73,100,1,14.28,100,1,12.71,100,1,14.46,100,1,12.5,700,1,14.48,700,1,12.49,200,1,14.52,200,1,12.46,100,1,14.56,800,1,12.43,700,1,14.6,700,1,ARL,331929633
2048,2025-07-17T16:07:22.817341789Z,2025-07-17T16:07:22.817341789Z,10,2,1108,A,A,0,14.660000000,100,130,166020,276946309,13.11,100,1,13.69,15,1,12.98,200,1,13.7,100,1,12.9,2,1,13.85,2,1,12.86,100,1,14.14,100,1,12.73,100,1,14.28,100,1,12.71,100,1,14.46,100,1,12.5,700,1,14.48,700,1,12.49,200,1,14.52,200,1,12.46,100,1,14.56,800,1,12.43,700,1,14.6,700,1,ARL,332385565
2049,2025-07-17T16:07:22.817459170Z,2025-07-17T16:07:22.817459170Z,10,2,1108,C,A,0,15.380000000,100,0,165529,276946313,13.11,100,1,13.69,15,1,12.98,200,1,13.7,100,1,12.9,2,1,13.85,2,1,12.86,100,1,14.14,100,1,12.73,100,1,14.28,100,1,12.71,100,1,14.46,100,1,12.5,700,1,14.48,700,1,12.49,200,1,14.52,200,1,12.46,100,1,14.56,800,1,12.43,700,1,14.6,700,1,ARL,331929445
2050,2025-07-17T16:07:22.817459170Z,2025-07-17T16:07:22.817459170Z,10,2,1108,A,A,0,15.070000000,100,130,165529,276946313,13.11,100,1,13.69,15,1,12.98,200,1,13.7,100,1,12.9,2,1,13.85,2,1,12.86,100,1,14.14,100,1,12.73,100,1,14.28,100,1,12.71,100,1,14.46,100,1,12.5,700,1,14.48,700,1,12.49,200,1,14.52,200,1,12.46,100,1,14.56,800,1,12.43,700,1,14.6,700,1,ARL,332385569
2051,2025-07-17T16:07:22.818400003Z,2025-07-17T16:07:22.818400003Z,10,2,1108,C,A,0,16.080000000,100,0,165763,276946327,13.11,100,1,13.69,15,1,12.98,200,1,13.7,100,1,12.9,2,1,13.85,2,1,12.86,100,1,14.14,100,1,12.73,100,1,14.28,100,1,12.71,100,1,14.46,100,1,12.5,700,1,14.48,700,1,12.49,200,1,14.52,200,1,12.46,100,1,14.56,800,1,12.43,700,1,14.6,700,1,ARL,331934377
2052,2025-07-17T16:07:22.818400003Z,2025-07-17T16:07:22.818400003Z,10,2,1108,A,A,0,15.760000000,100,130,165763,276946327,13.11,100,1,13.69,15,1,12.98,200,1,13.7,100,1,12.9,2,1,13.85,2,1,12.86,100,1,14.14,100,1,12.73,100,1,14.28,100,1,12.71,100,1,14.46,100,1,12.5,700,1,14.48,700,1,12.49,200,1,14.52,200,1,12.46,100,1,14.56,800,1,12.43,700,1,14.6,700,1,ARL,332385585
2053,2025-07-17T16:07:22.819545360Z,2025-07-17T16:07:22.819545360Z,10,2,1108,C,A,0,17.610000000,100,0,165623,276946336,13.11,100,1,13.69,15,1,12.98,200,1,13.7,100,1,12.9,2,1,13.85,2,1,12.86,100,1,14.14,100,1,12.73,100,1,14.28,100,1,12.71,100,1,14.46,100,1,12.5,700,1,14.48,700,1,12.49,200,1,14.52,200,1,12.46,100,1,14.56,800,1,12.43,700,1,14.6,700,1,ARL,331942981
2054,2025-07-17T16:07:22.819545360Z,2025-07-17T16:07:22.819545360Z,10,2,1108,A,A,0,17.400000000,100,130,165623,276946336,13.11,100,1,13.69,15,1,12.98,200,1,13.7,100,1,12.9,2,1,13.85,2,1,12.86,100,1,14.14,100,1,12.73,100,1,14.28,100,1,12.71,100,1,14.46,100,1,12.5,700,1,14.48,700,1,12.49,200,1,14.52,200,1,12.46,100,1,14.56,800,1,12.43,700,1,14.6,700,1,ARL,332385593
2055,2025-07-17T16:07:22.819606945Z,2025-07-17T16:07:22.819606945Z,10,2,1108,C,A,0,14.630000000,100,0,165463,276946337,13.11,100,1,13.69,15,1,12.98,200,1,13.7,100,1,12.9,2,1,13.85,2,1,12.86,100,1,14.14,100,1,12.73,100,1,14.28,100,1,12.71,100,1,14.46,100,1,12.5,700,1,14.48,700,1,12.49,200,1,14.52,200,1,12.46,100,1,14.56,800,1,12.43,700,1,14.6,700,1,ARL,331927477
2056,2025-07-17T16:07:22.819606945Z,2025-07-17T16:07:22.819606945Z,10,2,1108,A,A,0,14.490000000,100,130,165463,276946337,13.11,100,1,13.69,15,1,12.98,200,1,13.7,100,1,12.9,2,1,13.85,2,1,12.86,100,1,14.14,100,1,12.73,100,1,14.28,100,1,12.71,100,1,14.46,100,1,12.5,700,1,14.48,700,1,12.49,200,1,14.49,100,1,12.46,100,1,14.52,200,1,12.43,700,1,14.56,800,1,ARL,332385597
2057,2025-07-17T16:07:22.821000003Z,2025-07-17T16:07:22.821000003Z,10,2,1108,C,A,0,14.140000000,100,130,165448,276946343,13.11,100,1,13.69,15,1,12.98,200,1,13.7,100,1,12.9,2,1,13.85,2,1,12.86,100,1,14.28,100,1,12.73,100,1,14.46,100,1,12.71,100,1,14.48,700,1,12.5,700,1,14.49,100,1,12.49,200,1,14.52,200,1,12.46,100,1,14.56,800,1,12.43,700,1,14.6,700,1,ARL,331943133
2058,2025-07-17T16:07:22.821052982Z,2025-07-17T16:07:22.821052982Z,10,2,1108,A,A,0,13.970000000,100,130,165225,276946344,13.11,100,1,13.69,15,1,12.98,200,1,13.7,100,1,12.9,2,1,13.85,2,1,12.86,100,1,13.97,100,1,12.73,100,1,14.28,100,1,12.71,100,1,14.46,100,1,12.5,700,1,14.48,700,1,12.49,200,1,14.49,100,1,12.46,100,1,14.52,200,1,12.43,700,1,14.56,800,1,ARL,332385613
2059,2025-07-17T16:07:22.831949887Z,2025-07-17T16:07:22.831949887Z,10,2,1108,C,A,0,14.960000000,100,0,169333,276946801,13.11,100,1,13.69,15,1,12.98,200,1,13.7,100,1,12.9,2,1,13.85,2,1,12.86,100,1,13.97,100,1,12.73,100,1,14.28,100,1,12.71,100,1,14.46,100,1,12.5,700,1,14.48,700,1,12.49,200,1,14.49,100,1,12.46,100,1,14.52,200,1,12.43,700,1,14.56,800,1,ARL,331928129
2060,2025-07-17T16:07:22.831949887Z,2025-07-17T16:07:22.831949887Z,10,2,1108,A,A,0,14.660000000,100,128,169333,276946801,13.11,100,1,13.69,15,1,12.98,200,1,13.7,100,1,12.9,2,1,13.85,2,1,12.86,100,1,13.97,100,1,12.73,100,1,14.28,100,1,12.71,100,1,14.46,100,1,12.5,700,1,14.48,700,1,12.49,200,1,14.49,100,1,12.46,100,1,14.52,200,1,12.43,700,1,14.56,800,1,ARL,332386121
2061,2025-07-17T16:07:28.273658191Z,2025-07-17T16:07:28.273658191Z,10,2,1108,C,A,0,13.690000000,15,130,165417,277012951,13.11,100,1,13.7,100,1,12.98,200,1,13.85,2,1,12.9,2,1,13.97,100,1,12.86,100,1,14.28,100,1,12.73,100,1,14.46,100,1,12.71,100,1,14.48,700,1,12.5,700,1,14.49,100,1,12.49,200,1,14.52,200,1,12.46,100,1,14.56,800,1,12.43,700,1,14.6,700,1,ARL,332385317
2062,2025-07-17T16:07:28.700815737Z,2025-07-17T16:07:28.700815737Z,10,2,1108,C,A,0,13.700000000,100,130,165412,277019711,13.11,100,1,13.85,2,1,12.98,200,1,13.97,100,1,12.9,2,1,14.28,100,1,12.86,100,1,14.46,100,1,12.73,100,1,14.48,700,1,12.71,100,1,14.49,100,1,12.5,700,1,14.52,200,1,12.49,200,1,14.56,800,1,12.46,100,1,14.6,700,1,12.43,700,1,14.66,200,1,ARL,332385325
2063,2025-07-17T16:07:28.701230409Z,2025-07-17T16:07:28.701230409Z,10,2,1108,C,B,0,12.900000000,2,0,166260,277019718,13.11,100,1,13.85,2,1,12.98,200,1,13.97,100,1,12.86,100,1,14.28,100,1,12.73,100,1,14.46,100,1,12.71,100,1,14.48,700,1,12.5,700,1,14.49,100,1,12.49,200,1,14.52,200,1,12.46,100,1,14.56,800,1,12.43,700,1,14.6,700,1,12.42,700,1,14.66,200,1,ARL,331694297
2064,2025-07-17T16:07:28.701230409Z,2025-07-17T16:07:28.701230409Z,10,2,1108,A,B,0,13.010000000,2,130,166260,277019718,13.11,100,1,13.85,2,1,13.01,2,1,13.97,100,1,12.98,200,1,14.28,100,1,12.86,100,1,14.46,100,1,12.73,100,1,14.48,700,1,12.71,100,1,14.49,100,1,12.5,700,1,14.52,200,1,12.49,200,1,14.56,800,1,12.46,100,1,14.6,700,1,12.43,700,1,14.66,200,1,ARL,332494213
2065,2025-07-17T16:07:28.701547540Z,2025-07-17T16:07:28.701547540Z,10,2,1108,C,A,0,14.760000000,100,0,165692,277019720,13.11,100,1,13.85,2,1,13.01,2,1,13.97,100,1,12.98,200,1,14.28,100,1,12.86,100,1,14.46,100,1,12.73,100,1,14.48,700,1,12.71,100,1,14.49,100,1,12.5,700,1,14.52,200,1,12.49,200,1,14.56,800,1,12.46,100,1,14.6,700,1,12.43,700,1,14.66,200,1,ARL,332385501
2066,2025-07-17T16:07:28.701547540Z,2025-07-17T16:07:28.701547540Z,10,2,1108,A,A,0,14.820000000,100,130,165692,277019720,13.11,100,1,13.85,2,1,13.01,2,1,13.97,100,1,12.98,200,1,14.28,100,1,12.86,100,1,14.46,100,1,12.73,100,1,14.48,700,1,12.71,100,1,14.49,100,1,12.5,700,1,14.52,200,1,12.49,200,1,14.56,800,1,12.46,100,1,14.6,700,1,12.43,700,1,14.66,200,1,ARL,332494229
2067,2025-07-17T16:07:28.702000772Z,2025-07-17T16:07:28.702000772Z,10,2,1108,C,A,0,15.760000000,100,0,165525,277019722,13.11,100,1,13.85,2,1,13.01,2,1,13.97,100,1,12.98,200,1,14.28,100,1,12.86,100,1,14.46,100,1,12.73,100,1,14.48,700,1,12.71,100,1,14.49,100,1,12.5,700,1,14.52,200,1,12.49,200,1,14.56,800,1,12.46,100,1,14.6,700,1,12.43,700,1,14.66,200,1,ARL,332385585
2068,2025-07-17T16:07:28.702000772Z,2025-07-17T16:07:28.702000772Z,10,2,1108,A,A,0,16.010000000,100,130,165525,277019722,13.11,100,1,13.85,2,1,13.01,2,1,13.97,100,1,12.98,200,1,14.28,100,1,12.86,100,1,14.46,100,1,12.73,100,1,14.48,700,1,12.71,100,1,14.49,100,1,12.5,700,1,14.52,200,1,12.49,200,1,14.56,800,1,12.46,100,1,14.6,700,1,12.43,700,1,14.66,200,1,ARL,332494245
2069,2025-07-17T16:07:28.702476699Z,2025-07-17T16:07:28.702476699Z,10,2,1108,C,A,0,14.660000000,100,0,165321,277019729,13.11,100,1,13.85,2,1,13.01,2,1,13.97,100,1,12.98,200,1,14.28,100,1,12.86,100,1,14.46,100,1,12.73,100,1,14.48,700,1,12.71,100,1,14.49,100,1,12.5,700,1,14.52,200,1,12.49,200,1,14.56,800,1,12.46,100,1,14.6,700,1,12.43,700,1,14.66,100,1,ARL,332386121
2070,2025-07-17T16:07:28.702476699Z,2025-07-17T16:07:28.702476699Z,10,2,1108,A,A,0,14.950000000,100,130,165321,277019729,13.11,100,1,13.85,2,1,13.01,2,1,13.97,100,1,12.98,200,1,14.28,100,1,12.86,100,1,14.46,100,1,12.73,100,1,14.48,700,1,12.71,100,1,14.49,100,1,12.5,700,1,14.52,200,1,12.49,200,1,14.56,800,1,12.46,100,1,14.6,700,1,12.43,700,1,14.66,100,1,ARL,332494281
2071,2025-07-17T16:07:28.703357714Z,2025-07-17T16:07:28.703357714Z,10,2,1108,C,A,0,14.660000000,100,0,165378,277019733,13.11,100,1,13.85,2,1,13.01,2,1,13.97,100,1,12.98,200,1,14.28,100,1,12.86,100,1,14.46,100,1,12.73,100,1,14.48,700,1,12.71,100,1,14.49,100,1,12.5,700,1,14.52,200,1,12.49,200,1,14.56,800,1,12.46,100,1,14.6,700,1,12.43,700,1,14.68,700,1,ARL,332385565
2072,2025-07-17T16:07:28.703357714Z,2025-07-17T16:07:28.703357714Z,10,2,1108,A,A,0,14.950000000,100,130,165378,277019733,13.11,100,1,13.85,2,1,13.01,2,1,13.97,100,1,12.98,200,1,14.28,100,1,12.86,100,1,14.46,100,1,12.73,100,1,14.48,700,1,12.71,100,1,14.49,100,1,12.5,700,1,14.52,200,1,12.49,200,1,14.56,800,1,12.46,100,1,14.6,700,1,12.43,700,1,14.68,700,1,ARL,332494285
2073,2025-07-17T16:07:28.703754662Z,2025-07-17T16:07:28.703754662Z,10,2,1108,C,A,0,15.070000000,100,0,165674,277019735,13.11,100,1,13.85,2,1,13.01,2,1,13.97,100,1,12.98,200,1,14.28,100,1,12.86,100,1,14.46,100,1,12.73,100,1,14.48,700,1,12.71,100,1,14.49,100,1,12.5,700,1,14.52,200,1,12.49,200,1,14.56,800,1,12.46,100,1,14.6,700,1,12.43,700,1,14.68,700,1,ARL,332385569
2074,2025-07-17T16:07:28.703754662Z,2025-07-17T16:07:28.703754662Z,10,2,1108,A,A,0,15.370000000,100,130,165674,277019735,13.11,100,1,13.85,2,1,13.01,2,1,13.97,100,1,12.98,200,1,14.28,100,1,12.86,100,1,14.46,100,1,12.73,100,1,14.48,700,1,12.71,100,1,14.49,100,1,12.5,700,1,14.52,200,1,12.49,200,1,14.56,800,1,12.46,100,1,14.6,700,1,12.43,700,1,14.68,700,1,ARL,332494289
2075,2025-07-17T16:07:28.704032725Z,2025-07-17T16:07:28.704032725Z,10,2,1108,C,A,0,17.400000000,100,0,165378,277019738,13.11,100,1,13.85,2,1,13.01,2,1,13.97,100,1,12.98,200,1,14.28,100,1,12.86,100,1,14.46,100,1,12.73,100,1,14.48,700,1,12.71,100,1,14.49,100,1,12.5,700,1,14.52,200,1,12.49,200,1,14.56,800,1,12.46,100,1,14.6,700,1,12.43,700,1,14.68,700,1,ARL,332385593
2076,2025-07-17T16:07:28.704032725Z,2025-07-17T16:07:28.704032725Z,10,2,1108,A,A,0,17.750000000,100,130,165378,277019738,13.11,100,1,13.85,2,1,13.01,2,1,13.97,100,1,12.98,200,1,14.28,100,1,12.86,100,1,14.46,100,1,12.73,100,1,14.48,700,1,12.71,100,1,14.49,100,1,12.5,700,1,14.52,200,1,12.49,200,1,14.56,800,1,12.46,100,1,14.6,700,1,12.43,700,1,14.68,700,1,ARL,332494297
2077,2025-07-17T16:07:28.724036175Z,2025-07-17T16:07:28.724036175Z,10,2,1108,C,A,0,13.970000000,100,130,165665,277019926,13.11,100,1,13.85,2,1,13.01,2,1,14.28,100,1,12.98,200,1,14.46,100,1,12.86,100,1,14.48,700,1,12.73,100,1,14.49,100,1,12.71,100,1,14.52,200,1,12.5,700,1,14.56,800,1,12.49,200,1,14.6,700,1,12.46,100,1,14.68,700,1,12.43,700,1,14.82,100,1,ARL,332385613
2078,2025-07-17T16:07:28.724085453Z,2025-07-17T16:07:28.724085453Z,10,2,1108,A,A,0,14.200000000,100,130,165382,277019929,13.11,100,1,13.85,2,1,13.01,2,1,14.2,100,1,12.98,200,1,14.28,100,1,12.86,100,1,14.46,100,1,12.73,100,1,14.48,700,1,12.71,100,1,14.49,100,1,12.5,700,1,14.52,200,1,12.49,200,1,14.56,800,1,12.46,100,1,14.6,700,1,12.43,700,1,14.68,700,1,ARL,332494893
2079,2025-07-17T16:07:28.751662660Z,2025-07-17T16:07:28.751662660Z,10,2,1108,C,A,0,14.820000000,100,0,165460,277020284,13.11,100,1,13.85,2,1,13.01,2,1,14.2,100,1,12.98,200,1,14.28,100,1,12.86,100,1,14.46,100,1,12.73,100,1,14.48,700,1,12.71,100,1,14.49,100,1,12.5,700,1,14.52,200,1,12.49,200,1,14.56,800,1,12.46,100,1,14.6,700,1,12.43,700,1,14.68,700,1,ARL,332494229
2080,2025-07-17T16:07:28.751662660Z,2025-07-17T16:07:28.751662660Z,10,2,1108,A,A,0,15.050000000,100,130,165460,277020284,13.11,100,1,13.85,2,1,13.01,2,1,14.2,100,1,12.98,200,1,14.28,100,1,12.86,100,1,14.46,100,1,12.73,100,1,14.48,700,1,12.71,100,1,14.49,100,1,12.5,700,1,14.52,200,1,12.49,200,1,14.56,800,1,12.46,100,1,14.6,700,1,12.43,700,1,14.68,700,1,ARL,332495781
2081,2025-07-17T16:07:28.830995364Z,2025-07-17T16:07:28.830995364Z,10,2,1108,C,A,0,14.490000000,100,130,165623,277021007,13.11,100,1,13.85,2,1,13.01,2,1,14.2,100,1,12.98,200,1,14.28,100,1,12.86,100,1,14.46,100,1,12.73,100,1,14.48,700,1,12.71,100,1,14.52,200,1,12.5,700,1,14.56,800,1,12.49,200,1,14.6,700,1,12.46,100,1,14.68,700,1,12.43,700,1,14.95,200,1,ARL,332385597
2082,2025-07-17T16:07:28.831125667Z,2025-07-17T16:07:28.831125667Z,10,2,1108,A,A,0,14.770000000,100,130,165710,277021012,13.11,100,1,13.85,2,1,13.01,2,1,14.2,100,1,12.98,200,1,14.28,100,1,12.86,100,1,14.46,100,1,12.73,100,1,14.48,700,1,12.71,100,1,14.52,200,1,12.5,700,1,14.56,800,1,12.49,200,1,14.6,700,1,12.46,100,1,14.68,700,1,12.43,700,1,14.77,100,1,ARL,332497653
2083,2025-07-17T16:07:29.214500816Z,2025-07-17T16:07:29.214500816Z,10,2,1108,A,A,0,13.860000000,100,128,166454,277029015,13.11,100,1,13.85,2,1,13.01,2,1,13.86,100,1,12.98,200,1,14.2,100,1,12.86,100,1,14.28,100,1,12.73,100,1,14.46,100,1,12.71,100,1,14.48,700,1,12.5,700,1,14.52,200,1,12.49,200,1,14.56,800,1,12.46,100,1,14.6,700,1,12.43,700,1,14.68,700,1,ARL,332508813
2084,2025-07-17T16:07:29.215292291Z,2025-07-17T16:07:29.215292291Z,10,2,1108,C,A,0,15.050000000,100,0,166553,277029273,13.11,100,1,13.85,2,1,13.01,2,1,13.86,100,1,12.98,200,1,14.2,100,1,12.86,100,1,14.28,100,1,12.73,100,1,14.46,100,1,12.71,100,1,14.48,700,1,12.5,700,1,14.52,200,1,12.49,200,1,14.56,800,1,12.46,100,1,14.6,700,1,12.43,700,1,14.68,700,1,ARL,332495781
2085,2025-07-17T16:07:29.215292291Z,2025-07-17T16:07:29.215292291Z,10,2,1108,A,A,0,14.930000000,100,128,166553,277029273,13.11,100,1,13.85,2,1,13.01,2,1,13.86,100,1,12.98,200,1,14.2,100,1,12.86,100,1,14.28,100,1,12.73,100,1,14.46,100,1,12.71,100,1,14.48,700,1,12.5,700,1,14.52,200,1,12.49,200,1,14.56,800,1,12.46,100,1,14.6,700,1,12.43,700,1,14.68,700,1,ARL,332508997
2086,2025-07-17T16:08:20.816087447Z,2025-07-17T16:08:20.816087447Z,10,2,1108,A,A,0,13.680000000,15,130,165403,277732167,13.11,100,1,13.68,15,1,13.01,2,1,13.85,2,1,12.98,200,1,13.86,100,1,12.86,100,1,14.2,100,1,12.73,100,1,14.28,100,1,12.71,100,1,14.46,100,1,12.5,700,1,14.48,700,1,12.49,200,1,14.52,200,1,12.46,100,1,14.56,800,1,12.43,700,1,14.6,700,1,ARL,333436357
2087,2025-07-17T16:08:20.816200644Z,2025-07-17T16:08:20.816200644Z,10,2,1108,C,A,0,13.860000000,100,0,165561,277732170,13.11,100,1,13.68,15,1,13.01,2,1,13.85,2,1,12.98,200,1,14.2,100,1,12.86,100,1,14.28,100,1,12.73,100,1,14.46,100,1,12.71,100,1,14.48,700,1,12.5,700,1,14.52,200,1,12.49,200,1,14.56,800,1,12.46,100,1,14.6,700,1,12.43,700,1,14.68,700,1,ARL,332508813
2088,2025-07-17T16:08:20.816200644Z,2025-07-17T16:08:20.816200644Z,10,2,1108,A,A,0,13.690000000,100,130,165561,277732170,13.11,100,1,13.68,15,1,13.01,2,1,13.69,100,1,12.98,200,1,13.85,2,1,12.86,100,1,14.2,100,1,12.73,100,1,14.28,100,1,12.71,100,1,14.46,100,1,12.5,700,1,14.48,700,1,12.49,200,1,14.52,200,1,12.46,100,1,14.56,800,1,12.43,700,1,14.6,700,1,ARL,333436361
2089,2025-07-17T16:08:20.816932150Z,2025-07-17T16:08:20.816932150Z,10,2,1108,C,A,0,14.930000000,100,0,165437,277732194,13.11,100,1,13.68,15,1,13.01,2,1,13.69,100,1,12.98,200,1,13.85,2,1,12.86,100,1,14.2,100,1,12.73,100,1,14.28,100,1,12.71,100,1,14.46,100,1,12.5,700,1,14.48,700,1,12.49,200,1,14.52,200,1,12.46,100,1,14.56,800,1,12.43,700,1,14.6,700,1,ARL,332508997
2090,2025-07-17T16:08:20.816932150Z,2025-07-17T16:08:20.816932150Z,10,2,1108,A,A,0,14.750000000,100,130,165437,277732194,13.11,100,1,13.68,15,1,13.01,2,1,13.69,100,1,12.98,200,1,13.85,2,1,12.86,100,1,14.2,100,1,12.73,100,1,14.28,100,1,12.71,100,1,14.46,100,1,12.5,700,1,14.48,700,1,12.49,200,1,14.52,200,1,12.46,100,1,14.56,800,1,12.43,700,1,14.6,700,1,ARL,333436397
2091,2025-07-17T16:08:20.818559377Z,2025-07-17T16:08:20.818559377Z,10,2,1108,C,A,0,15.370000000,100,0,165725,277732213,13.11,100,1,13.68,15,1,13.01,2,1,13.69,100,1,12.98,200,1,13.85,2,1,12.86,100,1,14.2,100,1,12.73,100,1,14.28,100,1,12.71,100,1,14.46,100,1,12.5,700,1,14.48,700,1,12.49,200,1,14.52,200,1,12.46,100,1,14.56,800,1,12.43,700,1,14.6,700,1,ARL,332494289
2092,2025-07-17T16:08:20.818559377Z,2025-07-17T16:08:20.818559377Z,10,2,1108,A,A,0,15.060000000,100,130,165725,277732213,13.11,100,1,13.68,15,1,13.01,2,1,13.69,100,1,12.98,200,1,13.85,2,1,12.86,100,1,14.2,100,1,12.73,100,1,14.28,100,1,12.71,100,1,14.46,100,1,12.5,700,1,14.48,700,1,12.49,200,1,14.52,200,1,12.46,100,1,14.56,800,1,12.43,700,1,14.6,700,1,ARL,333436421
2093,2025-07-17T16:08:20.818965359Z,2025-07-17T16:08:20.818965359Z,10,2,1108,C,A,0,14.950000000,100,0,165461,277732216,13.11,100,1,13.68,15,1,13.01,2,1,13.69,100,1,12.98,200,1,13.85,2,1,12.86,100,1,14.2,100,1,12.73,100,1,14.28,100,1,12.71,100,1,14.46,100,1,12.5,700,1,14.48,700,1,12.49,200,1,14.52,200,1,12.46,100,1,14.56,800,1,12.43,700,1,14.6,700,1,ARL,332494285
2094,2025-07-17T16:08:20.818965359Z,2025-07-17T16:08:20.818965359Z,10,2,1108,A,A,0,14.650000000,100,130,165461,277732216,13.11,100,1,13.68,15,1,13.01,2,1,13.69,100,1,12.98,200,1,13.85,2,1,12.86,100,1,14.2,100,1,12.73,100,1,14.28,100,1,12.71,100,1,14.46,100,1,12.5,700,1,14.48,700,1,12.49,200,1,14.52,200,1,12.46,100,1,14.56,800,1,12.43,700,1,14.6,700,1,ARL,333436425
2095,2025-07-17T16:08:20.819601669Z,2025-07-17T16:08:20.819601669Z,10,2,1108,C,A,0,17.750000000,100,0,165422,277732221,13.11,100,1,13.68,15,1,13.01,2,1,13.69,100,1,12.98,200,1,13.85,2,1,12.86,100,1,14.2,100,1,12.73,100,1,14.28,100,1,12.71,100,1,14.46,100,1,12.5,700,1,14.48,700,1,12.49,200,1,14.52,200,1,12.46,100,1,14.56,800,1,12.43,700,1,14.6,700,1,ARL,332494297
2096,2025-07-17T16:08:20.819601669Z,2025-07-17T16:08:20.819601669Z,10,2,1108,A,A,0,17.390000000,100,130,165422,277732221,13.11,100,1,13.68,15,1,13.01,2,1,13.69,100,1,12.98,200,1,13.85,2,1,12.86,100,1,14.2,100,1,12.73,100,1,14.28,100,1,12.71,100,1,14.46,100,1,12.5,700,1,14.48,700,1,12.49,200,1,14.52,200,1,12.46,100,1,14.56,800,1,12.43,700,1,14.6,700,1,ARL,333436441
2097,2025-07-17T16:08:20.820500575Z,2025-07-17T16:08:20.820500575Z,10,2,1108,C,A,0,16.010000000,100,0,165594,277732228,13.11,100,1,13.68,15,1,13.01,2,1,13.69,100,1,12.98,200,1,13.85,2,1,12.86,100,1,14.2,100,1,12.73,100,1,14.28,100,1,12.71,100,1,14.46,100,1,12.5,700,1,14.48,700,1,12.49,200,1,14.52,200,1,12.46,100,1,14.56,800,1,12.43,700,1,14.6,700,1,ARL,332494245
2098,2025-07-17T16:08:20.820500575Z,2025-07-17T16:08:20.820500575Z,10,2,1108,A,A,0,15.750000000,100,130,165594,277732228,13.11,100,1,13.68,15,1,13.01,2,1,13.69,100,1,12.98,200,1,13.85,2,1,12.86,100,1,14.2,100,1,12.73,100,1,14.28,100,1,12.71,100,1,14.46,100,1,12.5,700,1,14.48,700,1,12.49,200,1,14.52,200,1,12.46,100,1,14.56,800,1,12.43,700,1,14.6,700,1,ARL,333436449
2099,2025-07-17T16:08:20.821924168Z,2025-07-17T16:08:20.821924168Z,10,2,1108,C,A,0,14.200000000,100,130,165376,277732239,13.11,100,1,13.68,15,1,13.01,2,1,13.69,100,1,12.98,200,1,13.85,2,1,12.86,100,1,14.28,100,1,12.73,100,1,14.46,100,1,12.71,100,1,14.48,700,1,12.5,700,1,14.52,200,1,12.49,200,1,14.56,800,1,12.46,100,1,14.6,700,1,12.43,700,1,14.65,100,1,ARL,332494893
2100,2025-07-17T16:08:20.821974299Z,2025-07-17T16:08:20.821974299Z,10,2,1108,A,A,0,13.960000000,100,130,165242,277732240,13.11,100,1,13.68,15,1,13.01,2,1,13.69,100,1,12.98,200,1,13.85,2,1,12.86,100,1,13.96,100,1,12.73,100,1,14.28,100,1,12.71,100,1,14.46,100,1,12.5,700,1,14.48,700,1,12.49,200,1,14.52,200,1,12.46,100,1,14.56,800,1,12.43,700,1,14.6,700,1,ARL,333436473
2101,2025-07-17T16:08:20.829945074Z,2025-07-17T16:08:20.829945074Z,10,2,1108,C,A,0,14.950000000,100,0,165425,277732299,13.11,100,1,13.68,15,1,13.01,2,1,13.69,100,1,12.98,200,1,13.85,2,1,12.86,100,1,13.96,100,1,12.73,100,1,14.28,100,1,12.71,100,1,14.46,100,1,12.5,700,1,14.48,700,1,12.49,200,1,14.52,200,1,12.46,100,1,14.56,800,1,12.43,700,1,14.6,700,1,ARL,332494281
2102,2025-07-17T16:08:20.829945074Z,2025-07-17T16:08:20.829945074Z,10,2,1108,A,A,0,14.650000000,100,130,165425,277732299,13.11,100,1,13.68,15,1,13.01,2,1,13.69,100,1,12.98,200,1,13.85,2,1,12.86,100,1,13.96,100,1,12.73,100,1,14.28,100,1,12.71,100,1,14.46,100,1,12.5,700,1,14.48,700,1,12.49,200,1,14.52,200,1,12.46,100,1,14.56,800,1,12.43,700,1,14.6,700,1,ARL,333436589
2103,2025-07-17T16:08:20.966063681Z,2025-07-17T16:08:20.966063681Z,10,2,1108,C,A,0,14.770000000,100,0,165585,277733304,13.11,100,1,13.68,15,1,13.01,2,1,13.69,100,1,12.98,200,1,13.85,2,1,12.86,100,1,13.96,100,1,12.73,100,1,14.28,100,1,12.71,100,1,14.46,100,1,12.5,700,1,14.48,700,1,12.49,200,1,14.52,200,1,12.46,100,1,14.56,800,1,12.43,700,1,14.6,700,1,ARL,332497653
2104,2025-07-17T16:08:20.966063681Z,2025-07-17T16:08:20.966063681Z,10,2,1108,A,A,0,14.480000000,100,130,165585,277733304,13.11,100,1,13.68,15,1,13.01,2,1,13.69,100,1,12.98,200,1,13.85,2,1,12.86,100,1,13.96,100,1,12.73,100,1,14.28,100,1,12.71,100,1,14.46,100,1,12.5,700,1,14.48,800,1,12.49,200,1,14.52,200,1,12.46,100,1,14.56,800,1,12.43,700,1,14.6,700,1,ARL,333438545
2105,2025-07-17T16:08:22.998002821Z,2025-07-17T16:08:22.998002821Z,10,2,1108,C,A,0,13.680000000,15,130,165365,277766492,13.11,100,1,13.69,100,1,13.01,2,1,13.85,2,1,12.98,200,1,13.96,100,1,12.86,100,1,14.28,100,1,12.73,100,1,14.46,100,1,12.71,100,1,14.48,800,1,12.5,700,1,14.52,200,1,12.49,200,1,14.56,800,1,12.46,100,1,14.6,700,1,12.43,700,1,14.65,200,1,ARL,333436357
2106,2025-07-17T16:08:27.482344236Z,2025-07-17T16:08:27.482344236Z,10,2,1108,C,A,0,13.690000000,100,130,165448,277841171,13.11,100,1,13.85,2,1,13.01,2,1,13.96,100,1,12.98,200,1,14.28,100,1,12.86,100,1,14.46,100,1,12.73,100,1,14.48,800,1,12.71,100,1,14.52,200,1,12.5,700,1,14.56,800,1,12.49,200,1,14.6,700,1,12.46,100,1,14.65,200,1,12.43,700,1,14.68,700,1,ARL,333436361
2107,2025-07-17T16:08:27.483075481Z,2025-07-17T16:08:27.483075481Z,10,2,1108,C,A,0,14.750000000,100,0,165526,277841175,13.11,100,1,13.85,2,1,13.01,2,1,13.96,100,1,12.98,200,1,14.28,100,1,12.86,100,1,14.46,100,1,12.73,100,1,14.48,800,1,12.71,100,1,14.52,200,1,12.5,700,1,14.56,800,1,12.49,200,1,14.6,700,1,12.46,100,1,14.65,200,1,12.43,700,1,14.68,700,1,ARL,333436397
2108,2025-07-17T16:08:27.483075481Z,2025-07-17T16:08:27.483075481Z,10,2,1108,A,A,0,14.990000000,100,130,165526,277841175,13.11,100,1,13.85,2,1,13.01,2,1,13.96,100,1,12.98,200,1,14.28,100,1,12.86,100,1,14.46,100,1,12.73,100,1,14.48,800,1,12.71,100,1,14.52,200,1,12.5,700,1,14.56,800,1,12.49,200,1,14.6,700,1,12.46,100,1,14.65,200,1,12.43,700,1,14.68,700,1,ARL,333581389
2109,2025-07-17T16:08:27.483420069Z,2025-07-17T16:08:27.483420069Z,10,2,1108,C,A,0,14.520000000,100,0,165823,277841178,13.11,100,1,13.85,2,1,13.01,2,1,13.96,100,1,12.98,200,1,14.28,100,1,12.86,100,1,14.46,100,1,12.73,100,1,14.48,800,1,12.71,100,1,14.52,100,1,12.5,700,1,14.56,800,1,12.49,200,1,14.6,700,1,12.46,100,1,14.65,200,1,12.43,700,1,14.68,700,1,ARL,328780577
2110,2025-07-17T16:08:27.483420069Z,2025-07-17T16:08:27.483420069Z,10,2,1108,A,A,0,14.740000000,100,130,165823,277841178,13.11,100,1,13.85,2,1,13.01,2,1,13.96,100,1,12.98,200,1,14.28,100,1,12.86,100,1,14.46,100,1,12.73,100,1,14.48,800,1,12.71,100,1,14.52,100,1,12.5,700,1,14.56,800,1,12.49,200,1,14.6,700,1,12.46,100,1,14.65,200,1,12.43,700,1,14.68,700,1,ARL,333581393
2111,2025-07-17T16:08:27.483913735Z,2025-07-17T16:08:27.483913735Z,10,2,1108,C,A,0,14.650000000,100,0,165489,277841218,13.11,100,1,13.85,2,1,13.01,2,1,13.96,100,1,12.98,200,1,14.28,100,1,12.86,100,1,14.46,100,1,12.73,100,1,14.48,800,1,12.71,100,1,14.52,100,1,12.5,700,1,14.56,800,1,12.49,200,1,14.6,700,1,12.46,100,1,14.65,100,1,12.43,700,1,14.68,700,1,ARL,333436589
2112,2025-07-17T16:08:27.483913735Z,2025-07-17T16:08:27.483913735Z,10,2,1108,A,A,0,14.940000000,100,130,165489,277841218,13.11,100,1,13.85,2,1,13.01,2,1,13.96,100,1,12.98,200,1,14.28,100,1,12.86,100,1,14.46,100,1,12.73,100,1,14.48,800,1,12.71,100,1,14.52,100,1,12.5,700,1,14.56,800,1,12.49,200,1,14.6,700,1,12.46,100,1,14.65,100,1,12.43,700,1,14.68,700,1,ARL,333581409
2113,2025-07-17T16:08:27.484693568Z,2025-07-17T16:08:27.484693568Z,10,2,1108,C,A,0,17.390000000,100,0,165620,277841226,13.11,100,1,13.85,2,1,13.01,2,1,13.96,100,1,12.98,200,1,14.28,100,1,12.86,100,1,14.46,100,1,12.73,100,1,14.48,800,1,12.71,100,1,14.52,100,1,12.5,700,1,14.56,800,1,12.49,200,1,14.6,700,1,12.46,100,1,14.65,100,1,12.43,700,1,14.68,700,1,ARL,333436441
2114,2025-07-17T16:08:27.484693568Z,2025-07-17T16:08:27.484693568Z,10,2,1108,A,A,0,17.730000000,100,130,165620,277841226,13.11,100,1,13.85,2,1,13.01,2,1,13.96,100,1,12.98,200,1,14.28,100,1,12.86,100,1,14.46,100,1,12.73,100,1,14.48,800,1,12.71,100,1,14.52,100,1,12.5,700,1,14.56,800,1,12.49,200,1,14.6,700,1,12.46,100,1,14.65,100,1,12.43,700,1,14.68,700,1,ARL,333581425
2115,2025-07-17T16:08:27.484800296Z,2025-07-17T16:08:27.484800296Z,10,2,1108,C,A,0,14.650000000,100,0,165661,277841228,13.11,100,1,13.85,2,1,13.01,2,1,13.96,100,1,12.98,200,1,14.28,100,1,12.86,100,1,14.46,100,1,12.73,100,1,14.48,800,1,12.71,100,1,14.52,100,1,12.5,700,1,14.56,800,1,12.49,200,1,14.6,700,1,12.46,100,1,14.68,700,1,12.43,700,1,14.74,100,1,ARL,333436425
2116,2025-07-17T16:08:27.484800296Z,2025-07-17T16:08:27.484800296Z,10,2,1108,A,A,0,14.940000000,100,130,165661,277841228,13.11,100,1,13.85,2,1,13.01,2,1,13.96,100,1,12.98,200,1,14.28,100,1,12.86,100,1,14.46,100,1,12.73,100,1,14.48,800,1,12.71,100,1,14.52,100,1,12.5,700,1,14.56,800,1,12.49,200,1,14.6,700,1,12.46,100,1,14.68,700,1,12.43,700,1,14.74,100,1,ARL,333581429
2117,2025-07-17T16:08:27.484813280Z,2025-07-17T16:08:27.484813280Z,10,2,1108,C,A,0,15.750000000,100,0,165579,277841229,13.11,100,1,13.85,2,1,13.01,2,1,13.96,100,1,12.98,200,1,14.28,100,1,12.86,100,1,14.46,100,1,12.73,100,1,14.48,800,1,12.71,100,1,14.52,100,1,12.5,700,1,14.56,800,1,12.49,200,1,14.6,700,1,12.46,100,1,14.68,700,1,12.43,700,1,14.74,100,1,ARL,333436449
2118,2025-07-17T16:08:27.484813280Z,2025-07-17T16:08:27.484813280Z,10,2,1108,A,A,0,16.060000000,100,130,165579,277841229,13.11,100,1,13.85,2,1,13.01,2,1,13.96,100,1,12.98,200,1,14.28,100,1,12.86,100,1,14.46,100,1,12.73,100,1,14.48,800,1,12.71,100,1,14.52,100,1,12.5,700,1,14.56,800,1,12.49,200,1,14.6,700,1,12.46,100,1,14.68,700,1,12.43,700,1,14.74,100,1,ARL,333581433
2119,2025-07-17T16:08:27.485186411Z,2025-07-17T16:08:27.485186411Z,10,2,1108,C,A,0,15.060000000,100,0,165793,277841231,13.11,100,1,13.85,2,1,13.01,2,1,13.96,100,1,12.98,200,1,14.28,100,1,12.86,100,1,14.46,100,1,12.73,100,1,14.48,800,1,12.71,100,1,14.52,100,1,12.5,700,1,14.56,800,1,12.49,200,1,14.6,700,1,12.46,100,1,14.68,700,1,12.43,700,1,14.74,100,1,ARL,333436421
2120,2025-07-17T16:08:27.485186411Z,2025-07-17T16:08:27.485186411Z,10,2,1108,A,A,0,15.360000000,100,130,165793,277841231,13.11,100,1,13.85,2,1,13.01,2,1,13.96,100,1,12.98,200,1,14.28,100,1,12.86,100,1,14.46,100,1,12.73,100,1,14.48,800,1,12.71,100,1,14.52,100,1,12.5,700,1,14.56,800,1,12.49,200,1,14.6,700,1,12.46,100,1,14.68,700,1,12.43,700,1,14.74,100,1,ARL,333581441
2121,2025-07-17T16:08:27.487097702Z,2025-07-17T16:08:27.487097702Z,10,2,1108,C,A,0,14.520000000,100,0,165574,277841319,13.11,100,1,13.85,2,1,13.01,2,1,13.96,100,1,12.98,200,1,14.28,100,1,12.86,100,1,14.46,100,1,12.73,100,1,14.48,800,1,12.71,100,1,14.56,800,1,12.5,700,1,14.6,700,1,12.49,200,1,14.68,700,1,12.46,100,1,14.74,100,1,12.43,700,1,14.94,200,1,ARL,328780597
2122,2025-07-17T16:08:27.487097702Z,2025-07-17T16:08:27.487097702Z,10,2,1108,A,A,0,14.740000000,100,130,165574,277841319,13.11,100,1,13.85,2,1,13.01,2,1,13.96,100,1,12.98,200,1,14.28,100,1,12.86,100,1,14.46,100,1,12.73,100,1,14.48,800,1,12.71,100,1,14.56,800,1,12.5,700,1,14.6,700,1,12.49,200,1,14.68,700,1,12.46,100,1,14.74,200,1,12.43,700,1,14.94,200,1,ARL,333581481
2123,2025-07-17T16:08:27.492093401Z,2025-07-17T16:08:27.492093401Z,10,2,1108,C,A,0,14.480000000,100,130,165505,277841396,13.11,100,1,13.85,2,1,13.01,2,1,13.96,100,1,12.98,200,1,14.28,100,1,12.86,100,1,14.46,100,1,12.73,100,1,14.48,700,1,12.71,100,1,14.56,800,1,12.5,700,1,14.6,700,1,12.49,200,1,14.68,700,1,12.46,100,1,14.74,200,1,12.43,700,1,14.94,200,1,ARL,333438545
2124,2025-07-17T16:08:27.492220454Z,2025-07-17T16:08:27.492220454Z,10,2,1108,A,A,0,14.750000000,100,130,165296,277841397,13.11,100,1,13.85,2,1,13.01,2,1,13.96,100,1,12.98,200,1,14.28,100,1,12.86,100,1,14.46,100,1,12.73,100,1,14.48,700,1,12.71,100,1,14.56,800,1,12.5,700,1,14.6,700,1,12.49,200,1,14.68,700,1,12.46,100,1,14.74,200,1,12.43,700,1,14.75,100,1,ARL,333581569
2125,2025-07-17T16:08:27.496770678Z,2025-07-17T16:08:27.496770678Z,10,2,1108,C,A,0,13.960000000,100,130,165444,277841427,13.11,100,1,13.85,2,1,13.01,2,1,14.28,100,1,12.98,200,1,14.46,100,1,12.86,100,1,14.48,700,1,12.73,100,1,14.56,800,1,12.71,100,1,14.6,700,1,12.5,700,1,14.68,700,1,12.49,200,1,14.74,200,1,12.46,100,1,14.75,100,1,12.43,700,1,14.94,200,1,ARL,333436473
2126,2025-07-17T16:08:27.496822540Z,2025-07-17T16:08:27.496822540Z,10,2,1108,A,A,0,14.190000000,100,130,165292,277841428,13.11,100,1,13.85,2,1,13.01,2,1,14.19,100,1,12.98,200,1,14.28,100,1,12.86,100,1,14.46,100,1,12.73,100,1,14.48,700,1,12.71,100,1,14.56,800,1,12.5,700,1,14.6,700,1,12.49,200,1,14.68,700,1,12.46,100,1,14.74,200,1,12.43,700,1,14.75,100,1,ARL,333581625
2127,2025-07-17T16:08:27.500928061Z,2025-07-17T16:08:27.500928061Z,10,2,1108,C,A,0,13.850000000,2,0,165557,277841469,13.11,100,1,14.19,100,1,13.01,2,1,14.28,100,1,12.98,200,1,14.46,100,1,12.86,100,1,14.48,700,1,12.73,100,1,14.56,800,1,12.71,100,1,14.6,700,1,12.5,700,1,14.68,700,1,12.49,200,1,14.74,200,1,12.46,100,1,14.75,100,1,12.43,700,1,14.94,200,1,ARL,331155889
2128,2025-07-17T16:08:27.500928061Z,2025-07-17T16:08:27.500928061Z,10,2,1108,A,A,0,13.980000000,2,130,165557,277841469,13.11,100,1,13.98,2,1,13.01,2,1,14.19,100,1,12.98,200,1,14.28,100,1,12.86,100,1,14.46,100,1,12.73,100,1,14.48,700,1,12.71,100,1,14.56,800,1,12.5,700,1,14.6,700,1,12.49,200,1,14.68,700,1,12.46,100,1,14.74,200,1,12.43,700,1,14.75,100,1,ARL,333581677
2129,2025-07-17T16:08:27.516449334Z,2025-07-17T16:08:27.516449334Z,10,2,1108,C,A,0,14.190000000,100,130,165039,277841551,13.11,100,1,13.98,2,1,13.01,2,1,14.28,100,1,12.98,200,1,14.46,100,1,12.86,100,1,14.48,700,1,12.73,100,1,14.56,800,1,12.71,100,1,14.6,700,1,12.5,700,1,14.68,700,1,12.49,200,1,14.74,200,1,12.46,100,1,14.75,100,1,12.43,700,1,14.94,200,1,ARL,333581625
2130,2025-07-17T16:08:27.516496962Z,2025-07-17T16:08:27.516496962Z,10,2,1108,A,A,0,14.260000000,100,130,165137,277841552,13.11,100,1,13.98,2,1,13.01,2,1,14.26,100,1,12.98,200,1,14.28,100,1,12.86,100,1,14.46,100,1,12.73,100,1,14.48,700,1,12.71,100,1,14.56,800,1,12.5,700,1,14.6,700,1,12.49,200,1,14.68,700,1,12.46,100,1,14.74,200,1,12.43,700,1,14.75,100,1,ARL,333581765
2131,2025-07-17T16:08:27.533773259Z,2025-07-17T16:08:27.533773259Z,10,2,1108,C,A,0,14.990000000,100,0,165191,277841588,13.11,100,1,13.98,2,1,13.01,2,1,14.26,100,1,12.98,200,1,14.28,100,1,12.86,100,1,14.46,100,1,12.73,100,1,14.48,700,1,12.71,100,1,14.56,800,1,12.5,700,1,14.6,700,1,12.49,200,1,14.68,700,1,12.46,100,1,14.74,200,1,12.43,700,1,14.75,100,1,ARL,333581389
2132,2025-07-17T16:08:27.533773259Z,2025-07-17T16:08:27.533773259Z,10,2,1108,A,A,0,15.040000000,100,130,165191,277841588,13.11,100,1,13.98,2,1,13.01,2,1,14.26,100,1,12.98,200,1,14.28,100,1,12.86,100,1,14.46,100,1,12.73,100,1,14.48,700,1,12.71,100,1,14.56,800,1,12.5,700,1,14.6,700,1,12.49,200,1,14.68,700,1,12.46,100,1,14.74,200,1,12.43,700,1,14.75,100,1,ARL,333581845
2133,2025-07-17T16:08:27.987513451Z,2025-07-17T16:08:27.987513451Z,10,2,1108,A,A,0,13.990000000,100,130,165288,277846288,13.11,100,1,13.98,2,1,13.01,2,1,13.99,100,1,12.98,200,1,14.26,100,1,12.86,100,1,14.28,100,1,12.73,100,1,14.46,100,1,12.71,100,1,14.48,700,1,12.5,700,1,14.56,800,1,12.49,200,1,14.6,700,1,12.46,100,1,14.68,700,1,12.43,700,1,14.74,200,1,ARL,333590057
2134,2025-07-17T16:08:58.024814068Z,2025-07-17T16:08:58.024814068Z,10,2,1108,A,A,0,13.810000000,15,130,165314,278261182,13.11,100,1,13.81,15,1,13.01,2,1,13.98,2,1,12.98,200,1,13.99,100,1,12.86,100,1,14.26,100,1,12.73,100,1,14.28,100,1,12.71,100,1,14.46,100,1,12.5,700,1,14.48,700,1,12.49,200,1,14.56,800,1,12.46,100,1,14.6,700,1,12.43,700,1,14.68,700,1,ARL,334141429
2135,2025-07-17T16:09:00.222509491Z,2025-07-17T16:09:00.222509491Z,10,2,1108,C,A,0,13.990000000,100,0,165743,278295684,13.11,100,1,13.81,15,1,13.01,2,1,13.98,2,1,12.98,200,1,14.26,100,1,12.86,100,1,14.28,100,1,12.73,100,1,14.46,100,1,12.71,100,1,14.48,700,1,12.5,700,1,14.56,800,1,12.49,200,1,14.6,700,1,12.46,100,1,14.68,700,1,12.43,700,1,14.74,200,1,ARL,333590057
2136,2025-07-17T16:09:00.222509491Z,2025-07-17T16:09:00.222509491Z,10,2,1108,A,A,0,13.820000000,100,130,165743,278295684,13.11,100,1,13.81,15,1,13.01,2,1,13.82,100,1,12.98,200,1,13.98,2,1,12.86,100,1,14.26,100,1,12.73,100,1,14.28,100,1,12.71,100,1,14.46,100,1,12.5,700,1,14.48,700,1,12.49,200,1,14.56,800,1,12.46,100,1,14.6,700,1,12.43,700,1,14.68,700,1,ARL,334189729
2137,2025-07-17T16:09:00.223269382Z,2025-07-17T16:09:00.223269382Z,10,2,1108,C,A,0,15.040000000,100,0,167375,278295848,13.11,100,1,13.81,15,1,13.01,2,1,13.82,100,1,12.98,200,1,13.98,2,1,12.86,100,1,14.26,100,1,12.73,100,1,14.28,100,1,12.71,100,1,14.46,100,1,12.5,700,1,14.48,700,1,12.49,200,1,14.56,800,1,12.46,100,1,14.6,700,1,12.43,700,1,14.68,700,1,ARL,333581845
2138,2025-07-17T16:09:00.223269382Z,2025-07-17T16:09:00.223269382Z,10,2,1108,A,A,0,14.890000000,100,128,167375,278295848,13.11,100,1,13.81,15,1,13.01,2,1,13.82,100,1,12.98,200,1,13.98,2,1,12.86,100,1,14.26,100,1,12.73,100,1,14.28,100,1,12.71,100,1,14.46,100,1,12.5,700,1,14.48,700,1,12.49,200,1,14.56,800,1,12.46,100,1,14.6,700,1,12.43,700,1,14.68,700,1,ARL,334189777
2139,2025-07-17T16:09:00.226338384Z,2025-07-17T16:09:00.226338384Z,10,2,1108,C,A,0,14.750000000,100,0,165962,278296281,13.11,100,1,13.81,15,1,13.01,2,1,13.82,100,1,12.98,200,1,13.98,2,1,12.86,100,1,14.26,100,1,12.73,100,1,14.28,100,1,12.71,100,1,14.46,100,1,12.5,700,1,14.48,700,1,12.49,200,1,14.56,800,1,12.46,100,1,14.6,700,1,12.43,700,1,14.68,700,1,ARL,333581569
2140,2025-07-17T16:09:00.226338384Z,2025-07-17T16:09:00.226338384Z,10,2,1108,A,A,0,14.610000000,100,130,165962,278296281,13.11,100,1,13.81,15,1,13.01,2,1,13.82,100,1,12.98,200,1,13.98,2,1,12.86,100,1,14.26,100,1,12.73,100,1,14.28,100,1,12.71,100,1,14.46,100,1,12.5,700,1,14.48,700,1,12.49,200,1,14.56,800,1,12.46,100,1,14.6,700,1,12.43,700,1,14.61,100,1,ARL,334190189
2141,2025-07-17T16:09:00.227763275Z,2025-07-17T16:09:00.227763275Z,10,2,1108,C,A,0,14.260000000,100,130,165786,278296402,13.11,100,1,13.81,15,1,13.01,2,1,13.82,100,1,12.98,200,1,13.98,2,1,12.86,100,1,14.28,100,1,12.73,100,1,14.46,100,1,12.71,100,1,14.48,700,1,12.5,700,1,14.56,800,1,12.49,200,1,14.6,700,1,12.46,100,1,14.61,100,1,12.43,700,1,14.68,700,1,ARL,333581765
2142,2025-07-17T16:09:00.227818153Z,2025-07-17T16:09:00.227818153Z,10,2,1108,A,A,0,14.100000000,100,130,165330,278296411,13.11,100,1,13.81,15,1,13.01,2,1,13.82,100,1,12.98,200,1,13.98,2,1,12.86,100,1,14.1,100,1,12.73,100,1,14.28,100,1,12.71,100,1,14.46,100,1,12.5,700,1,14.48,700,1,12.49,200,1,14.56,800,1,12.46,100,1,14.6,700,1,12.43,700,1,14.61,100,1,ARL,334190225
2143,2025-07-17T16:09:00.232743323Z,2025-07-17T16:09:00.232743323Z,10,2,1108,C,A,0,14.940000000,100,0,165559,278296544,13.11,100,1,13.81,15,1,13.01,2,1,13.82,100,1,12.98,200,1,13.98,2,1,12.86,100,1,14.1,100,1,12.73,100,1,14.28,100,1,12.71,100,1,14.46,100,1,12.5,700,1,14.48,700,1,12.49,200,1,14.56,800,1,12.46,100,1,14.6,700,1,12.43,700,1,14.61,100,1,ARL,333581429
2144,2025-07-17T16:09:00.232743323Z,2025-07-17T16:09:00.232743323Z,10,2,1108,A,A,0,14.790000000,100,130,165559,278296544,13.11,100,1,13.81,15,1,13.01,2,1,13.82,100,1,12.98,200,1,13.98,2,1,12.86,100,1,14.1,100,1,12.73,100,1,14.28,100,1,12.71,100,1,14.46,100,1,12.5,700,1,14.48,700,1,12.49,200,1,14.56,800,1,12.46,100,1,14.6,700,1,12.43,700,1,14.61,100,1,ARL,334190353
2145,2025-07-17T16:09:00.326127587Z,2025-07-17T16:09:00.326127587Z,10,2,1108,C,A,0,17.730000000,100,0,165699,278298302,13.11,100,1,13.81,15,1,13.01,2,1,13.82,100,1,12.98,200,1,13.98,2,1,12.86,100,1,14.1,100,1,12.73,100,1,14.28,100,1,12.71,100,1,14.46,100,1,12.5,700,1,14.48,700,1,12.49,200,1,14.56,800,1,12.46,100,1,14.6,700,1,12.43,700,1,14.61,100,1,ARL,333581425
2146,2025-07-17T16:09:00.326127587Z,2025-07-17T16:09:00.326127587Z,10,2,1108,A,A,0,17.560000000,100,130,165699,278298302,13.11,100,1,13.81,15,1,13.01,2,1,13.82,100,1,12.98,200,1,13.98,2,1,12.86,100,1,14.1,100,1,12.73,100,1,14.28,100,1,12.71,100,1,14.46,100,1,12.5,700,1,14.48,700,1,12.49,200,1,14.56,800,1,12.46,100,1,14.6,700,1,12.43,700,1,14.61,100,1,ARL,334192253
2147,2025-07-17T16:09:00.335442266Z,2025-07-17T16:09:00.335442266Z,10,2,1108,C,A,0,16.060000000,100,0,165561,278298372,13.11,100,1,13.81,15,1,13.01,2,1,13.82,100,1,12.98,200,1,13.98,2,1,12.86,100,1,14.1,100,1,12.73,100,1,14.28,100,1,12.71,100,1,14.46,100,1,12.5,700,1,14.48,700,1,12.49,200,1,14.56,800,1,12.46,100,1,14.6,700,1,12.43,700,1,14.61,100,1,ARL,333581433
2148,2025-07-17T16:09:00.335442266Z,2025-07-17T16:09:00.335442266Z,10,2,1108,A,A,0,15.900000000,100,130,165561,278298372,13.11,100,1,13.81,15,1,13.01,2,1,13.82,100,1,12.98,200,1,13.98,2,1,12.86,100,1,14.1,100,1,12.73,100,1,14.28,100,1,12.71,100,1,14.46,100,1,12.5,700,1,14.48,700,1,12.49,200,1,14.56,800,1,12.46,100,1,14.6,700,1,12.43,700,1,14.61,100,1,ARL,334192405
2149,2025-07-17T16:09:00.695610142Z,2025-07-17T16:09:00.695610142Z,10,2,1108,C,A,0,14.940000000,100,0,165868,278304343,13.11,100,1,13.81,15,1,13.01,2,1,13.82,100,1,12.98,200,1,13.98,2,1,12.86,100,1,14.1,100,1,12.73,100,1,14.28,100,1,12.71,100,1,14.46,100,1,12.5,700,1,14.48,700,1,12.49,200,1,14.56,800,1,12.46,100,1,14.6,700,1,12.43,700,1,14.61,100,1,ARL,333581409
2150,2025-07-17T16:09:00.695610142Z,2025-07-17T16:09:00.695610142Z,10,2,1108,A,A,0,14.790000000,100,130,165868,278304343,13.11,100,1,13.81,15,1,13.01,2,1,13.82,100,1,12.98,200,1,13.98,2,1,12.86,100,1,14.1,100,1,12.73,100,1,14.28,100,1,12.71,100,1,14.46,100,1,12.5,700,1,14.48,700,1,12.49,200,1,14.56,800,1,12.46,100,1,14.6,700,1,12.43,700,1,14.61,100,1,ARL,334199009
2151,2025-07-17T16:09:08.719524374Z,2025-07-17T16:09:08.719524374Z,10,2,1108,A,A,0,13.750000000,15,130,166319,278436950,13.11,100,1,13.75,15,1,13.01,2,1,13.81,15,1,12.98,200,1,13.82,100,1,12.86,100,1,13.98,2,1,12.73,100,1,14.1,100,1,12.71,100,1,14.28,100,1,12.5,700,1,14.46,100,1,12.49,200,1,14.48,700,1,12.46,100,1,14.56,800,1,12.43,700,1,14.6,700,1,ARL,334366613
2152,2025-07-17T16:09:08.719706070Z,2025-07-17T16:09:08.719706070Z,10,2,1108,C,A,0,13.820000000,100,0,165340,278436967,13.11,100,1,13.75,15,1,13.01,2,1,13.81,15,1,12.98,200,1,13.98,2,1,12.86,100,1,14.1,100,1,12.73,100,1,14.28,100,1,12.71,100,1,14.46,100,1,12.5,700,1,14.48,700,1,12.49,200,1,14.56,800,1,12.46,100,1,14.6,700,1,12.43,700,1,14.61,100,1,ARL,334189729
2153,2025-07-17T16:09:08.719706070Z,2025-07-17T16:09:08.719706070Z,10,2,1108,A,A,0,13.760000000,100,130,165340,278436967,13.11,100,1,13.75,15,1,13.01,2,1,13.76,100,1,12.98,200,1,13.81,15,1,12.86,100,1,13.98,2,1,12.73,100,1,14.1,100,1,12.71,100,1,14.28,100,1,12.5,700,1,14.46,100,1,12.49,200,1,14.48,700,1,12.46,100,1,14.56,800,1,12.43,700,1,14.6,700,1,ARL,334366617
2154,2025-07-17T16:09:08.720442245Z,2025-07-17T16:09:08.720442245Z,10,2,1108,C,A,0,14.890000000,100,0,165687,278436994,13.11,100,1,13.75,15,1,13.01,2,1,13.76,100,1,12.98,200,1,13.81,15,1,12.86,100,1,13.98,2,1,12.73,100,1,14.1,100,1,12.71,100,1,14.28,100,1,12.5,700,1,14.46,100,1,12.49,200,1,14.48,700,1,12.46,100,1,14.56,800,1,12.43,700,1,14.6,700,1,ARL,334189777
2155,2025-07-17T16:09:08.720442245Z,2025-07-17T16:09:08.720442245Z,10,2,1108,A,A,0,14.830000000,100,130,165687,278436994,13.11,100,1,13.75,15,1,13.01,2,1,13.76,100,1,12.98,200,1,13.81,15,1,12.86,100,1,13.98,2,1,12.73,100,1,14.1,100,1,12.71,100,1,14.28,100,1,12.5,700,1,14.46,100,1,12.49,200,1,14.48,700,1,12.46,100,1,14.56,800,1,12.43,700,1,14.6,700,1,ARL,334366645
2156,2025-07-17T16:09:18.819135505Z,2025-07-17T16:09:18.819135505Z,10,2,1108,C,A,0,13.810000000,15,130,165230,278596985,13.11,100,1,13.75,15,1,13.01,2,1,13.76,100,1,12.98,200,1,13.98,2,1,12.86,100,1,14.1,100,1,12.73,100,1,14.28,100,1,12.71,100,1,14.46,100,1,12.5,700,1,14.48,700,1,12.49,200,1,14.56,800,1,12.46,100,1,14.6,700,1,12.43,700,1,14.61,100,1,ARL,334141429
2157,2025-07-17T16:09:19.927039122Z,2025-07-17T16:09:19.927039122Z,10,2,1108,A,A,0,13.730000000,15,130,165901,278621672,13.11,100,1,13.73,15,1,13.01,2,1,13.75,15,1,12.98,200,1,13.76,100,1,12.86,100,1,13.98,2,1,12.73,100,1,14.1,100,1,12.71,100,1,14.28,100,1,12.5,700,1,14.46,100,1,12.49,200,1,14.48,700,1,12.46,100,1,14.56,800,1,12.43,700,1,14.6,700,1,ARL,334583329
2158,2025-07-17T16:09:19.927745104Z,2025-07-17T16:09:19.927745104Z,10,2,1108,C,A,0,14.740000000,100,0,165599,278621693,13.11,100,1,13.73,15,1,13.01,2,1,13.75,15,1,12.98,200,1,13.76,100,1,12.86,100,1,13.98,2,1,12.73,100,1,14.1,100,1,12.71,100,1,14.28,100,1,12.5,700,1,14.46,100,1,12.49,200,1,14.48,700,1,12.46,100,1,14.56,800,1,12.43,700,1,14.6,700,1,ARL,333581393
2159,2025-07-17T16:09:19.927745104Z,2025-07-17T16:09:19.927745104Z,10,2,1108,A,A,0,14.620000000,100,130,165599,278621693,13.11,100,1,13.73,15,1,13.01,2,1,13.75,15,1,12.98,200,1,13.76,100,1,12.86,100,1,13.98,2,1,12.73,100,1,14.1,100,1,12.71,100,1,14.28,100,1,12.5,700,1,14.46,100,1,12.49,200,1,14.48,700,1,12.46,100,1,14.56,800,1,12.43,700,1,14.6,700,1,ARL,334583349
2160,2025-07-17T16:09:19.928153837Z,2025-07-17T16:09:19.928153837Z,10,2,1108,C,A,0,14.740000000,100,0,165532,278621695,13.11,100,1,13.73,15,1,13.01,2,1,13.75,15,1,12.98,200,1,13.76,100,1,12.86,100,1,13.98,2,1,12.73,100,1,14.1,100,1,12.71,100,1,14.28,100,1,12.5,700,1,14.46,100,1,12.49,200,1,14.48,700,1,12.46,100,1,14.56,800,1,12.43,700,1,14.6,700,1,ARL,333581481
2161,2025-07-17T16:09:19.928153837Z,2025-07-17T16:09:19.928153837Z,10,2,1108,A,A,0,14.620000000,100,130,165532,278621695,13.11,100,1,13.73,15,1,13.01,2,1,13.75,15,1,12.98,200,1,13.76,100,1,12.86,100,1,13.98,2,1,12.73,100,1,14.1,100,1,12.71,100,1,14.28,100,1,12.5,700,1,14.46,100,1,12.49,200,1,14.48,700,1,12.46,100,1,14.56,800,1,12.43,700,1,14.6,700,1,ARL,334583361
2162,2025-07-17T16:09:20.284695585Z,2025-07-17T16:09:20.284695585Z,10,2,1108,C,A,0,13.760000000,100,0,165490,278629057,13.11,100,1,13.73,15,1,13.01,2,1,13.75,15,1,12.98,200,1,13.98,2,1,12.86,100,1,14.1,100,1,12.73,100,1,14.28,100,1,12.71,100,1,14.46,100,1,12.5,700,1,14.48,700,1,12.49,200,1,14.56,800,1,12.46,100,1,14.6,700,1,12.43,700,1,14.61,100,1,ARL,334366617
2163,2025-07-17T16:09:20.284695585Z,2025-07-17T16:09:20.284695585Z,10,2,1108,A,A,0,13.740000000,100,130,165490,278629057,13.11,100,1,13.73,15,1,13.01,2,1,13.74,100,1,12.98,200,1,13.75,15,1,12.86,100,1,13.98,2,1,12.73,100,1,14.1,100,1,12.71,100,1,14.28,100,1,12.5,700,1,14.46,100,1,12.49,200,1,14.48,700,1,12.46,100,1,14.56,800,1,12.43,700,1,14.6,700,1,ARL,334593569
2164,2025-07-17T16:09:20.293106270Z,2025-07-17T16:09:20.293106270Z,10,2,1108,C,A,0,14.100000000,100,130,165350,278629219,13.11,100,1,13.73,15,1,13.01,2,1,13.74,100,1,12.98,200,1,13.75,15,1,12.86,100,1,13.98,2,1,12.73,100,1,14.28,100,1,12.71,100,1,14.46,100,1,12.5,700,1,14.48,700,1,12.49,200,1,14.56,800,1,12.46,100,1,14.6,700,1,12.43,700,1,14.61,100,1,ARL,334190225
2165,2025-07-17T16:09:20.293161454Z,2025-07-17T16:09:20.293161454Z,10,2,1108,A,A,0,14.010000000,100,130,165187,278629220,13.11,100,1,13.73,15,1,13.01,2,1,13.74,100,1,12.98,200,1,13.75,15,1,12.86,100,1,13.98,2,1,12.73,100,1,14.01,100,1,12.71,100,1,14.28,100,1,12.5,700,1,14.46,100,1,12.49,200,1,14.48,700,1,12.46,100,1,14.56,800,1,12.43,700,1,14.6,700,1,ARL,334593753
2166,2025-07-17T16:09:20.818648795Z,2025-07-17T16:09:20.818648795Z,10,2,1108,C,A,0,13.730000000,15,130,165140,278640667,13.11,100,1,13.74,100,1,13.01,2,1,13.75,15,1,12.98,200,1,13.98,2,1,12.86,100,1,14.01,100,1,12.73,100,1,14.28,100,1,12.71,100,1,14.46,100,1,12.5,700,1,14.48,700,1,12.49,200,1,14.56,800,1,12.46,100,1,14.6,700,1,12.43,700,1,14.61,100,1,ARL,334583329
2167,2025-07-17T16:09:20.818761228Z,2025-07-17T16:09:20.818761228Z,10,2,1108,C,A,0,13.750000000,15,130,165128,278640670,13.11,100,1,13.74,100,1,13.01,2,1,13.98,2,1,12.98,200,1,14.01,100,1,12.86,100,1,14.28,100,1,12.73,100,1,14.46,100,1,12.71,100,1,14.48,700,1,12.5,700,1,14.56,800,1,12.49,200,1,14.6,700,1,12.46,100,1,14.61,100,1,12.43,700,1,14.62,200,1,ARL,334366613
2168,2025-07-17T16:09:28.985956629Z,2025-07-17T16:09:28.985956629Z,10,2,1108,C,A,0,13.980000000,2,0,165803,278784943,13.11,100,1,13.74,100,1,13.01,2,1,14.01,100,1,12.98,200,1,14.28,100,1,12.86,100,1,14.46,100,1,12.73,100,1,14.48,700,1,12.71,100,1,14.56,800,1,12.5,700,1,14.6,700,1,12.49,200,1,14.61,100,1,12.46,100,1,14.62,200,1,12.43,700,1,14.68,700,1,ARL,333581677
2169,2025-07-17T16:09:28.985956629Z,2025-07-17T16:09:28.985956629Z,10,2,1108,A,A,0,13.900000000,2,130,165803,278784943,13.11,100,1,13.74,100,1,13.01,2,1,13.9,2,1,12.98,200,1,14.01,100,1,12.86,100,1,14.28,100,1,12.73,100,1,14.46,100,1,12.71,100,1,14.48,700,1,12.5,700,1,14.56,800,1,12.49,200,1,14.6,700,1,12.46,100,1,14.61,100,1,12.43,700,1,14.62,200,1,ARL,334804177
2170,2025-07-17T16:09:40.821522565Z,2025-07-17T16:09:40.821522565Z,10,2,1108,A,A,0,13.700000000,15,130,165340,278938091,13.11,100,1,13.7,15,1,13.01,2,1,13.74,100,1,12.98,200,1,13.9,2,1,12.86,100,1,14.01,100,1,12.73,100,1,14.28,100,1,12.71,100,1,14.46,100,1,12.5,700,1,14.48,700,1,12.49,200,1,14.56,800,1,12.46,100,1,14.6,700,1,12.43,700,1,14.61,100,1,ARL,335003269
2171,2025-07-17T16:09:40.853439053Z,2025-07-17T16:09:40.853439053Z,10,2,1108,C,A,0,13.740000000,100,0,165524,278938747,13.11,100,1,13.7,15,1,13.01,2,1,13.9,2,1,12.98,200,1,14.01,100,1,12.86,100,1,14.28,100,1,12.73,100,1,14.46,100,1,12.71,100,1,14.48,700,1,12.5,700,1,14.56,800,1,12.49,200,1,14.6,700,1,12.46,100,1,14.61,100,1,12.43,700,1,14.62,200,1,ARL,334593569
2172,2025-07-17T16:09:40.853439053Z,2025-07-17T16:09:40.853439053Z,10,2,1108,A,A,0,13.710000000,100,130,165524,278938747,13.11,100,1,13.7,15,1,13.01,2,1,13.71,100,1,12.98,200,1,13.9,2,1,12.86,100,1,14.01,100,1,12.73,100,1,14.28,100,1,12.71,100,1,14.46,100,1,12.5,700,1,14.48,700,1,12.49,200,1,14.56,800,1,12.46,100,1,14.6,700,1,12.43,700,1,14.61,100,1,ARL,335003813
2173,2025-07-17T16:09:40.854190408Z,2025-07-17T16:09:40.854190408Z,10,2,1108,C,A,0,14.830000000,100,0,165614,278938765,13.11,100,1,13.7,15,1,13.01,2,1,13.71,100,1,12.98,200,1,13.9,2,1,12.86,100,1,14.01,100,1,12.73,100,1,14.28,100,1,12.71,100,1,14.46,100,1,12.5,700,1,14.48,700,1,12.49,200,1,14.56,800,1,12.46,100,1,14.6,700,1,12.43,700,1,14.61,100,1,ARL,334366645
2174,2025-07-17T16:09:40.854190408Z,2025-07-17T16:09:40.854190408Z,10,2,1108,A,A,0,14.770000000,100,130,165614,278938765,13.11,100,1,13.7,15,1,13.01,2,1,13.71,100,1,12.98,200,1,13.9,2,1,12.86,100,1,14.01,100,1,12.73,100,1,14.28,100,1,12.71,100,1,14.46,100,1,12.5,700,1,14.48,700,1,12.49,200,1,14.56,800,1,12.46,100,1,14.6,700,1,12.43,700,1,14.61,100,1,ARL,335003845
2175,2025-07-17T16:09:40.855558831Z,2025-07-17T16:09:40.855558831Z,10,2,1108,C,A,0,17.560000000,100,0,165591,278938788,13.11,100,1,13.7,15,1,13.01,2,1,13.71,100,1,12.98,200,1,13.9,2,1,12.86,100,1,14.01,100,1,12.73,100,1,14.28,100,1,12.71,100,1,14.46,100,1,12.5,700,1,14.48,700,1,12.49,200,1,14.56,800,1,12.46,100,1,14.6,700,1,12.43,700,1,14.61,100,1,ARL,334192253
2176,2025-07-17T16:09:40.855558831Z,2025-07-17T16:09:40.855558831Z,10,2,1108,A,A,0,17.420000000,100,130,165591,278938788,13.11,100,1,13.7,15,1,13.01,2,1,13.71,100,1,12.98,200,1,13.9,2,1,12.86,100,1,14.01,100,1,12.73,100,1,14.28,100,1,12.71,100,1,14.46,100,1,12.5,700,1,14.48,700,1,12.49,200,1,14.56,800,1,12.46,100,1,14.6,700,1,12.43,700,1,14.61,100,1,ARL,335003849
2177,2025-07-17T16:09:50.820783486Z,2025-07-17T16:09:50.820783486Z,10,2,1108,A,A,0,13.670000000,15,130,165645,279081140,13.11,100,1,13.67,15,1,13.01,2,1,13.7,15,1,12.98,200,1,13.71,100,1,12.86,100,1,13.9,2,1,12.73,100,1,14.01,100,1,12.71,100,1,14.28,100,1,12.5,700,1,14.46,100,1,12.49,200,1,14.48,700,1,12.46,100,1,14.56,800,1,12.43,700,1,14.6,700,1,ARL,335178437
2178,2025-07-17T16:09:52.678611805Z,2025-07-17T16:09:52.678611805Z,10,2,1108,C,A,0,13.710000000,100,0,165553,279109959,13.11,100,1,13.67,15,1,13.01,2,1,13.7,15,1,12.98,200,1,13.9,2,1,12.86,100,1,14.01,100,1,12.73,100,1,14.28,100,1,12.71,100,1,14.46,100,1,12.5,700,1,14.48,700,1,12.49,200,1,14.56,800,1,12.46,100,1,14.6,700,1,12.43,700,1,14.61,100,1,ARL,335003813
2179,2025-07-17T16:09:52.678611805Z,2025-07-17T16:09:52.678611805Z,10,2,1108,A,A,0,13.680000000,100,130,165553,279109959,13.11,100,1,13.67,15,1,13.01,2,1,13.68,100,1,12.98,200,1,13.7,15,1,12.86,100,1,13.9,2,1,12.73,100,1,14.01,100,1,12.71,100,1,14.28,100,1,12.5,700,1,14.46,100,1,12.49,200,1,14.48,700,1,12.46,100,1,14.56,800,1,12.43,700,1,14.6,700,1,ARL,335220349
2180,2025-07-17T16:09:52.679678566Z,2025-07-17T16:09:52.679678566Z,10,2,1108,C,A,0,15.900000000,100,0,165772,279109991,13.11,100,1,13.67,15,1,13.01,2,1,13.68,100,1,12.98,200,1,13.7,15,1,12.86,100,1,13.9,2,1,12.73,100,1,14.01,100,1,12.71,100,1,14.28,100,1,12.5,700,1,14.46,100,1,12.49,200,1,14.48,700,1,12.46,100,1,14.56,800,1,12.43,700,1,14.6,700,1,ARL,334192405
2181,2025-07-17T16:09:52.679678566Z,2025-07-17T16:09:52.679678566Z,10,2,1108,A,A,0,15.740000000,100,130,165772,279109991,13.11,100,1,13.67,15,1,13.01,2,1,13.68,100,1,12.98,200,1,13.7,15,1,12.86,100,1,13.9,2,1,12.73,100,1,14.01,100,1,12.71,100,1,14.28,100,1,12.5,700,1,14.46,100,1,12.49,200,1,14.48,700,1,12.46,100,1,14.56,800,1,12.43,700,1,14.6,700,1,ARL,335220497
2182,2025-07-17T16:09:52.679769832Z,2025-07-17T16:09:52.679769832Z,10,2,1108,C,A,0,14.790000000,100,0,166994,279109996,13.11,100,1,13.67,15,1,13.01,2,1,13.68,100,1,12.98,200,1,13.7,15,1,12.86,100,1,13.9,2,1,12.73,100,1,14.01,100,1,12.71,100,1,14.28,100,1,12.5,700,1,14.46,100,1,12.49,200,1,14.48,700,1,12.46,100,1,14.56,800,1,12.43,700,1,14.6,700,1,ARL,334190353
2183,2025-07-17T16:09:52.679769832Z,2025-07-17T16:09:52.679769832Z,10,2,1108,A,A,0,14.640000000,100,130,166994,279109996,13.11,100,1,13.67,15,1,13.01,2,1,13.68,100,1,12.98,200,1,13.7,15,1,12.86,100,1,13.9,2,1,12.73,100,1,14.01,100,1,12.71,100,1,14.28,100,1,12.5,700,1,14.46,100,1,12.49,200,1,14.48,700,1,12.46,100,1,14.56,800,1,12.43,700,1,14.6,700,1,ARL,335220525
2184,2025-07-17T16:09:52.680672148Z,2025-07-17T16:09:52.680672148Z,10,2,1108,C,A,0,15.360000000,100,0,165588,279110032,13.11,100,1,13.67,15,1,13.01,2,1,13.68,100,1,12.98,200,1,13.7,15,1,12.86,100,1,13.9,2,1,12.73,100,1,14.01,100,1,12.71,100,1,14.28,100,1,12.5,700,1,14.46,100,1,12.49,200,1,14.48,700,1,12.46,100,1,14.56,800,1,12.43,700,1,14.6,700,1,ARL,333581441
2185,2025-07-17T16:09:52.680672148Z,2025-07-17T16:09:52.680672148Z,10,2,1108,A,A,0,15.050000000,100,130,165588,279110032,13.11,100,1,13.67,15,1,13.01,2,1,13.68,100,1,12.98,200,1,13.7,15,1,12.86,100,1,13.9,2,1,12.73,100,1,14.01,100,1,12.71,100,1,14.28,100,1,12.5,700,1,14.46,100,1,12.49,200,1,14.48,700,1,12.46,100,1,14.56,800,1,12.43,700,1,14.6,700,1,ARL,335220549
2186,2025-07-17T16:09:52.681844377Z,2025-07-17T16:09:52.681844377Z,10,2,1108,C,A,0,14.610000000,100,130,165561,279110066,13.11,100,1,13.67,15,1,13.01,2,1,13.68,100,1,12.98,200,1,13.7,15,1,12.86,100,1,13.9,2,1,12.73,100,1,14.01,100,1,12.71,100,1,14.28,100,1,12.5,700,1,14.46,100,1,12.49,200,1,14.48,700,1,12.46,100,1,14.56,800,1,12.43,700,1,14.6,700,1,ARL,334190189
2187,2025-07-17T16:09:52.681961200Z,2025-07-17T16:09:52.681961200Z,10,2,1108,A,A,0,14.470000000,100,130,166330,279110068,13.11,100,1,13.67,15,1,13.01,2,1,13.68,100,1,12.98,200,1,13.7,15,1,12.86,100,1,13.9,2,1,12.73,100,1,14.01,100,1,12.71,100,1,14.28,100,1,12.5,700,1,14.46,100,1,12.49,200,1,14.47,100,1,12.46,100,1,14.48,700,1,12.43,700,1,14.56,800,1,ARL,335220561
2188,2025-07-17T16:09:52.683757265Z,2025-07-17T16:09:52.683757265Z,10,2,1108,C,A,0,14.790000000,100,0,165442,279110090,13.11,100,1,13.67,15,1,13.01,2,1,13.68,100,1,12.98,200,1,13.7,15,1,12.86,100,1,13.9,2,1,12.73,100,1,14.01,100,1,12.71,100,1,14.28,100,1,12.5,700,1,14.46,100,1,12.49,200,1,14.47,100,1,12.46,100,1,14.48,700,1,12.43,700,1,14.56,800,1,ARL,334199009
2189,2025-07-17T16:09:52.683757265Z,2025-07-17T16:09:52.683757265Z,10,2,1108,A,A,0,14.640000000,100,130,165442,279110090,13.11,100,1,13.67,15,1,13.01,2,1,13.68,100,1,12.98,200,1,13.7,15,1,12.86,100,1,13.9,2,1,12.73,100,1,14.01,100,1,12.71,100,1,14.28,100,1,12.5,700,1,14.46,100,1,12.49,200,1,14.47,100,1,12.46,100,1,14.48,700,1,12.43,700,1,14.56,800,1,ARL,335220629
2190,2025-07-17T16:10:04.521306513Z,2025-07-17T16:10:04.521306513Z,10,2,1108,C,A,0,13.670000000,15,130,165291,279306715,13.11,100,1,13.68,100,1,13.01,2,1,13.7,15,1,12.98,200,1,13.9,2,1,12.86,100,1,14.01,100,1,12.73,100,1,14.28,100,1,12.71,100,1,14.46,100,1,12.5,700,1,14.47,100,1,12.49,200,1,14.48,700,1,12.46,100,1,14.56,800,1,12.43,700,1,14.6,700,1,ARL,335178437
2191,2025-07-17T16:10:04.561688313Z,2025-07-17T16:10:04.561688313Z,10,2,1108,C,A,0,13.700000000,15,128,166543,279312083,13.11,100,1,13.68,100,1,13.01,2,1,13.9,2,1,12.98,200,1,14.01,100,1,12.86,100,1,14.28,100,1,12.73,100,1,14.46,100,1,12.71,100,1,14.47,100,1,12.5,700,1,14.48,700,1,12.49,200,1,14.56,800,1,12.46,100,1,14.6,700,1,12.43,700,1,14.62,200,1,ARL,335003269
2192,2025-07-17T16:10:32.822495087Z,2025-07-17T16:10:32.822495087Z,10,2,1108,A,A,0,13.650000000,15,130,165411,279705339,13.11,100,1,13.65,15,1,13.01,2,1,13.68,100,1,12.98,200,1,13.9,2,1,12.86,100,1,14.01,100,1,12.73,100,1,14.28,100,1,12.71,100,1,14.46,100,1,12.5,700,1,14.47,100,1,12.49,200,1,14.48,700,1,12.46,100,1,14.56,800,1,12.43,700,1,14.6,700,1,ARL,335996705
2193,2025-07-17T16:10:32.822757517Z,2025-07-17T16:10:32.822757517Z,10,2,1108,C,A,0,13.680000000,100,0,165621,279705347,13.11,100,1,13.65,15,1,13.01,2,1,13.9,2,1,12.98,200,1,14.01,100,1,12.86,100,1,14.28,100,1,12.73,100,1,14.46,100,1,12.71,100,1,14.47,100,1,12.5,700,1,14.48,700,1,12.49,200,1,14.56,800,1,12.46,100,1,14.6,700,1,12.43,700,1,14.62,200,1,ARL,335220349
2194,2025-07-17T16:10:32.822757517Z,2025-07-17T16:10:32.822757517Z,10,2,1108,A,A,0,13.660000000,100,130,165621,279705347,13.11,100,1,13.65,15,1,13.01,2,1,13.66,100,1,12.98,200,1,13.9,2,1,12.86,100,1,14.01,100,1,12.73,100,1,14.28,100,1,12.71,100,1,14.46,100,1,12.5,700,1,14.47,100,1,12.49,200,1,14.48,700,1,12.46,100,1,14.56,800,1,12.43,700,1,14.6,700,1,ARL,335996709
2195,2025-07-17T16:10:32.823491276Z,2025-07-17T16:10:32.823491276Z,10,2,1108,C,A,0,14.770000000,100,0,165627,279705362,13.11,100,1,13.65,15,1,13.01,2,1,13.66,100,1,12.98,200,1,13.9,2,1,12.86,100,1,14.01,100,1,12.73,100,1,14.28,100,1,12.71,100,1,14.46,100,1,12.5,700,1,14.47,100,1,12.49,200,1,14.48,700,1,12.46,100,1,14.56,800,1,12.43,700,1,14.6,700,1,ARL,335003845
2196,2025-07-17T16:10:32.823491276Z,2025-07-17T16:10:32.823491276Z,10,2,1108,A,A,0,14.720000000,100,130,165627,279705362,13.11,100,1,13.65,15,1,13.01,2,1,13.66,100,1,12.98,200,1,13.9,2,1,12.86,100,1,14.01,100,1,12.73,100,1,14.28,100,1,12.71,100,1,14.46,100,1,12.5,700,1,14.47,100,1,12.49,200,1,14.48,700,1,12.46,100,1,14.56,800,1,12.43,700,1,14.6,700,1,ARL,335996725
2197,2025-07-17T16:10:32.830032662Z,2025-07-17T16:10:32.830032662Z,10,2,1108,C,A,0,14.010000000,100,130,168182,279705485,13.11,100,1,13.65,15,1,13.01,2,1,13.66,100,1,12.98,200,1,13.9,2,1,12.86,100,1,14.28,100,1,12.73,100,1,14.46,100,1,12.71,100,1,14.47,100,1,12.5,700,1,14.48,700,1,12.49,200,1,14.56,800,1,12.46,100,1,14.6,700,1,12.43,700,1,14.62,200,1,ARL,334593753
2198,2025-07-17T16:10:32.830085472Z,2025-07-17T16:10:32.830085472Z,10,2,1108,A,A,0,13.930000000,100,130,165248,279705486,13.11,100,1,13.65,15,1,13.01,2,1,13.66,100,1,12.98,200,1,13.9,2,1,12.86,100,1,13.93,100,1,12.73,100,1,14.28,100,1,12.71,100,1,14.46,100,1,12.5,700,1,14.47,100,1,12.49,200,1,14.48,700,1,12.46,100,1,14.56,800,1,12.43,700,1,14.6,700,1,ARL,335996777
2199,2025-07-17T16:10:42.822189504Z,2025-07-17T16:10:42.822189504Z,10,2,1108,A,A,0,13.630000000,15,130,165365,279834760,13.11,100,1,13.63,15,1,13.01,2,1,13.65,15,1,12.98,200,1,13.66,100,1,12.86,100,1,13.9,2,1,12.73,100,1,13.93,100,1,12.71,100,1,14.28,100,1,12.5,700,1,14.46,100,1,12.49,200,1,14.47,100,1,12.46,100,1,14.48,700,1,12.43,700,1,14.56,800,1,ARL,336161333
2200,2025-07-17T16:10:42.822258887Z,2025-07-17T16:10:42.822258887Z,10,2,1108,C,A,0,13.660000000,100,0,165776,279834761,13.11,100,1,13.63,15,1,13.01,2,1,13.65,15,1,12.98,200,1,13.9,2,1,12.86,100,1,13.93,100,1,12.73,100,1,14.28,100,1,12.71,100,1,14.46,100,1,12.5,700,1,14.47,100,1,12.49,200,1,14.48,700,1,12.46,100,1,14.56,800,1,12.43,700,1,14.6,700,1,ARL,335996709
2201,2025-07-17T16:10:42.822258887Z,2025-07-17T16:10:42.822258887Z,10,2,1108,A,A,0,13.640000000,100,130,165776,279834761,13.11,100,1,13.63,15,1,13.01,2,1,13.64,100,1,12.98,200,1,13.65,15,1,12.86,100,1,13.9,2,1,12.73,100,1,13.93,100,1,12.71,100,1,14.28,100,1,12.5,700,1,14.46,100,1,12.49,200,1,14.47,100,1,12.46,100,1,14.48,700,1,12.43,700,1,14.56,800,1,ARL,336161337
2202,2025-07-17T16:10:42.822998664Z,2025-07-17T16:10:42.822998664Z,10,2,1108,C,A,0,14.460000000,100,130,165265,279834765,13.11,100,1,13.63,15,1,13.01,2,1,13.64,100,1,12.98,200,1,13.65,15,1,12.86,100,1,13.9,2,1,12.73,100,1,13.93,100,1,12.71,100,1,14.28,100,1,12.5,700,1,14.47,100,1,12.49,200,1,14.48,700,1,12.46,100,1,14.56,800,1,12.43,700,1,14.6,700,1,ARL,331927161
2203,2025-07-17T16:10:42.823352130Z,2025-07-17T16:10:42.823352130Z,10,2,1108,A,A,0,14.250000000,100,130,165314,279834767,13.11,100,1,13.63,15,1,13.01,2,1,13.64,100,1,12.98,200,1,13.65,15,1,12.86,100,1,13.9,2,1,12.73,100,1,13.93,100,1,12.71,100,1,14.25,100,1,12.5,700,1,14.28,100,1,12.49,200,1,14.47,100,1,12.46,100,1,14.48,700,1,12.43,700,1,14.56,800,1,ARL,336161365
2204,2025-07-17T16:10:46.533890361Z,2025-07-17T16:10:46.533890361Z,10,2,1108,C,A,0,14.620000000,100,0,165581,279921726,13.11,100,1,13.63,15,1,13.01,2,1,13.64,100,1,12.98,200,1,13.65,15,1,12.86,100,1,13.9,2,1,12.73,100,1,13.93,100,1,12.71,100,1,14.25,100,1,12.5,700,1,14.28,100,1,12.49,200,1,14.47,100,1,12.46,100,1,14.48,700,1,12.43,700,1,14.56,800,1,ARL,334583349
2205,2025-07-17T16:10:46.533890361Z,2025-07-17T16:10:46.533890361Z,10,2,1108,A,A,0,14.510000000,100,130,165581,279921726,13.11,100,1,13.63,15,1,13.01,2,1,13.64,100,1,12.98,200,1,13.65,15,1,12.86,100,1,13.9,2,1,12.73,100,1,13.93,100,1,12.71,100,1,14.25,100,1,12.5,700,1,14.28,100,1,12.49,200,1,14.47,100,1,12.46,100,1,14.48,700,1,12.43,700,1,14.51,100,1,ARL,336259225
2206,2025-07-17T16:10:46.537992315Z,2025-07-17T16:10:46.537992315Z,10,2,1108,C,A,0,13.650000000,15,128,166559,279921911,13.11,100,1,13.63,15,1,13.01,2,1,13.64,100,1,12.98,200,1,13.9,2,1,12.86,100,1,13.93,100,1,12.73,100,1,14.25,100,1,12.71,100,1,14.28,100,1,12.5,700,1,14.47,100,1,12.49,200,1,14.48,700,1,12.46,100,1,14.51,100,1,12.43,700,1,14.56,800,1,ARL,335996705
2207,2025-07-17T16:10:46.561080616Z,2025-07-17T16:10:46.561080616Z,10,2,1108,C,A,0,14.620000000,100,0,165414,279924883,13.11,100,1,13.63,15,1,13.01,2,1,13.64,100,1,12.98,200,1,13.9,2,1,12.86,100,1,13.93,100,1,12.73,100,1,14.25,100,1,12.71,100,1,14.28,100,1,12.5,700,1,14.47,100,1,12.49,200,1,14.48,700,1,12.46,100,1,14.51,100,1,12.43,700,1,14.56,800,1,ARL,334583361
2208,2025-07-17T16:10:46.561080616Z,2025-07-17T16:10:46.561080616Z,10,2,1108,A,A,0,14.510000000,100,130,165414,279924883,13.11,100,1,13.63,15,1,13.01,2,1,13.64,100,1,12.98,200,1,13.9,2,1,12.86,100,1,13.93,100,1,12.73,100,1,14.25,100,1,12.71,100,1,14.28,100,1,12.5,700,1,14.47,100,1,12.49,200,1,14.48,700,1,12.46,100,1,14.51,200,1,12.43,700,1,14.56,800,1,ARL,336261905
2209,2025-07-17T16:10:47.543238729Z,2025-07-17T16:10:47.543238729Z,10,2,1108,A,A,0,13.610000000,15,130,165272,279938097,13.11,100,1,13.61,15,1,13.01,2,1,13.63,15,1,12.98,200,1,13.64,100,1,12.86,100,1,13.9,2,1,12.73,100,1,13.93,100,1,12.71,100,1,14.25,100,1,12.5,700,1,14.28,100,1,12.49,200,1,14.47,100,1,12.46,100,1,14.48,700,1,12.43,700,1,14.51,200,1,ARL,336278197
2210,2025-07-17T16:10:48.657290980Z,2025-07-17T16:10:48.657290980Z,10,2,1108,C,A,0,13.640000000,100,0,165415,279952266,13.11,100,1,13.61,15,1,13.01,2,1,13.63,15,1,12.98,200,1,13.9,2,1,12.86,100,1,13.93,100,1,12.73,100,1,14.25,100,1,12.71,100,1,14.28,100,1,12.5,700,1,14.47,100,1,12.49,200,1,14.48,700,1,12.46,100,1,14.51,200,1,12.43,700,1,14.56,800,1,ARL,336161337
2211,2025-07-17T16:10:48.657290980Z,2025-07-17T16:10:48.657290980Z,10,2,1108,A,A,0,13.620000000,100,130,165415,279952266,13.11,100,1,13.61,15,1,13.01,2,1,13.62,100,1,12.98,200,1,13.63,15,1,12.86,100,1,13.9,2,1,12.73,100,1,13.93,100,1,12.71,100,1,14.25,100,1,12.5,700,1,14.28,100,1,12.49,200,1,14.47,100,1,12.46,100,1,14.48,700,1,12.43,700,1,14.51,200,1,ARL,336295769
2212,2025-07-17T16:10:48.658033954Z,2025-07-17T16:10:48.658033954Z,10,2,1108,C,A,0,14.720000000,100,0,165471,279952282,13.11,100,1,13.61,15,1,13.01,2,1,13.62,100,1,12.98,200,1,13.63,15,1,12.86,100,1,13.9,2,1,12.73,100,1,13.93,100,1,12.71,100,1,14.25,100,1,12.5,700,1,14.28,100,1,12.49,200,1,14.47,100,1,12.46,100,1,14.48,700,1,12.43,700,1,14.51,200,1,ARL,335996725
2213,2025-07-17T16:10:48.658033954Z,2025-07-17T16:10:48.658033954Z,10,2,1108,A,A,0,14.680000000,100,130,165471,279952282,13.11,100,1,13.61,15,1,13.01,2,1,13.62,100,1,12.98,200,1,13.63,15,1,12.86,100,1,13.9,2,1,12.73,100,1,13.93,100,1,12.71,100,1,14.25,100,1,12.5,700,1,14.28,100,1,12.49,200,1,14.47,100,1,12.46,100,1,14.48,700,1,12.43,700,1,14.51,200,1,ARL,336295845
2214,2025-07-17T16:10:51.058878264Z,2025-07-17T16:10:51.058878264Z,10,2,1108,C,A,0,13.610000000,15,128,166028,280001840,13.11,100,1,13.62,100,1,13.01,2,1,13.63,15,1,12.98,200,1,13.9,2,1,12.86,100,1,13.93,100,1,12.73,100,1,14.25,100,1,12.71,100,1,14.28,100,1,12.5,700,1,14.47,100,1,12.49,200,1,14.48,700,1,12.46,100,1,14.51,200,1,12.43,700,1,14.56,800,1,ARL,336278197
2215,2025-07-17T16:10:51.059016199Z,2025-07-17T16:10:51.059016199Z,10,2,1108,C,A,0,13.630000000,15,128,167724,280001873,13.11,100,1,13.62,100,1,13.01,2,1,13.9,2,1,12.98,200,1,13.93,100,1,12.86,100,1,14.25,100,1,12.73,100,1,14.28,100,1,12.71,100,1,14.47,100,1,12.5,700,1,14.48,700,1,12.49,200,1,14.51,200,1,12.46,100,1,14.56,800,1,12.43,700,1,14.6,700,1,ARL,336161333
2216,2025-07-17T16:10:51.059443298Z,2025-07-17T16:10:51.059443298Z,10,2,1108,C,A,0,13.620000000,100,130,165455,280001952,13.11,100,1,13.9,2,1,13.01,2,1,13.93,100,1,12.98,200,1,14.25,100,1,12.86,100,1,14.28,100,1,12.73,100,1,14.47,100,1,12.71,100,1,14.48,700,1,12.5,700,1,14.51,200,1,12.49,200,1,14.56,800,1,12.46,100,1,14.6,700,1,12.43,700,1,14.64,200,1,ARL,336295769
2217,2025-07-17T16:10:51.170545251Z,2025-07-17T16:10:51.170545251Z,10,2,1108,A,A,0,13.910000000,100,130,165358,280003702,13.11,100,1,13.9,2,1,13.01,2,1,13.91,100,1,12.98,200,1,13.93,100,1,12.86,100,1,14.25,100,1,12.73,100,1,14.28,100,1,12.71,100,1,14.47,100,1,12.5,700,1,14.48,700,1,12.49,200,1,14.51,200,1,12.46,100,1,14.56,800,1,12.43,700,1,14.6,700,1,ARL,336351081
2218,2025-07-17T16:10:52.958288317Z,2025-07-17T16:10:52.958288317Z,10,2,1108,A,A,0,13.600000000,15,130,165324,280050139,13.11,100,1,13.6,15,1,13.01,2,1,13.9,2,1,12.98,200,1,13.91,100,1,12.86,100,1,13.93,100,1,12.73,100,1,14.25,100,1,12.71,100,1,14.28,100,1,12.5,700,1,14.47,100,1,12.49,200,1,14.48,700,1,12.46,100,1,14.51,200,1,12.43,700,1,14.56,800,1,ARL,336402845
